WARNING:django.request:Not Found: /favicon.ico
ERROR:django.request:Internal Server Error: /api/login/
Traceback (most recent call last):
  File "C:\Users\.-\AppData\Local\Programs\Python\Python312\Lib\site-packages\django\core\handlers\exception.py", line 55, in inner
    response = get_response(request)
               ^^^^^^^^^^^^^^^^^^^^^
  File "C:\Users\.-\AppData\Local\Programs\Python\Python312\Lib\site-packages\django\core\handlers\base.py", line 197, in _get_response
    response = wrapped_callback(request, *callback_args, **callback_kwargs)
               ^^^^^^^^^^^^^^^^^^^^^^^^^^^^^^^^^^^^^^^^^^^^^^^^^^^^^^^^^^^^
  File "C:\Users\.-\AppData\Local\Programs\Python\Python312\Lib\site-packages\django\views\decorators\csrf.py", line 65, in _view_wrapper
    return view_func(request, *args, **kwargs)
           ^^^^^^^^^^^^^^^^^^^^^^^^^^^^^^^^^^^
  File "C:\Users\.-\AppData\Local\Programs\Python\Python312\Lib\site-packages\django\views\generic\base.py", line 104, in view
    return self.dispatch(request, *args, **kwargs)
           ^^^^^^^^^^^^^^^^^^^^^^^^^^^^^^^^^^^^^^^
  File "C:\Users\.-\AppData\Local\Programs\Python\Python312\Lib\site-packages\rest_framework\views.py", line 509, in dispatch
    response = self.handle_exception(exc)
               ^^^^^^^^^^^^^^^^^^^^^^^^^^
  File "C:\Users\.-\AppData\Local\Programs\Python\Python312\Lib\site-packages\rest_framework\views.py", line 469, in handle_exception
    self.raise_uncaught_exception(exc)
  File "C:\Users\.-\AppData\Local\Programs\Python\Python312\Lib\site-packages\rest_framework\views.py", line 480, in raise_uncaught_exception
    raise exc
  File "C:\Users\.-\AppData\Local\Programs\Python\Python312\Lib\site-packages\rest_framework\views.py", line 506, in dispatch
    response = handler(request, *args, **kwargs)
               ^^^^^^^^^^^^^^^^^^^^^^^^^^^^^^^^^
  File "D:\fyp\SmartSuiteBackend\smartsuite\accounts\api\views.py", line 46, in post
    'id': serializer.data['id'],
          ^^^^^^^^^^^^^^^
  File "C:\Users\.-\AppData\Local\Programs\Python\Python312\Lib\site-packages\rest_framework\serializers.py", line 571, in data
    ret = super().data
          ^^^^^^^^^^^^
  File "C:\Users\.-\AppData\Local\Programs\Python\Python312\Lib\site-packages\rest_framework\serializers.py", line 249, in data
    self._data = self.to_representation(self.instance)
                 ^^^^^^^^^^^^^^^^^^^^^^^^^^^^^^^^^^^^^
  File "C:\Users\.-\AppData\Local\Programs\Python\Python312\Lib\site-packages\rest_framework\serializers.py", line 538, in to_representation
    ret[field.field_name] = field.to_representation(attribute)
                            ^^^^^^^^^^^^^^^^^^^^^^^^^^^^^^^^^^
  File "C:\Users\.-\AppData\Local\Programs\Python\Python312\Lib\site-packages\rest_framework\fields.py", line 1870, in to_representation
    return method(value)
           ^^^^^^^^^^^^^
  File "D:\fyp\SmartSuiteBackend\smartsuite\accounts\api\serializers.py", line 136, in get_age
    today = datetime.today()
            ^^^^^^^^^^^^^^
AttributeError: module 'datetime' has no attribute 'today'
INFO:django.utils.autoreload:D:\fyp\SmartSuiteBackend\smartsuite\accounts\api\serializers.py changed, reloading.
INFO:django.utils.autoreload:D:\fyp\SmartSuiteBackend\smartsuite\accounts\api\urls.py changed, reloading.
WARNING:django.request:Unauthorized: /api/summary/
INFO:django.utils.autoreload:D:\fyp\SmartSuiteBackend\smartsuite\accounts\api\urls.py changed, reloading.
INFO:django.utils.autoreload:D:\fyp\SmartSuiteBackend\smartsuite\subjects\api\urls.py changed, reloading.
WARNING:django.request:Unauthorized: /api/summary/
INFO:django.utils.autoreload:D:\fyp\SmartSuiteBackend\smartsuite\subjects\api\views.py changed, reloading.
ERROR:django.request:Internal Server Error: /api/summary/
Traceback (most recent call last):
  File "C:\Users\.-\AppData\Local\Programs\Python\Python312\Lib\site-packages\django\core\handlers\exception.py", line 55, in inner
    response = get_response(request)
               ^^^^^^^^^^^^^^^^^^^^^
  File "C:\Users\.-\AppData\Local\Programs\Python\Python312\Lib\site-packages\django\core\handlers\base.py", line 197, in _get_response
    response = wrapped_callback(request, *callback_args, **callback_kwargs)
               ^^^^^^^^^^^^^^^^^^^^^^^^^^^^^^^^^^^^^^^^^^^^^^^^^^^^^^^^^^^^
  File "C:\Users\.-\AppData\Local\Programs\Python\Python312\Lib\site-packages\django\views\decorators\csrf.py", line 65, in _view_wrapper
    return view_func(request, *args, **kwargs)
           ^^^^^^^^^^^^^^^^^^^^^^^^^^^^^^^^^^^
  File "C:\Users\.-\AppData\Local\Programs\Python\Python312\Lib\site-packages\django\views\generic\base.py", line 104, in view
    return self.dispatch(request, *args, **kwargs)
           ^^^^^^^^^^^^^^^^^^^^^^^^^^^^^^^^^^^^^^^
  File "C:\Users\.-\AppData\Local\Programs\Python\Python312\Lib\site-packages\rest_framework\views.py", line 509, in dispatch
    response = self.handle_exception(exc)
               ^^^^^^^^^^^^^^^^^^^^^^^^^^
  File "C:\Users\.-\AppData\Local\Programs\Python\Python312\Lib\site-packages\rest_framework\views.py", line 469, in handle_exception
    self.raise_uncaught_exception(exc)
  File "C:\Users\.-\AppData\Local\Programs\Python\Python312\Lib\site-packages\rest_framework\views.py", line 480, in raise_uncaught_exception
    raise exc
  File "C:\Users\.-\AppData\Local\Programs\Python\Python312\Lib\site-packages\rest_framework\views.py", line 506, in dispatch
    response = handler(request, *args, **kwargs)
               ^^^^^^^^^^^^^^^^^^^^^^^^^^^^^^^^^
  File "D:\fyp\SmartSuiteBackend\smartsuite\subjects\api\views.py", line 149, in post
    return Response({"id": created_summary.id, "summary": f"{created_summary.summary}",
                           ^^^^^^^^^^^^^^^
UnboundLocalError: cannot access local variable 'created_summary' where it is not associated with a value
INFO:django.utils.autoreload:D:\fyp\SmartSuiteBackend\smartsuite\subjects\admin.py changed, reloading.
ERROR:django.request:Internal Server Error: /admin/subjects/pdffiles/fa7cdc6d-f943-4485-8661-a9fad91f1f28/change/
Traceback (most recent call last):
  File "C:\Users\.-\AppData\Local\Programs\Python\Python312\Lib\site-packages\django\core\handlers\exception.py", line 55, in inner
    response = get_response(request)
               ^^^^^^^^^^^^^^^^^^^^^
  File "C:\Users\.-\AppData\Local\Programs\Python\Python312\Lib\site-packages\django\core\handlers\base.py", line 197, in _get_response
    response = wrapped_callback(request, *callback_args, **callback_kwargs)
               ^^^^^^^^^^^^^^^^^^^^^^^^^^^^^^^^^^^^^^^^^^^^^^^^^^^^^^^^^^^^
  File "C:\Users\.-\AppData\Local\Programs\Python\Python312\Lib\site-packages\django\contrib\admin\options.py", line 716, in wrapper
    return self.admin_site.admin_view(view)(*args, **kwargs)
           ^^^^^^^^^^^^^^^^^^^^^^^^^^^^^^^^^^^^^^^^^^^^^^^^^
  File "C:\Users\.-\AppData\Local\Programs\Python\Python312\Lib\site-packages\django\utils\decorators.py", line 188, in _view_wrapper
    result = _process_exception(request, e)
             ^^^^^^^^^^^^^^^^^^^^^^^^^^^^^^
  File "C:\Users\.-\AppData\Local\Programs\Python\Python312\Lib\site-packages\django\utils\decorators.py", line 186, in _view_wrapper
    response = view_func(request, *args, **kwargs)
               ^^^^^^^^^^^^^^^^^^^^^^^^^^^^^^^^^^^
  File "C:\Users\.-\AppData\Local\Programs\Python\Python312\Lib\site-packages\django\views\decorators\cache.py", line 80, in _view_wrapper
    response = view_func(request, *args, **kwargs)
               ^^^^^^^^^^^^^^^^^^^^^^^^^^^^^^^^^^^
  File "C:\Users\.-\AppData\Local\Programs\Python\Python312\Lib\site-packages\django\contrib\admin\sites.py", line 240, in inner
    return view(request, *args, **kwargs)
           ^^^^^^^^^^^^^^^^^^^^^^^^^^^^^^
  File "C:\Users\.-\AppData\Local\Programs\Python\Python312\Lib\site-packages\django\contrib\admin\options.py", line 1948, in change_view
    return self.changeform_view(request, object_id, form_url, extra_context)
           ^^^^^^^^^^^^^^^^^^^^^^^^^^^^^^^^^^^^^^^^^^^^^^^^^^^^^^^^^^^^^^^^^
  File "C:\Users\.-\AppData\Local\Programs\Python\Python312\Lib\site-packages\django\utils\decorators.py", line 48, in _wrapper
    return bound_method(*args, **kwargs)
           ^^^^^^^^^^^^^^^^^^^^^^^^^^^^^
  File "C:\Users\.-\AppData\Local\Programs\Python\Python312\Lib\site-packages\django\utils\decorators.py", line 188, in _view_wrapper
    result = _process_exception(request, e)
             ^^^^^^^^^^^^^^^^^^^^^^^^^^^^^^
  File "C:\Users\.-\AppData\Local\Programs\Python\Python312\Lib\site-packages\django\utils\decorators.py", line 186, in _view_wrapper
    response = view_func(request, *args, **kwargs)
               ^^^^^^^^^^^^^^^^^^^^^^^^^^^^^^^^^^^
  File "C:\Users\.-\AppData\Local\Programs\Python\Python312\Lib\site-packages\django\contrib\admin\options.py", line 1804, in changeform_view
    return self._changeform_view(request, object_id, form_url, extra_context)
           ^^^^^^^^^^^^^^^^^^^^^^^^^^^^^^^^^^^^^^^^^^^^^^^^^^^^^^^^^^^^^^^^^^
  File "C:\Users\.-\AppData\Local\Programs\Python\Python312\Lib\site-packages\django\contrib\admin\options.py", line 1912, in _changeform_view
    **self.admin_site.each_context(request),
      ^^^^^^^^^^^^^^^^^^^^^^^^^^^^^^^^^^^^^
  File "C:\Users\.-\AppData\Local\Programs\Python\Python312\Lib\site-packages\django\contrib\admin\sites.py", line 335, in each_context
    "available_apps": self.get_app_list(request),
                      ^^^^^^^^^^^^^^^^^^^^^^^^^^
  File "D:\fyp\SmartSuiteBackend\smartsuite\accounts\models.py", line 96, in get_app_list
    app['models'].sort(key=lambda x: ordering[x['name']])
  File "D:\fyp\SmartSuiteBackend\smartsuite\accounts\models.py", line 96, in <lambda>
    app['models'].sort(key=lambda x: ordering[x['name']])
                                     ~~~~~~~~^^^^^^^^^^^
KeyError: 'Summaries'
INFO:django.utils.autoreload:D:\fyp\SmartSuiteBackend\smartsuite\accounts\models.py changed, reloading.
ERROR:django.request:Internal Server Error: /api/summary/
Traceback (most recent call last):
  File "C:\Users\.-\AppData\Local\Programs\Python\Python312\Lib\site-packages\django\core\handlers\exception.py", line 55, in inner
    response = get_response(request)
               ^^^^^^^^^^^^^^^^^^^^^
  File "C:\Users\.-\AppData\Local\Programs\Python\Python312\Lib\site-packages\django\core\handlers\base.py", line 197, in _get_response
    response = wrapped_callback(request, *callback_args, **callback_kwargs)
               ^^^^^^^^^^^^^^^^^^^^^^^^^^^^^^^^^^^^^^^^^^^^^^^^^^^^^^^^^^^^
  File "C:\Users\.-\AppData\Local\Programs\Python\Python312\Lib\site-packages\django\views\decorators\csrf.py", line 65, in _view_wrapper
    return view_func(request, *args, **kwargs)
           ^^^^^^^^^^^^^^^^^^^^^^^^^^^^^^^^^^^
  File "C:\Users\.-\AppData\Local\Programs\Python\Python312\Lib\site-packages\django\views\generic\base.py", line 104, in view
    return self.dispatch(request, *args, **kwargs)
           ^^^^^^^^^^^^^^^^^^^^^^^^^^^^^^^^^^^^^^^
  File "C:\Users\.-\AppData\Local\Programs\Python\Python312\Lib\site-packages\rest_framework\views.py", line 509, in dispatch
    response = self.handle_exception(exc)
               ^^^^^^^^^^^^^^^^^^^^^^^^^^
  File "C:\Users\.-\AppData\Local\Programs\Python\Python312\Lib\site-packages\rest_framework\views.py", line 469, in handle_exception
    self.raise_uncaught_exception(exc)
  File "C:\Users\.-\AppData\Local\Programs\Python\Python312\Lib\site-packages\rest_framework\views.py", line 480, in raise_uncaught_exception
    raise exc
  File "C:\Users\.-\AppData\Local\Programs\Python\Python312\Lib\site-packages\rest_framework\views.py", line 506, in dispatch
    response = handler(request, *args, **kwargs)
               ^^^^^^^^^^^^^^^^^^^^^^^^^^^^^^^^^
  File "D:\fyp\SmartSuiteBackend\smartsuite\subjects\api\views.py", line 149, in post
    return Response({"id": created_summary.id, "summary": f"{created_summary.summary}",
                           ^^^^^^^^^^^^^^^
UnboundLocalError: cannot access local variable 'created_summary' where it is not associated with a value
INFO:django.utils.autoreload:D:\fyp\SmartSuiteBackend\smartsuite\subjects\api\views.py changed, reloading.
INFO:subjects.api.gpts:Successfully decoded with encoding: utf-8
ERROR:django.request:Internal Server Error: /api/summary/
Traceback (most recent call last):
  File "C:\Users\.-\AppData\Local\Programs\Python\Python312\Lib\site-packages\django\core\handlers\exception.py", line 55, in inner
    response = get_response(request)
               ^^^^^^^^^^^^^^^^^^^^^
  File "C:\Users\.-\AppData\Local\Programs\Python\Python312\Lib\site-packages\django\core\handlers\base.py", line 197, in _get_response
    response = wrapped_callback(request, *callback_args, **callback_kwargs)
               ^^^^^^^^^^^^^^^^^^^^^^^^^^^^^^^^^^^^^^^^^^^^^^^^^^^^^^^^^^^^
  File "C:\Users\.-\AppData\Local\Programs\Python\Python312\Lib\site-packages\django\views\decorators\csrf.py", line 65, in _view_wrapper
    return view_func(request, *args, **kwargs)
           ^^^^^^^^^^^^^^^^^^^^^^^^^^^^^^^^^^^
  File "C:\Users\.-\AppData\Local\Programs\Python\Python312\Lib\site-packages\django\views\generic\base.py", line 104, in view
    return self.dispatch(request, *args, **kwargs)
           ^^^^^^^^^^^^^^^^^^^^^^^^^^^^^^^^^^^^^^^
  File "C:\Users\.-\AppData\Local\Programs\Python\Python312\Lib\site-packages\rest_framework\views.py", line 509, in dispatch
    response = self.handle_exception(exc)
               ^^^^^^^^^^^^^^^^^^^^^^^^^^
  File "C:\Users\.-\AppData\Local\Programs\Python\Python312\Lib\site-packages\rest_framework\views.py", line 469, in handle_exception
    self.raise_uncaught_exception(exc)
  File "C:\Users\.-\AppData\Local\Programs\Python\Python312\Lib\site-packages\rest_framework\views.py", line 480, in raise_uncaught_exception
    raise exc
  File "C:\Users\.-\AppData\Local\Programs\Python\Python312\Lib\site-packages\rest_framework\views.py", line 506, in dispatch
    response = handler(request, *args, **kwargs)
               ^^^^^^^^^^^^^^^^^^^^^^^^^^^^^^^^^
  File "D:\fyp\SmartSuiteBackend\smartsuite\subjects\api\views.py", line 142, in post
    created_summary = DocumentSummary.objects.create(
                      ^^^^^^^^^^^^^^^^^^^^^^^^^^^^^^^
  File "C:\Users\.-\AppData\Local\Programs\Python\Python312\Lib\site-packages\django\db\models\manager.py", line 87, in manager_method
    return getattr(self.get_queryset(), name)(*args, **kwargs)
           ^^^^^^^^^^^^^^^^^^^^^^^^^^^^^^^^^^^^^^^^^^^^^^^^^^^
  File "C:\Users\.-\AppData\Local\Programs\Python\Python312\Lib\site-packages\django\db\models\query.py", line 677, in create
    obj = self.model(**kwargs)
          ^^^^^^^^^^^^^^^^^^^^
  File "C:\Users\.-\AppData\Local\Programs\Python\Python312\Lib\site-packages\django\db\models\base.py", line 543, in __init__
    _setattr(self, field.name, rel_obj)
  File "C:\Users\.-\AppData\Local\Programs\Python\Python312\Lib\site-packages\django\db\models\fields\related_descriptors.py", line 284, in __set__
    raise ValueError(
ValueError: Cannot assign "'fa7cdc6d-f943-4485-8661-a9fad91f1f28'": "DocumentSummary.document" must be a "PDFFiles" instance.
INFO:django.utils.autoreload:D:\fyp\SmartSuiteBackend\smartsuite\subjects\api\views.py changed, reloading.
INFO:subjects.api.gpts:Successfully decoded with encoding: utf-8
ERROR:django.request:Internal Server Error: /api/summary/
Traceback (most recent call last):
  File "C:\Users\.-\AppData\Local\Programs\Python\Python312\Lib\site-packages\django\db\backends\utils.py", line 105, in _execute
    return self.cursor.execute(sql, params)
           ^^^^^^^^^^^^^^^^^^^^^^^^^^^^^^^^
psycopg2.errors.StringDataRightTruncation: value too long for type character varying(1000)


The above exception was the direct cause of the following exception:

Traceback (most recent call last):
  File "C:\Users\.-\AppData\Local\Programs\Python\Python312\Lib\site-packages\django\core\handlers\exception.py", line 55, in inner
    response = get_response(request)
               ^^^^^^^^^^^^^^^^^^^^^
  File "C:\Users\.-\AppData\Local\Programs\Python\Python312\Lib\site-packages\django\core\handlers\base.py", line 197, in _get_response
    response = wrapped_callback(request, *callback_args, **callback_kwargs)
               ^^^^^^^^^^^^^^^^^^^^^^^^^^^^^^^^^^^^^^^^^^^^^^^^^^^^^^^^^^^^
  File "C:\Users\.-\AppData\Local\Programs\Python\Python312\Lib\site-packages\django\views\decorators\csrf.py", line 65, in _view_wrapper
    return view_func(request, *args, **kwargs)
           ^^^^^^^^^^^^^^^^^^^^^^^^^^^^^^^^^^^
  File "C:\Users\.-\AppData\Local\Programs\Python\Python312\Lib\site-packages\django\views\generic\base.py", line 104, in view
    return self.dispatch(request, *args, **kwargs)
           ^^^^^^^^^^^^^^^^^^^^^^^^^^^^^^^^^^^^^^^
  File "C:\Users\.-\AppData\Local\Programs\Python\Python312\Lib\site-packages\rest_framework\views.py", line 509, in dispatch
    response = self.handle_exception(exc)
               ^^^^^^^^^^^^^^^^^^^^^^^^^^
  File "C:\Users\.-\AppData\Local\Programs\Python\Python312\Lib\site-packages\rest_framework\views.py", line 469, in handle_exception
    self.raise_uncaught_exception(exc)
  File "C:\Users\.-\AppData\Local\Programs\Python\Python312\Lib\site-packages\rest_framework\views.py", line 480, in raise_uncaught_exception
    raise exc
  File "C:\Users\.-\AppData\Local\Programs\Python\Python312\Lib\site-packages\rest_framework\views.py", line 506, in dispatch
    response = handler(request, *args, **kwargs)
               ^^^^^^^^^^^^^^^^^^^^^^^^^^^^^^^^^
  File "D:\fyp\SmartSuiteBackend\smartsuite\subjects\api\views.py", line 142, in post
    created_summary = DocumentSummary.objects.create(
                      ^^^^^^^^^^^^^^^^^^^^^^^^^^^^^^^
  File "C:\Users\.-\AppData\Local\Programs\Python\Python312\Lib\site-packages\django\db\models\manager.py", line 87, in manager_method
    return getattr(self.get_queryset(), name)(*args, **kwargs)
           ^^^^^^^^^^^^^^^^^^^^^^^^^^^^^^^^^^^^^^^^^^^^^^^^^^^
  File "C:\Users\.-\AppData\Local\Programs\Python\Python312\Lib\site-packages\django\db\models\query.py", line 679, in create
    obj.save(force_insert=True, using=self.db)
  File "C:\Users\.-\AppData\Local\Programs\Python\Python312\Lib\site-packages\django\db\models\base.py", line 822, in save
    self.save_base(
  File "C:\Users\.-\AppData\Local\Programs\Python\Python312\Lib\site-packages\django\db\models\base.py", line 909, in save_base
    updated = self._save_table(
              ^^^^^^^^^^^^^^^^^
  File "C:\Users\.-\AppData\Local\Programs\Python\Python312\Lib\site-packages\django\db\models\base.py", line 1071, in _save_table
    results = self._do_insert(
              ^^^^^^^^^^^^^^^^
  File "C:\Users\.-\AppData\Local\Programs\Python\Python312\Lib\site-packages\django\db\models\base.py", line 1112, in _do_insert
    return manager._insert(
           ^^^^^^^^^^^^^^^^
  File "C:\Users\.-\AppData\Local\Programs\Python\Python312\Lib\site-packages\django\db\models\manager.py", line 87, in manager_method
    return getattr(self.get_queryset(), name)(*args, **kwargs)
           ^^^^^^^^^^^^^^^^^^^^^^^^^^^^^^^^^^^^^^^^^^^^^^^^^^^
  File "C:\Users\.-\AppData\Local\Programs\Python\Python312\Lib\site-packages\django\db\models\query.py", line 1847, in _insert
    return query.get_compiler(using=using).execute_sql(returning_fields)
           ^^^^^^^^^^^^^^^^^^^^^^^^^^^^^^^^^^^^^^^^^^^^^^^^^^^^^^^^^^^^^
  File "C:\Users\.-\AppData\Local\Programs\Python\Python312\Lib\site-packages\django\db\models\sql\compiler.py", line 1823, in execute_sql
    cursor.execute(sql, params)
  File "C:\Users\.-\AppData\Local\Programs\Python\Python312\Lib\site-packages\django\db\backends\utils.py", line 122, in execute
    return super().execute(sql, params)
           ^^^^^^^^^^^^^^^^^^^^^^^^^^^^
  File "C:\Users\.-\AppData\Local\Programs\Python\Python312\Lib\site-packages\django\db\backends\utils.py", line 79, in execute
    return self._execute_with_wrappers(
           ^^^^^^^^^^^^^^^^^^^^^^^^^^^^
  File "C:\Users\.-\AppData\Local\Programs\Python\Python312\Lib\site-packages\django\db\backends\utils.py", line 92, in _execute_with_wrappers
    return executor(sql, params, many, context)
           ^^^^^^^^^^^^^^^^^^^^^^^^^^^^^^^^^^^^
  File "C:\Users\.-\AppData\Local\Programs\Python\Python312\Lib\site-packages\django\db\backends\utils.py", line 100, in _execute
    with self.db.wrap_database_errors:
  File "C:\Users\.-\AppData\Local\Programs\Python\Python312\Lib\site-packages\django\db\utils.py", line 91, in __exit__
    raise dj_exc_value.with_traceback(traceback) from exc_value
  File "C:\Users\.-\AppData\Local\Programs\Python\Python312\Lib\site-packages\django\db\backends\utils.py", line 105, in _execute
    return self.cursor.execute(sql, params)
           ^^^^^^^^^^^^^^^^^^^^^^^^^^^^^^^^
django.db.utils.DataError: value too long for type character varying(1000)

WARNING:django.request:Not Found: /favicon.ico
INFO:subjects.api.gpts:Successfully decoded with encoding: utf-8
ERROR:django.request:Internal Server Error: /api/summary/
Traceback (most recent call last):
  File "C:\Users\.-\AppData\Local\Programs\Python\Python312\Lib\site-packages\django\db\backends\utils.py", line 105, in _execute
    return self.cursor.execute(sql, params)
           ^^^^^^^^^^^^^^^^^^^^^^^^^^^^^^^^
psycopg2.errors.StringDataRightTruncation: value too long for type character varying(1000)


The above exception was the direct cause of the following exception:

Traceback (most recent call last):
  File "C:\Users\.-\AppData\Local\Programs\Python\Python312\Lib\site-packages\django\core\handlers\exception.py", line 55, in inner
    response = get_response(request)
               ^^^^^^^^^^^^^^^^^^^^^
  File "C:\Users\.-\AppData\Local\Programs\Python\Python312\Lib\site-packages\django\core\handlers\base.py", line 197, in _get_response
    response = wrapped_callback(request, *callback_args, **callback_kwargs)
               ^^^^^^^^^^^^^^^^^^^^^^^^^^^^^^^^^^^^^^^^^^^^^^^^^^^^^^^^^^^^
  File "C:\Users\.-\AppData\Local\Programs\Python\Python312\Lib\site-packages\django\views\decorators\csrf.py", line 65, in _view_wrapper
    return view_func(request, *args, **kwargs)
           ^^^^^^^^^^^^^^^^^^^^^^^^^^^^^^^^^^^
  File "C:\Users\.-\AppData\Local\Programs\Python\Python312\Lib\site-packages\django\views\generic\base.py", line 104, in view
    return self.dispatch(request, *args, **kwargs)
           ^^^^^^^^^^^^^^^^^^^^^^^^^^^^^^^^^^^^^^^
  File "C:\Users\.-\AppData\Local\Programs\Python\Python312\Lib\site-packages\rest_framework\views.py", line 509, in dispatch
    response = self.handle_exception(exc)
               ^^^^^^^^^^^^^^^^^^^^^^^^^^
  File "C:\Users\.-\AppData\Local\Programs\Python\Python312\Lib\site-packages\rest_framework\views.py", line 469, in handle_exception
    self.raise_uncaught_exception(exc)
  File "C:\Users\.-\AppData\Local\Programs\Python\Python312\Lib\site-packages\rest_framework\views.py", line 480, in raise_uncaught_exception
    raise exc
  File "C:\Users\.-\AppData\Local\Programs\Python\Python312\Lib\site-packages\rest_framework\views.py", line 506, in dispatch
    response = handler(request, *args, **kwargs)
               ^^^^^^^^^^^^^^^^^^^^^^^^^^^^^^^^^
  File "D:\fyp\SmartSuiteBackend\smartsuite\subjects\api\views.py", line 142, in post
    created_summary = DocumentSummary.objects.create(
                      ^^^^^^^^^^^^^^^^^^^^^^^^^^^^^^^
  File "C:\Users\.-\AppData\Local\Programs\Python\Python312\Lib\site-packages\django\db\models\manager.py", line 87, in manager_method
    return getattr(self.get_queryset(), name)(*args, **kwargs)
           ^^^^^^^^^^^^^^^^^^^^^^^^^^^^^^^^^^^^^^^^^^^^^^^^^^^
  File "C:\Users\.-\AppData\Local\Programs\Python\Python312\Lib\site-packages\django\db\models\query.py", line 679, in create
    obj.save(force_insert=True, using=self.db)
  File "C:\Users\.-\AppData\Local\Programs\Python\Python312\Lib\site-packages\django\db\models\base.py", line 822, in save
    self.save_base(
  File "C:\Users\.-\AppData\Local\Programs\Python\Python312\Lib\site-packages\django\db\models\base.py", line 909, in save_base
    updated = self._save_table(
              ^^^^^^^^^^^^^^^^^
  File "C:\Users\.-\AppData\Local\Programs\Python\Python312\Lib\site-packages\django\db\models\base.py", line 1071, in _save_table
    results = self._do_insert(
              ^^^^^^^^^^^^^^^^
  File "C:\Users\.-\AppData\Local\Programs\Python\Python312\Lib\site-packages\django\db\models\base.py", line 1112, in _do_insert
    return manager._insert(
           ^^^^^^^^^^^^^^^^
  File "C:\Users\.-\AppData\Local\Programs\Python\Python312\Lib\site-packages\django\db\models\manager.py", line 87, in manager_method
    return getattr(self.get_queryset(), name)(*args, **kwargs)
           ^^^^^^^^^^^^^^^^^^^^^^^^^^^^^^^^^^^^^^^^^^^^^^^^^^^
  File "C:\Users\.-\AppData\Local\Programs\Python\Python312\Lib\site-packages\django\db\models\query.py", line 1847, in _insert
    return query.get_compiler(using=using).execute_sql(returning_fields)
           ^^^^^^^^^^^^^^^^^^^^^^^^^^^^^^^^^^^^^^^^^^^^^^^^^^^^^^^^^^^^^
  File "C:\Users\.-\AppData\Local\Programs\Python\Python312\Lib\site-packages\django\db\models\sql\compiler.py", line 1823, in execute_sql
    cursor.execute(sql, params)
  File "C:\Users\.-\AppData\Local\Programs\Python\Python312\Lib\site-packages\django\db\backends\utils.py", line 122, in execute
    return super().execute(sql, params)
           ^^^^^^^^^^^^^^^^^^^^^^^^^^^^
  File "C:\Users\.-\AppData\Local\Programs\Python\Python312\Lib\site-packages\django\db\backends\utils.py", line 79, in execute
    return self._execute_with_wrappers(
           ^^^^^^^^^^^^^^^^^^^^^^^^^^^^
  File "C:\Users\.-\AppData\Local\Programs\Python\Python312\Lib\site-packages\django\db\backends\utils.py", line 92, in _execute_with_wrappers
    return executor(sql, params, many, context)
           ^^^^^^^^^^^^^^^^^^^^^^^^^^^^^^^^^^^^
  File "C:\Users\.-\AppData\Local\Programs\Python\Python312\Lib\site-packages\django\db\backends\utils.py", line 100, in _execute
    with self.db.wrap_database_errors:
  File "C:\Users\.-\AppData\Local\Programs\Python\Python312\Lib\site-packages\django\db\utils.py", line 91, in __exit__
    raise dj_exc_value.with_traceback(traceback) from exc_value
  File "C:\Users\.-\AppData\Local\Programs\Python\Python312\Lib\site-packages\django\db\backends\utils.py", line 105, in _execute
    return self.cursor.execute(sql, params)
           ^^^^^^^^^^^^^^^^^^^^^^^^^^^^^^^^
django.db.utils.DataError: value too long for type character varying(1000)

INFO:django.utils.autoreload:D:\fyp\SmartSuiteBackend\smartsuite\subjects\api\views.py changed, reloading.
INFO:subjects.api.gpts:Successfully decoded with encoding: utf-8
ERROR:django.request:Internal Server Error: /api/summary/
Traceback (most recent call last):
  File "C:\Users\.-\AppData\Local\Programs\Python\Python312\Lib\site-packages\django\db\backends\utils.py", line 105, in _execute
    return self.cursor.execute(sql, params)
           ^^^^^^^^^^^^^^^^^^^^^^^^^^^^^^^^
psycopg2.errors.StringDataRightTruncation: value too long for type character varying(1000)


The above exception was the direct cause of the following exception:

Traceback (most recent call last):
  File "C:\Users\.-\AppData\Local\Programs\Python\Python312\Lib\site-packages\django\core\handlers\exception.py", line 55, in inner
    response = get_response(request)
               ^^^^^^^^^^^^^^^^^^^^^
  File "C:\Users\.-\AppData\Local\Programs\Python\Python312\Lib\site-packages\django\core\handlers\base.py", line 197, in _get_response
    response = wrapped_callback(request, *callback_args, **callback_kwargs)
               ^^^^^^^^^^^^^^^^^^^^^^^^^^^^^^^^^^^^^^^^^^^^^^^^^^^^^^^^^^^^
  File "C:\Users\.-\AppData\Local\Programs\Python\Python312\Lib\site-packages\django\views\decorators\csrf.py", line 65, in _view_wrapper
    return view_func(request, *args, **kwargs)
           ^^^^^^^^^^^^^^^^^^^^^^^^^^^^^^^^^^^
  File "C:\Users\.-\AppData\Local\Programs\Python\Python312\Lib\site-packages\django\views\generic\base.py", line 104, in view
    return self.dispatch(request, *args, **kwargs)
           ^^^^^^^^^^^^^^^^^^^^^^^^^^^^^^^^^^^^^^^
  File "C:\Users\.-\AppData\Local\Programs\Python\Python312\Lib\site-packages\rest_framework\views.py", line 509, in dispatch
    response = self.handle_exception(exc)
               ^^^^^^^^^^^^^^^^^^^^^^^^^^
  File "C:\Users\.-\AppData\Local\Programs\Python\Python312\Lib\site-packages\rest_framework\views.py", line 469, in handle_exception
    self.raise_uncaught_exception(exc)
  File "C:\Users\.-\AppData\Local\Programs\Python\Python312\Lib\site-packages\rest_framework\views.py", line 480, in raise_uncaught_exception
    raise exc
  File "C:\Users\.-\AppData\Local\Programs\Python\Python312\Lib\site-packages\rest_framework\views.py", line 506, in dispatch
    response = handler(request, *args, **kwargs)
               ^^^^^^^^^^^^^^^^^^^^^^^^^^^^^^^^^
  File "D:\fyp\SmartSuiteBackend\smartsuite\subjects\api\views.py", line 146, in post
    created_summary = DocumentSummary.objects.create(
                      ^^^^^^^^^^^^^^^^^^^^^^^^^^^^^^^
  File "C:\Users\.-\AppData\Local\Programs\Python\Python312\Lib\site-packages\django\db\models\manager.py", line 87, in manager_method
    return getattr(self.get_queryset(), name)(*args, **kwargs)
           ^^^^^^^^^^^^^^^^^^^^^^^^^^^^^^^^^^^^^^^^^^^^^^^^^^^
  File "C:\Users\.-\AppData\Local\Programs\Python\Python312\Lib\site-packages\django\db\models\query.py", line 679, in create
    obj.save(force_insert=True, using=self.db)
  File "C:\Users\.-\AppData\Local\Programs\Python\Python312\Lib\site-packages\django\db\models\base.py", line 822, in save
    self.save_base(
  File "C:\Users\.-\AppData\Local\Programs\Python\Python312\Lib\site-packages\django\db\models\base.py", line 909, in save_base
    updated = self._save_table(
              ^^^^^^^^^^^^^^^^^
  File "C:\Users\.-\AppData\Local\Programs\Python\Python312\Lib\site-packages\django\db\models\base.py", line 1071, in _save_table
    results = self._do_insert(
              ^^^^^^^^^^^^^^^^
  File "C:\Users\.-\AppData\Local\Programs\Python\Python312\Lib\site-packages\django\db\models\base.py", line 1112, in _do_insert
    return manager._insert(
           ^^^^^^^^^^^^^^^^
  File "C:\Users\.-\AppData\Local\Programs\Python\Python312\Lib\site-packages\django\db\models\manager.py", line 87, in manager_method
    return getattr(self.get_queryset(), name)(*args, **kwargs)
           ^^^^^^^^^^^^^^^^^^^^^^^^^^^^^^^^^^^^^^^^^^^^^^^^^^^
  File "C:\Users\.-\AppData\Local\Programs\Python\Python312\Lib\site-packages\django\db\models\query.py", line 1847, in _insert
    return query.get_compiler(using=using).execute_sql(returning_fields)
           ^^^^^^^^^^^^^^^^^^^^^^^^^^^^^^^^^^^^^^^^^^^^^^^^^^^^^^^^^^^^^
  File "C:\Users\.-\AppData\Local\Programs\Python\Python312\Lib\site-packages\django\db\models\sql\compiler.py", line 1823, in execute_sql
    cursor.execute(sql, params)
  File "C:\Users\.-\AppData\Local\Programs\Python\Python312\Lib\site-packages\django\db\backends\utils.py", line 122, in execute
    return super().execute(sql, params)
           ^^^^^^^^^^^^^^^^^^^^^^^^^^^^
  File "C:\Users\.-\AppData\Local\Programs\Python\Python312\Lib\site-packages\django\db\backends\utils.py", line 79, in execute
    return self._execute_with_wrappers(
           ^^^^^^^^^^^^^^^^^^^^^^^^^^^^
  File "C:\Users\.-\AppData\Local\Programs\Python\Python312\Lib\site-packages\django\db\backends\utils.py", line 92, in _execute_with_wrappers
    return executor(sql, params, many, context)
           ^^^^^^^^^^^^^^^^^^^^^^^^^^^^^^^^^^^^
  File "C:\Users\.-\AppData\Local\Programs\Python\Python312\Lib\site-packages\django\db\backends\utils.py", line 100, in _execute
    with self.db.wrap_database_errors:
  File "C:\Users\.-\AppData\Local\Programs\Python\Python312\Lib\site-packages\django\db\utils.py", line 91, in __exit__
    raise dj_exc_value.with_traceback(traceback) from exc_value
  File "C:\Users\.-\AppData\Local\Programs\Python\Python312\Lib\site-packages\django\db\backends\utils.py", line 105, in _execute
    return self.cursor.execute(sql, params)
           ^^^^^^^^^^^^^^^^^^^^^^^^^^^^^^^^
django.db.utils.DataError: value too long for type character varying(1000)

INFO:django.utils.autoreload:D:\fyp\SmartSuiteBackend\smartsuite\subjects\models.py changed, reloading.
INFO:subjects.api.gpts:Successfully decoded with encoding: utf-8
INFO:django.utils.autoreload:D:\fyp\SmartSuiteBackend\smartsuite\subjects\api\gpts.py changed, reloading.
INFO:subjects.api.gpts:Successfully decoded with encoding: utf-8
INFO:django.utils.autoreload:D:\fyp\SmartSuiteBackend\smartsuite\subjects\api\views.py changed, reloading.
INFO:subjects.api.gpts:Successfully decoded with encoding: utf-8
INFO:django.utils.autoreload:D:\fyp\SmartSuiteBackend\smartsuite\subjects\api\views.py changed, reloading.
INFO:subjects.api.gpts:Successfully decoded with encoding: utf-8
ERROR:django.request:Not Extended: /api/summary/
INFO:django.utils.autoreload:D:\fyp\SmartSuiteBackend\smartsuite\subjects\api\views.py changed, reloading.
INFO:subjects.api.gpts:Successfully decoded with encoding: utf-8
INFO:django.utils.autoreload:D:\fyp\SmartSuiteBackend\smartsuite\subjects\api\views.py changed, reloading.
INFO:django.utils.autoreload:D:\fyp\SmartSuiteBackend\smartsuite\subjects\api\views.py changed, reloading.
INFO:subjects.api.gpts:Successfully decoded with encoding: utf-8
INFO:subjects.api.gpts:Successfully decoded with encoding: utf-8
INFO:django.utils.autoreload:D:\fyp\SmartSuiteBackend\smartsuite\subjects\api\views.py changed, reloading.
INFO:subjects.api.gpts:Successfully decoded with encoding: utf-8
INFO:django.utils.autoreload:D:\fyp\SmartSuiteBackend\smartsuite\subjects\api\views.py changed, reloading.
INFO:django.utils.autoreload:D:\fyp\SmartSuiteBackend\smartsuite\subjects\api\views.py changed, reloading.
INFO:django.utils.autoreload:D:\fyp\SmartSuiteBackend\smartsuite\subjects\api\urls.py changed, reloading.
INFO:subjects.api.gpts:Successfully decoded with encoding: utf-8
ERROR:django.request:Internal Server Error: /api/keypoints/
Traceback (most recent call last):
  File "C:\Users\.-\AppData\Local\Programs\Python\Python312\Lib\site-packages\django\core\handlers\exception.py", line 55, in inner
    response = get_response(request)
               ^^^^^^^^^^^^^^^^^^^^^
  File "C:\Users\.-\AppData\Local\Programs\Python\Python312\Lib\site-packages\django\core\handlers\base.py", line 197, in _get_response
    response = wrapped_callback(request, *callback_args, **callback_kwargs)
               ^^^^^^^^^^^^^^^^^^^^^^^^^^^^^^^^^^^^^^^^^^^^^^^^^^^^^^^^^^^^
  File "C:\Users\.-\AppData\Local\Programs\Python\Python312\Lib\site-packages\django\views\decorators\csrf.py", line 65, in _view_wrapper
    return view_func(request, *args, **kwargs)
           ^^^^^^^^^^^^^^^^^^^^^^^^^^^^^^^^^^^
  File "C:\Users\.-\AppData\Local\Programs\Python\Python312\Lib\site-packages\django\views\generic\base.py", line 104, in view
    return self.dispatch(request, *args, **kwargs)
           ^^^^^^^^^^^^^^^^^^^^^^^^^^^^^^^^^^^^^^^
  File "C:\Users\.-\AppData\Local\Programs\Python\Python312\Lib\site-packages\rest_framework\views.py", line 509, in dispatch
    response = self.handle_exception(exc)
               ^^^^^^^^^^^^^^^^^^^^^^^^^^
  File "C:\Users\.-\AppData\Local\Programs\Python\Python312\Lib\site-packages\rest_framework\views.py", line 469, in handle_exception
    self.raise_uncaught_exception(exc)
  File "C:\Users\.-\AppData\Local\Programs\Python\Python312\Lib\site-packages\rest_framework\views.py", line 480, in raise_uncaught_exception
    raise exc
  File "C:\Users\.-\AppData\Local\Programs\Python\Python312\Lib\site-packages\rest_framework\views.py", line 506, in dispatch
    response = handler(request, *args, **kwargs)
               ^^^^^^^^^^^^^^^^^^^^^^^^^^^^^^^^^
  File "D:\fyp\SmartSuiteBackend\smartsuite\subjects\api\views.py", line 206, in post
    return Response({"id": created_keypoint.id, "summary": f"{created_keypoint.summary}",
                                                              ^^^^^^^^^^^^^^^^^^^^^^^^
AttributeError: 'DocumentKeypoint' object has no attribute 'summary'
INFO:django.utils.autoreload:D:\fyp\SmartSuiteBackend\smartsuite\subjects\api\views.py changed, reloading.
INFO:subjects.api.gpts:Successfully decoded with encoding: utf-8
INFO:subjects.api.gpts:Successfully decoded with encoding: utf-8
INFO:subjects.api.gpts:Successfully decoded with encoding: utf-8
ERROR:subjects.api.gpts:Error reading DOC/DOCX file: name 'docx' is not defined
ERROR:django.request:Internal Server Error: /api/keypoints/
INFO:django.utils.autoreload:D:\fyp\SmartSuiteBackend\smartsuite\subjects\api\gpts.py changed, reloading.
INFO:django.utils.autoreload:D:\fyp\SmartSuiteBackend\smartsuite\subjects\api\gpts.py changed, reloading.
ERROR:subjects.api.gpts:Error reading DOC/DOCX file: name 'docx' is not defined
ERROR:django.request:Internal Server Error: /api/keypoints/
INFO:django.utils.autoreload:D:\fyp\SmartSuiteBackend\smartsuite\subjects\api\gpts.py changed, reloading.
ERROR:subjects.api.gpts:Error reading DOC/DOCX file: name 'docx' is not defined
ERROR:django.request:Internal Server Error: /api/keypoints/
INFO:django.utils.autoreload:D:\fyp\SmartSuiteBackend\smartsuite\subjects\api\gpts.py changed, reloading.
ERROR:subjects.api.gpts:Error reading DOC/DOCX file: name 'docx' is not defined
ERROR:django.request:Internal Server Error: /api/keypoints/
INFO:django.utils.autoreload:D:\fyp\SmartSuiteBackend\smartsuite\subjects\api\gpts.py changed, reloading.
ERROR:subjects.api.gpts:Error reading DOC/DOCX file: name 'docx' is not defined
ERROR:django.request:Internal Server Error: /api/keypoints/
INFO:django.utils.autoreload:D:\fyp\SmartSuiteBackend\smartsuite\subjects\api\gpts.py changed, reloading.
INFO:django.utils.autoreload:D:\fyp\SmartSuiteBackend\smartsuite\subjects\api\gpts.py changed, reloading.
INFO:django.utils.autoreload:D:\fyp\SmartSuiteBackend\smartsuite\subjects\api\gpts.py changed, reloading.
INFO:django.utils.autoreload:D:\fyp\SmartSuiteBackend\smartsuite\accounts\api\serializers.py changed, reloading.
INFO:django.utils.autoreload:D:\fyp\SmartSuiteBackend\smartsuite\accounts\api\views.py changed, reloading.
WARNING:django.request:Unauthorized: /api/login/
ERROR:django.request:Internal Server Error: /api/login/
Traceback (most recent call last):
  File "C:\Users\.-\AppData\Local\Programs\Python\Python312\Lib\site-packages\django\core\handlers\exception.py", line 55, in inner
    response = get_response(request)
               ^^^^^^^^^^^^^^^^^^^^^
  File "C:\Users\.-\AppData\Local\Programs\Python\Python312\Lib\site-packages\django\core\handlers\base.py", line 197, in _get_response
    response = wrapped_callback(request, *callback_args, **callback_kwargs)
               ^^^^^^^^^^^^^^^^^^^^^^^^^^^^^^^^^^^^^^^^^^^^^^^^^^^^^^^^^^^^
  File "C:\Users\.-\AppData\Local\Programs\Python\Python312\Lib\site-packages\django\views\decorators\csrf.py", line 65, in _view_wrapper
    return view_func(request, *args, **kwargs)
           ^^^^^^^^^^^^^^^^^^^^^^^^^^^^^^^^^^^
  File "C:\Users\.-\AppData\Local\Programs\Python\Python312\Lib\site-packages\django\views\generic\base.py", line 104, in view
    return self.dispatch(request, *args, **kwargs)
           ^^^^^^^^^^^^^^^^^^^^^^^^^^^^^^^^^^^^^^^
  File "C:\Users\.-\AppData\Local\Programs\Python\Python312\Lib\site-packages\rest_framework\views.py", line 509, in dispatch
    response = self.handle_exception(exc)
               ^^^^^^^^^^^^^^^^^^^^^^^^^^
  File "C:\Users\.-\AppData\Local\Programs\Python\Python312\Lib\site-packages\rest_framework\views.py", line 469, in handle_exception
    self.raise_uncaught_exception(exc)
  File "C:\Users\.-\AppData\Local\Programs\Python\Python312\Lib\site-packages\rest_framework\views.py", line 480, in raise_uncaught_exception
    raise exc
  File "C:\Users\.-\AppData\Local\Programs\Python\Python312\Lib\site-packages\rest_framework\views.py", line 506, in dispatch
    response = handler(request, *args, **kwargs)
               ^^^^^^^^^^^^^^^^^^^^^^^^^^^^^^^^^
  File "D:\fyp\SmartSuiteBackend\smartsuite\accounts\api\views.py", line 106, in post
    'total_departments':serializer.data['departments'],
                        ~~~~~~~~~~~~~~~^^^^^^^^^^^^^^^
KeyError: 'departments'
INFO:django.utils.autoreload:D:\fyp\SmartSuiteBackend\smartsuite\accounts\api\views.py changed, reloading.
INFO:django.utils.autoreload:D:\fyp\SmartSuiteBackend\smartsuite\accounts\api\views.py changed, reloading.
INFO:django.utils.autoreload:D:\fyp\SmartSuiteBackend\smartsuite\smartsuite\settings.py changed, reloading.
WARNING:django.request:Not Found: /favicon.ico
INFO:django.utils.autoreload:D:\fyp\Deployed apis\semesters\api\views.py changed, reloading.
INFO:django.utils.autoreload:D:\fyp\Deployed apis\semesters\api\serializers.py changed, reloading.
INFO:django.utils.autoreload:D:\fyp\Deployed apis\semesters\api\views.py changed, reloading.
INFO:django.utils.autoreload:D:\fyp\Deployed apis\subjects\api\serializers.py changed, reloading.
INFO:django.utils.autoreload:D:\fyp\Deployed apis\subjects\api\views.py changed, reloading.
WARNING:django.request:Bad Request: /api/create-account/
WARNING:django.request:Not Found: /api/subject/2cfaf793-f669-4a23-b377-c6daf75ba993/
WARNING:django.request:Not Found: /api/subject_update/2cfaf793-f669-4a23-b377-c6daf75ba993/
WARNING:django.request:Unauthorized: /api/students_of_subjects/
WARNING:django.request:Forbidden: /api/students_of_subjects/
ERROR:django.request:Internal Server Error: /api/students_of_subjects/
Traceback (most recent call last):
  File "C:\Users\.-\AppData\Local\Programs\Python\Python312\Lib\site-packages\django\core\handlers\exception.py", line 55, in inner
    response = get_response(request)
               ^^^^^^^^^^^^^^^^^^^^^
  File "C:\Users\.-\AppData\Local\Programs\Python\Python312\Lib\site-packages\django\core\handlers\base.py", line 197, in _get_response
    response = wrapped_callback(request, *callback_args, **callback_kwargs)
               ^^^^^^^^^^^^^^^^^^^^^^^^^^^^^^^^^^^^^^^^^^^^^^^^^^^^^^^^^^^^
  File "C:\Users\.-\AppData\Local\Programs\Python\Python312\Lib\site-packages\django\views\decorators\csrf.py", line 65, in _view_wrapper
    return view_func(request, *args, **kwargs)
           ^^^^^^^^^^^^^^^^^^^^^^^^^^^^^^^^^^^
  File "C:\Users\.-\AppData\Local\Programs\Python\Python312\Lib\site-packages\django\views\generic\base.py", line 104, in view
    return self.dispatch(request, *args, **kwargs)
           ^^^^^^^^^^^^^^^^^^^^^^^^^^^^^^^^^^^^^^^
  File "C:\Users\.-\AppData\Local\Programs\Python\Python312\Lib\site-packages\rest_framework\views.py", line 509, in dispatch
    response = self.handle_exception(exc)
               ^^^^^^^^^^^^^^^^^^^^^^^^^^
  File "C:\Users\.-\AppData\Local\Programs\Python\Python312\Lib\site-packages\rest_framework\views.py", line 469, in handle_exception
    self.raise_uncaught_exception(exc)
  File "C:\Users\.-\AppData\Local\Programs\Python\Python312\Lib\site-packages\rest_framework\views.py", line 480, in raise_uncaught_exception
    raise exc
  File "C:\Users\.-\AppData\Local\Programs\Python\Python312\Lib\site-packages\rest_framework\views.py", line 506, in dispatch
    response = handler(request, *args, **kwargs)
               ^^^^^^^^^^^^^^^^^^^^^^^^^^^^^^^^^
  File "D:\fyp\Deployed apis\subjects\api\views.py", line 25, in get
    response = serializer.get(instance)
               ^^^^^^^^^^^^^^^^^^^^^^^^
  File "D:\fyp\Deployed apis\subjects\api\serializers.py", line 27, in get
    "teacher_details":TeacherDetailsSerializer(instance.teahcer).data,
                                               ^^^^^^^^^^^^^^^^
AttributeError: 'Subjects' object has no attribute 'teahcer'. Did you mean: 'teacher'?
INFO:django.utils.autoreload:D:\fyp\Deployed apis\subjects\api\serializers.py changed, reloading.
ERROR:django.request:Internal Server Error: /api/students_of_subjects/
Traceback (most recent call last):
  File "C:\Users\.-\AppData\Local\Programs\Python\Python312\Lib\site-packages\django\core\handlers\exception.py", line 55, in inner
    response = get_response(request)
               ^^^^^^^^^^^^^^^^^^^^^
  File "C:\Users\.-\AppData\Local\Programs\Python\Python312\Lib\site-packages\django\core\handlers\base.py", line 197, in _get_response
    response = wrapped_callback(request, *callback_args, **callback_kwargs)
               ^^^^^^^^^^^^^^^^^^^^^^^^^^^^^^^^^^^^^^^^^^^^^^^^^^^^^^^^^^^^
  File "C:\Users\.-\AppData\Local\Programs\Python\Python312\Lib\site-packages\django\views\decorators\csrf.py", line 65, in _view_wrapper
    return view_func(request, *args, **kwargs)
           ^^^^^^^^^^^^^^^^^^^^^^^^^^^^^^^^^^^
  File "C:\Users\.-\AppData\Local\Programs\Python\Python312\Lib\site-packages\django\views\generic\base.py", line 104, in view
    return self.dispatch(request, *args, **kwargs)
           ^^^^^^^^^^^^^^^^^^^^^^^^^^^^^^^^^^^^^^^
  File "C:\Users\.-\AppData\Local\Programs\Python\Python312\Lib\site-packages\rest_framework\views.py", line 509, in dispatch
    response = self.handle_exception(exc)
               ^^^^^^^^^^^^^^^^^^^^^^^^^^
  File "C:\Users\.-\AppData\Local\Programs\Python\Python312\Lib\site-packages\rest_framework\views.py", line 469, in handle_exception
    self.raise_uncaught_exception(exc)
  File "C:\Users\.-\AppData\Local\Programs\Python\Python312\Lib\site-packages\rest_framework\views.py", line 480, in raise_uncaught_exception
    raise exc
  File "C:\Users\.-\AppData\Local\Programs\Python\Python312\Lib\site-packages\rest_framework\views.py", line 506, in dispatch
    response = handler(request, *args, **kwargs)
               ^^^^^^^^^^^^^^^^^^^^^^^^^^^^^^^^^
  File "D:\fyp\Deployed apis\subjects\api\views.py", line 25, in get
    response = serializer.get(instance)
               ^^^^^^^^^^^^^^^^^^^^^^^^
  File "D:\fyp\Deployed apis\subjects\api\serializers.py", line 28, in get
    "students_list":StudentDetailsSerializer(instance.semester.batch.student.all, many=True).data,
                    ^^^^^^^^^^^^^^^^^^^^^^^^^^^^^^^^^^^^^^^^^^^^^^^^^^^^^^^^^^^^^^^^^^^^^^^^^^^^^
  File "C:\Users\.-\AppData\Local\Programs\Python\Python312\Lib\site-packages\rest_framework\serializers.py", line 795, in data
    ret = super().data
          ^^^^^^^^^^^^
  File "C:\Users\.-\AppData\Local\Programs\Python\Python312\Lib\site-packages\rest_framework\serializers.py", line 249, in data
    self._data = self.to_representation(self.instance)
                 ^^^^^^^^^^^^^^^^^^^^^^^^^^^^^^^^^^^^^
  File "C:\Users\.-\AppData\Local\Programs\Python\Python312\Lib\site-packages\rest_framework\serializers.py", line 713, in to_representation
    return [
           ^
TypeError: 'method' object is not iterable
INFO:django.utils.autoreload:D:\fyp\Deployed apis\subjects\api\serializers.py changed, reloading.
INFO:django.utils.autoreload:D:\fyp\Deployed apis\subjects\api\serializers.py changed, reloading.
ERROR:django.request:Internal Server Error: /api/students_of_subjects/
Traceback (most recent call last):
  File "C:\Users\.-\AppData\Local\Programs\Python\Python312\Lib\site-packages\rest_framework\fields.py", line 437, in get_attribute
    return get_attribute(instance, self.source_attrs)
           ^^^^^^^^^^^^^^^^^^^^^^^^^^^^^^^^^^^^^^^^^^
  File "C:\Users\.-\AppData\Local\Programs\Python\Python312\Lib\site-packages\rest_framework\fields.py", line 104, in get_attribute
    instance = getattr(instance, attr)
               ^^^^^^^^^^^^^^^^^^^^^^^
AttributeError: 'CustomUser' object has no attribute 'college_roll_number'

During handling of the above exception, another exception occurred:

Traceback (most recent call last):
  File "C:\Users\.-\AppData\Local\Programs\Python\Python312\Lib\site-packages\django\core\handlers\exception.py", line 55, in inner
    response = get_response(request)
               ^^^^^^^^^^^^^^^^^^^^^
  File "C:\Users\.-\AppData\Local\Programs\Python\Python312\Lib\site-packages\django\core\handlers\base.py", line 197, in _get_response
    response = wrapped_callback(request, *callback_args, **callback_kwargs)
               ^^^^^^^^^^^^^^^^^^^^^^^^^^^^^^^^^^^^^^^^^^^^^^^^^^^^^^^^^^^^
  File "C:\Users\.-\AppData\Local\Programs\Python\Python312\Lib\site-packages\django\views\decorators\csrf.py", line 65, in _view_wrapper
    return view_func(request, *args, **kwargs)
           ^^^^^^^^^^^^^^^^^^^^^^^^^^^^^^^^^^^
  File "C:\Users\.-\AppData\Local\Programs\Python\Python312\Lib\site-packages\django\views\generic\base.py", line 104, in view
    return self.dispatch(request, *args, **kwargs)
           ^^^^^^^^^^^^^^^^^^^^^^^^^^^^^^^^^^^^^^^
  File "C:\Users\.-\AppData\Local\Programs\Python\Python312\Lib\site-packages\rest_framework\views.py", line 509, in dispatch
    response = self.handle_exception(exc)
               ^^^^^^^^^^^^^^^^^^^^^^^^^^
  File "C:\Users\.-\AppData\Local\Programs\Python\Python312\Lib\site-packages\rest_framework\views.py", line 469, in handle_exception
    self.raise_uncaught_exception(exc)
  File "C:\Users\.-\AppData\Local\Programs\Python\Python312\Lib\site-packages\rest_framework\views.py", line 480, in raise_uncaught_exception
    raise exc
  File "C:\Users\.-\AppData\Local\Programs\Python\Python312\Lib\site-packages\rest_framework\views.py", line 506, in dispatch
    response = handler(request, *args, **kwargs)
               ^^^^^^^^^^^^^^^^^^^^^^^^^^^^^^^^^
  File "D:\fyp\Deployed apis\subjects\api\views.py", line 25, in get
    response = serializer.get(instance)
               ^^^^^^^^^^^^^^^^^^^^^^^^
  File "D:\fyp\Deployed apis\subjects\api\serializers.py", line 27, in get
    "students_list":StudentDetailsSerializer(instance.semester.batch.student.all(), many=True).data,
                    ^^^^^^^^^^^^^^^^^^^^^^^^^^^^^^^^^^^^^^^^^^^^^^^^^^^^^^^^^^^^^^^^^^^^^^^^^^^^^^^
  File "C:\Users\.-\AppData\Local\Programs\Python\Python312\Lib\site-packages\rest_framework\serializers.py", line 795, in data
    ret = super().data
          ^^^^^^^^^^^^
  File "C:\Users\.-\AppData\Local\Programs\Python\Python312\Lib\site-packages\rest_framework\serializers.py", line 249, in data
    self._data = self.to_representation(self.instance)
                 ^^^^^^^^^^^^^^^^^^^^^^^^^^^^^^^^^^^^^
  File "C:\Users\.-\AppData\Local\Programs\Python\Python312\Lib\site-packages\rest_framework\serializers.py", line 714, in to_representation
    self.child.to_representation(item) for item in iterable
    ^^^^^^^^^^^^^^^^^^^^^^^^^^^^^^^^^^
  File "C:\Users\.-\AppData\Local\Programs\Python\Python312\Lib\site-packages\rest_framework\serializers.py", line 525, in to_representation
    attribute = field.get_attribute(instance)
                ^^^^^^^^^^^^^^^^^^^^^^^^^^^^^
  File "C:\Users\.-\AppData\Local\Programs\Python\Python312\Lib\site-packages\rest_framework\fields.py", line 470, in get_attribute
    raise type(exc)(msg)
AttributeError: Got AttributeError when attempting to get a value for field `college_roll_number` on serializer `StudentDetailsSerializer`.
The serializer field might be named incorrectly and not match any attribute or key on the `CustomUser` instance.
Original exception text was: 'CustomUser' object has no attribute 'college_roll_number'.
INFO:django.utils.autoreload:D:\fyp\Deployed apis\subjects\api\serializers.py changed, reloading.
WARNING:django.request:Not Found: /favicon.ico
INFO:django.utils.autoreload:D:\fyp\Deployed apis\smartsuite\urls.py changed, reloading.
INFO:django.utils.autoreload:D:\fyp\Deployed apis\group_chats\api\views.py changed, reloading.
INFO:django.utils.autoreload:D:\fyp\Deployed apis\smartsuite\settings.py changed, reloading.
WARNING:django.request:Method Not Allowed: /api/create-group/
ERROR:django.request:Internal Server Error: /api/create-group/
Traceback (most recent call last):
  File "C:\Users\.-\AppData\Local\Programs\Python\Python312\Lib\site-packages\django\core\handlers\exception.py", line 55, in inner
    response = get_response(request)
               ^^^^^^^^^^^^^^^^^^^^^
  File "C:\Users\.-\AppData\Local\Programs\Python\Python312\Lib\site-packages\django\core\handlers\base.py", line 197, in _get_response
    response = wrapped_callback(request, *callback_args, **callback_kwargs)
               ^^^^^^^^^^^^^^^^^^^^^^^^^^^^^^^^^^^^^^^^^^^^^^^^^^^^^^^^^^^^
  File "C:\Users\.-\AppData\Local\Programs\Python\Python312\Lib\site-packages\django\views\decorators\csrf.py", line 65, in _view_wrapper
    return view_func(request, *args, **kwargs)
           ^^^^^^^^^^^^^^^^^^^^^^^^^^^^^^^^^^^
  File "C:\Users\.-\AppData\Local\Programs\Python\Python312\Lib\site-packages\django\views\generic\base.py", line 104, in view
    return self.dispatch(request, *args, **kwargs)
           ^^^^^^^^^^^^^^^^^^^^^^^^^^^^^^^^^^^^^^^
  File "C:\Users\.-\AppData\Local\Programs\Python\Python312\Lib\site-packages\rest_framework\views.py", line 509, in dispatch
    response = self.handle_exception(exc)
               ^^^^^^^^^^^^^^^^^^^^^^^^^^
  File "C:\Users\.-\AppData\Local\Programs\Python\Python312\Lib\site-packages\rest_framework\views.py", line 469, in handle_exception
    self.raise_uncaught_exception(exc)
  File "C:\Users\.-\AppData\Local\Programs\Python\Python312\Lib\site-packages\rest_framework\views.py", line 480, in raise_uncaught_exception
    raise exc
  File "C:\Users\.-\AppData\Local\Programs\Python\Python312\Lib\site-packages\rest_framework\views.py", line 506, in dispatch
    response = handler(request, *args, **kwargs)
               ^^^^^^^^^^^^^^^^^^^^^^^^^^^^^^^^^
  File "D:\fyp\Deployed apis\group_chats\api\views.py", line 11, in post
    if request.user.role == 'Teacher':
       ^^^^^^^^^^^^^^^^^
AttributeError: 'AnonymousUser' object has no attribute 'role'
ERROR:django.request:Internal Server Error: /api/login/
Traceback (most recent call last):
  File "C:\Users\.-\AppData\Local\Programs\Python\Python312\Lib\site-packages\django\core\handlers\exception.py", line 55, in inner
    response = get_response(request)
               ^^^^^^^^^^^^^^^^^^^^^
  File "C:\Users\.-\AppData\Local\Programs\Python\Python312\Lib\site-packages\django\core\handlers\base.py", line 197, in _get_response
    response = wrapped_callback(request, *callback_args, **callback_kwargs)
               ^^^^^^^^^^^^^^^^^^^^^^^^^^^^^^^^^^^^^^^^^^^^^^^^^^^^^^^^^^^^
  File "C:\Users\.-\AppData\Local\Programs\Python\Python312\Lib\site-packages\django\views\decorators\csrf.py", line 65, in _view_wrapper
    return view_func(request, *args, **kwargs)
           ^^^^^^^^^^^^^^^^^^^^^^^^^^^^^^^^^^^
  File "C:\Users\.-\AppData\Local\Programs\Python\Python312\Lib\site-packages\django\views\generic\base.py", line 104, in view
    return self.dispatch(request, *args, **kwargs)
           ^^^^^^^^^^^^^^^^^^^^^^^^^^^^^^^^^^^^^^^
  File "C:\Users\.-\AppData\Local\Programs\Python\Python312\Lib\site-packages\rest_framework\views.py", line 509, in dispatch
    response = self.handle_exception(exc)
               ^^^^^^^^^^^^^^^^^^^^^^^^^^
  File "C:\Users\.-\AppData\Local\Programs\Python\Python312\Lib\site-packages\rest_framework\views.py", line 469, in handle_exception
    self.raise_uncaught_exception(exc)
  File "C:\Users\.-\AppData\Local\Programs\Python\Python312\Lib\site-packages\rest_framework\views.py", line 480, in raise_uncaught_exception
    raise exc
  File "C:\Users\.-\AppData\Local\Programs\Python\Python312\Lib\site-packages\rest_framework\views.py", line 506, in dispatch
    response = handler(request, *args, **kwargs)
               ^^^^^^^^^^^^^^^^^^^^^^^^^^^^^^^^^
  File "D:\fyp\Deployed apis\accounts\api\views.py", line 75, in post
    'id': serializer.data['id'],
          ^^^^^^^^^^^^^^^
  File "C:\Users\.-\AppData\Local\Programs\Python\Python312\Lib\site-packages\rest_framework\serializers.py", line 571, in data
    ret = super().data
          ^^^^^^^^^^^^
  File "C:\Users\.-\AppData\Local\Programs\Python\Python312\Lib\site-packages\rest_framework\serializers.py", line 249, in data
    self._data = self.to_representation(self.instance)
                 ^^^^^^^^^^^^^^^^^^^^^^^^^^^^^^^^^^^^^
  File "C:\Users\.-\AppData\Local\Programs\Python\Python312\Lib\site-packages\rest_framework\serializers.py", line 538, in to_representation
    ret[field.field_name] = field.to_representation(attribute)
                            ^^^^^^^^^^^^^^^^^^^^^^^^^^^^^^^^^^
  File "C:\Users\.-\AppData\Local\Programs\Python\Python312\Lib\site-packages\rest_framework\fields.py", line 1870, in to_representation
    return method(value)
           ^^^^^^^^^^^^^
  File "D:\fyp\Deployed apis\accounts\api\serializers.py", line 220, in get_department
    student_batch = Batch.objects.get(student=obj.id, is_active=True)
                    ^^^^^^^^^^^^^^^^^^^^^^^^^^^^^^^^^^^^^^^^^^^^^^^^^
  File "C:\Users\.-\AppData\Local\Programs\Python\Python312\Lib\site-packages\django\db\models\manager.py", line 87, in manager_method
    return getattr(self.get_queryset(), name)(*args, **kwargs)
           ^^^^^^^^^^^^^^^^^^^^^^^^^^^^^^^^^^^^^^^^^^^^^^^^^^^
  File "C:\Users\.-\AppData\Local\Programs\Python\Python312\Lib\site-packages\django\db\models\query.py", line 649, in get
    raise self.model.DoesNotExist(
batch.models.Batch.DoesNotExist: Batch matching query does not exist.
WARNING:django.request:Unauthorized: /api/create-group/
INFO:django.utils.autoreload:D:\fyp\Deployed apis\group_chats\api\views.py changed, reloading.
INFO:django.utils.autoreload:D:\fyp\Deployed apis\group_chats\api\views.py changed, reloading.
INFO:django.utils.autoreload:D:\fyp\Deployed apis\group_chats\api\views.py changed, reloading.
INFO:django.utils.autoreload:D:\fyp\Deployed apis\group_chats\api\views.py changed, reloading.
WARNING:django.request:Bad Request: /api/create-group/
ERROR:django.request:Internal Server Error: /api/create-group/
Traceback (most recent call last):
  File "C:\Users\.-\AppData\Local\Programs\Python\Python312\Lib\site-packages\django\core\handlers\exception.py", line 55, in inner
    response = get_response(request)
               ^^^^^^^^^^^^^^^^^^^^^
  File "C:\Users\.-\AppData\Local\Programs\Python\Python312\Lib\site-packages\django\core\handlers\base.py", line 197, in _get_response
    response = wrapped_callback(request, *callback_args, **callback_kwargs)
               ^^^^^^^^^^^^^^^^^^^^^^^^^^^^^^^^^^^^^^^^^^^^^^^^^^^^^^^^^^^^
  File "C:\Users\.-\AppData\Local\Programs\Python\Python312\Lib\site-packages\django\views\decorators\csrf.py", line 65, in _view_wrapper
    return view_func(request, *args, **kwargs)
           ^^^^^^^^^^^^^^^^^^^^^^^^^^^^^^^^^^^
  File "C:\Users\.-\AppData\Local\Programs\Python\Python312\Lib\site-packages\django\views\generic\base.py", line 104, in view
    return self.dispatch(request, *args, **kwargs)
           ^^^^^^^^^^^^^^^^^^^^^^^^^^^^^^^^^^^^^^^
  File "C:\Users\.-\AppData\Local\Programs\Python\Python312\Lib\site-packages\rest_framework\views.py", line 509, in dispatch
    response = self.handle_exception(exc)
               ^^^^^^^^^^^^^^^^^^^^^^^^^^
  File "C:\Users\.-\AppData\Local\Programs\Python\Python312\Lib\site-packages\rest_framework\views.py", line 469, in handle_exception
    self.raise_uncaught_exception(exc)
  File "C:\Users\.-\AppData\Local\Programs\Python\Python312\Lib\site-packages\rest_framework\views.py", line 480, in raise_uncaught_exception
    raise exc
  File "C:\Users\.-\AppData\Local\Programs\Python\Python312\Lib\site-packages\rest_framework\views.py", line 506, in dispatch
    response = handler(request, *args, **kwargs)
               ^^^^^^^^^^^^^^^^^^^^^^^^^^^^^^^^^
  File "D:\fyp\Deployed apis\group_chats\api\views.py", line 14, in post
    if serializer.is_valid(raise_exception=True):
       ^^^^^^^^^^^^^^^^^^^^^^^^^^^^^^^^^^^^^^^^^
  File "C:\Users\.-\AppData\Local\Programs\Python\Python312\Lib\site-packages\rest_framework\serializers.py", line 223, in is_valid
    self._validated_data = self.run_validation(self.initial_data)
                           ^^^^^^^^^^^^^^^^^^^^^^^^^^^^^^^^^^^^^^
  File "C:\Users\.-\AppData\Local\Programs\Python\Python312\Lib\site-packages\rest_framework\serializers.py", line 445, in run_validation
    value = self.validate(value)
            ^^^^^^^^^^^^^^^^^^^^
  File "D:\fyp\Deployed apis\group_chats\api\serializers.py", line 15, in validate
    if teacher.role != "Teacher":
       ^^^^^^^^^^^^
AttributeError: 'NoneType' object has no attribute 'role'
INFO:django.utils.autoreload:D:\fyp\Deployed apis\group_chats\api\serializers.py changed, reloading.
ERROR:django.request:Internal Server Error: /api/create-group/
Traceback (most recent call last):
  File "C:\Users\.-\AppData\Local\Programs\Python\Python312\Lib\site-packages\django\core\handlers\exception.py", line 55, in inner
    response = get_response(request)
               ^^^^^^^^^^^^^^^^^^^^^
  File "C:\Users\.-\AppData\Local\Programs\Python\Python312\Lib\site-packages\django\core\handlers\base.py", line 197, in _get_response
    response = wrapped_callback(request, *callback_args, **callback_kwargs)
               ^^^^^^^^^^^^^^^^^^^^^^^^^^^^^^^^^^^^^^^^^^^^^^^^^^^^^^^^^^^^
  File "C:\Users\.-\AppData\Local\Programs\Python\Python312\Lib\site-packages\django\views\decorators\csrf.py", line 65, in _view_wrapper
    return view_func(request, *args, **kwargs)
           ^^^^^^^^^^^^^^^^^^^^^^^^^^^^^^^^^^^
  File "C:\Users\.-\AppData\Local\Programs\Python\Python312\Lib\site-packages\django\views\generic\base.py", line 104, in view
    return self.dispatch(request, *args, **kwargs)
           ^^^^^^^^^^^^^^^^^^^^^^^^^^^^^^^^^^^^^^^
  File "C:\Users\.-\AppData\Local\Programs\Python\Python312\Lib\site-packages\rest_framework\views.py", line 509, in dispatch
    response = self.handle_exception(exc)
               ^^^^^^^^^^^^^^^^^^^^^^^^^^
  File "C:\Users\.-\AppData\Local\Programs\Python\Python312\Lib\site-packages\rest_framework\views.py", line 469, in handle_exception
    self.raise_uncaught_exception(exc)
  File "C:\Users\.-\AppData\Local\Programs\Python\Python312\Lib\site-packages\rest_framework\views.py", line 480, in raise_uncaught_exception
    raise exc
  File "C:\Users\.-\AppData\Local\Programs\Python\Python312\Lib\site-packages\rest_framework\views.py", line 506, in dispatch
    response = handler(request, *args, **kwargs)
               ^^^^^^^^^^^^^^^^^^^^^^^^^^^^^^^^^
  File "D:\fyp\Deployed apis\group_chats\api\views.py", line 14, in post
    if serializer.is_valid(raise_exception=True):
       ^^^^^^^^^^^^^^^^^^^^^^^^^^^^^^^^^^^^^^^^^
  File "C:\Users\.-\AppData\Local\Programs\Python\Python312\Lib\site-packages\rest_framework\serializers.py", line 223, in is_valid
    self._validated_data = self.run_validation(self.initial_data)
                           ^^^^^^^^^^^^^^^^^^^^^^^^^^^^^^^^^^^^^^
  File "C:\Users\.-\AppData\Local\Programs\Python\Python312\Lib\site-packages\rest_framework\serializers.py", line 445, in run_validation
    value = self.validate(value)
            ^^^^^^^^^^^^^^^^^^^^
  File "D:\fyp\Deployed apis\group_chats\api\serializers.py", line 16, in validate
    if teacher.role != "Teacher":
       ^^^^^^^^^^^^
AttributeError: 'NoneType' object has no attribute 'role'
ERROR:django.request:Internal Server Error: /api/create-group/
Traceback (most recent call last):
  File "C:\Users\.-\AppData\Local\Programs\Python\Python312\Lib\site-packages\django\core\handlers\exception.py", line 55, in inner
    response = get_response(request)
               ^^^^^^^^^^^^^^^^^^^^^
  File "C:\Users\.-\AppData\Local\Programs\Python\Python312\Lib\site-packages\django\core\handlers\base.py", line 197, in _get_response
    response = wrapped_callback(request, *callback_args, **callback_kwargs)
               ^^^^^^^^^^^^^^^^^^^^^^^^^^^^^^^^^^^^^^^^^^^^^^^^^^^^^^^^^^^^
  File "C:\Users\.-\AppData\Local\Programs\Python\Python312\Lib\site-packages\django\views\decorators\csrf.py", line 65, in _view_wrapper
    return view_func(request, *args, **kwargs)
           ^^^^^^^^^^^^^^^^^^^^^^^^^^^^^^^^^^^
  File "C:\Users\.-\AppData\Local\Programs\Python\Python312\Lib\site-packages\django\views\generic\base.py", line 104, in view
    return self.dispatch(request, *args, **kwargs)
           ^^^^^^^^^^^^^^^^^^^^^^^^^^^^^^^^^^^^^^^
  File "C:\Users\.-\AppData\Local\Programs\Python\Python312\Lib\site-packages\rest_framework\views.py", line 509, in dispatch
    response = self.handle_exception(exc)
               ^^^^^^^^^^^^^^^^^^^^^^^^^^
  File "C:\Users\.-\AppData\Local\Programs\Python\Python312\Lib\site-packages\rest_framework\views.py", line 469, in handle_exception
    self.raise_uncaught_exception(exc)
  File "C:\Users\.-\AppData\Local\Programs\Python\Python312\Lib\site-packages\rest_framework\views.py", line 480, in raise_uncaught_exception
    raise exc
  File "C:\Users\.-\AppData\Local\Programs\Python\Python312\Lib\site-packages\rest_framework\views.py", line 506, in dispatch
    response = handler(request, *args, **kwargs)
               ^^^^^^^^^^^^^^^^^^^^^^^^^^^^^^^^^
  File "D:\fyp\Deployed apis\group_chats\api\views.py", line 14, in post
    if serializer.is_valid(raise_exception=True):
       ^^^^^^^^^^^^^^^^^^^^^^^^^^^^^^^^^^^^^^^^^
  File "C:\Users\.-\AppData\Local\Programs\Python\Python312\Lib\site-packages\rest_framework\serializers.py", line 223, in is_valid
    self._validated_data = self.run_validation(self.initial_data)
                           ^^^^^^^^^^^^^^^^^^^^^^^^^^^^^^^^^^^^^^
  File "C:\Users\.-\AppData\Local\Programs\Python\Python312\Lib\site-packages\rest_framework\serializers.py", line 445, in run_validation
    value = self.validate(value)
            ^^^^^^^^^^^^^^^^^^^^
  File "D:\fyp\Deployed apis\group_chats\api\serializers.py", line 16, in validate
    if teacher.role != "Teacher":
       ^^^^^^^^^^^^
AttributeError: 'NoneType' object has no attribute 'role'
INFO:django.utils.autoreload:D:\fyp\Deployed apis\group_chats\api\views.py changed, reloading.
ERROR:django.request:Internal Server Error: /api/create-group/
Traceback (most recent call last):
  File "C:\Users\.-\AppData\Local\Programs\Python\Python312\Lib\site-packages\django\core\handlers\exception.py", line 55, in inner
    response = get_response(request)
               ^^^^^^^^^^^^^^^^^^^^^
  File "C:\Users\.-\AppData\Local\Programs\Python\Python312\Lib\site-packages\django\core\handlers\base.py", line 197, in _get_response
    response = wrapped_callback(request, *callback_args, **callback_kwargs)
               ^^^^^^^^^^^^^^^^^^^^^^^^^^^^^^^^^^^^^^^^^^^^^^^^^^^^^^^^^^^^
  File "C:\Users\.-\AppData\Local\Programs\Python\Python312\Lib\site-packages\django\views\decorators\csrf.py", line 65, in _view_wrapper
    return view_func(request, *args, **kwargs)
           ^^^^^^^^^^^^^^^^^^^^^^^^^^^^^^^^^^^
  File "C:\Users\.-\AppData\Local\Programs\Python\Python312\Lib\site-packages\django\views\generic\base.py", line 104, in view
    return self.dispatch(request, *args, **kwargs)
           ^^^^^^^^^^^^^^^^^^^^^^^^^^^^^^^^^^^^^^^
  File "C:\Users\.-\AppData\Local\Programs\Python\Python312\Lib\site-packages\rest_framework\views.py", line 509, in dispatch
    response = self.handle_exception(exc)
               ^^^^^^^^^^^^^^^^^^^^^^^^^^
  File "C:\Users\.-\AppData\Local\Programs\Python\Python312\Lib\site-packages\rest_framework\views.py", line 469, in handle_exception
    self.raise_uncaught_exception(exc)
  File "C:\Users\.-\AppData\Local\Programs\Python\Python312\Lib\site-packages\rest_framework\views.py", line 480, in raise_uncaught_exception
    raise exc
  File "C:\Users\.-\AppData\Local\Programs\Python\Python312\Lib\site-packages\rest_framework\views.py", line 506, in dispatch
    response = handler(request, *args, **kwargs)
               ^^^^^^^^^^^^^^^^^^^^^^^^^^^^^^^^^
  File "D:\fyp\Deployed apis\group_chats\api\views.py", line 15, in post
    if serializer.is_valid(raise_exception=True):
       ^^^^^^^^^^^^^^^^^^^^^^^^^^^^^^^^^^^^^^^^^
  File "C:\Users\.-\AppData\Local\Programs\Python\Python312\Lib\site-packages\rest_framework\serializers.py", line 223, in is_valid
    self._validated_data = self.run_validation(self.initial_data)
                           ^^^^^^^^^^^^^^^^^^^^^^^^^^^^^^^^^^^^^^
  File "C:\Users\.-\AppData\Local\Programs\Python\Python312\Lib\site-packages\rest_framework\serializers.py", line 445, in run_validation
    value = self.validate(value)
            ^^^^^^^^^^^^^^^^^^^^
  File "D:\fyp\Deployed apis\group_chats\api\serializers.py", line 16, in validate
    if teacher.role != "Teacher":
       ^^^^^^^^^^^^
AttributeError: 'NoneType' object has no attribute 'role'
INFO:django.utils.autoreload:D:\fyp\Deployed apis\group_chats\api\serializers.py changed, reloading.
WARNING:django.request:Bad Request: /api/create-group/
INFO:django.utils.autoreload:D:\fyp\Deployed apis\group_chats\api\serializers.py changed, reloading.
WARNING:django.request:Bad Request: /api/create-group/
INFO:django.utils.autoreload:D:\fyp\Deployed apis\group_chats\api\serializers.py changed, reloading.
WARNING:django.request:Bad Request: /api/create-group/
WARNING:django.request:Bad Request: /api/create-group/
ERROR:django.request:Internal Server Error: /api/create-group/
Traceback (most recent call last):
  File "C:\Users\.-\AppData\Local\Programs\Python\Python312\Lib\site-packages\django\db\backends\utils.py", line 105, in _execute
    return self.cursor.execute(sql, params)
           ^^^^^^^^^^^^^^^^^^^^^^^^^^^^^^^^
  File "C:\Users\.-\AppData\Local\Programs\Python\Python312\Lib\site-packages\django\db\backends\sqlite3\base.py", line 329, in execute
    return super().execute(query, params)
           ^^^^^^^^^^^^^^^^^^^^^^^^^^^^^^
sqlite3.OperationalError: no such table: group_chats_groupchat

The above exception was the direct cause of the following exception:

Traceback (most recent call last):
  File "C:\Users\.-\AppData\Local\Programs\Python\Python312\Lib\site-packages\django\core\handlers\exception.py", line 55, in inner
    response = get_response(request)
               ^^^^^^^^^^^^^^^^^^^^^
  File "C:\Users\.-\AppData\Local\Programs\Python\Python312\Lib\site-packages\django\core\handlers\base.py", line 197, in _get_response
    response = wrapped_callback(request, *callback_args, **callback_kwargs)
               ^^^^^^^^^^^^^^^^^^^^^^^^^^^^^^^^^^^^^^^^^^^^^^^^^^^^^^^^^^^^
  File "C:\Users\.-\AppData\Local\Programs\Python\Python312\Lib\site-packages\django\views\decorators\csrf.py", line 65, in _view_wrapper
    return view_func(request, *args, **kwargs)
           ^^^^^^^^^^^^^^^^^^^^^^^^^^^^^^^^^^^
  File "C:\Users\.-\AppData\Local\Programs\Python\Python312\Lib\site-packages\django\views\generic\base.py", line 104, in view
    return self.dispatch(request, *args, **kwargs)
           ^^^^^^^^^^^^^^^^^^^^^^^^^^^^^^^^^^^^^^^
  File "C:\Users\.-\AppData\Local\Programs\Python\Python312\Lib\site-packages\rest_framework\views.py", line 509, in dispatch
    response = self.handle_exception(exc)
               ^^^^^^^^^^^^^^^^^^^^^^^^^^
  File "C:\Users\.-\AppData\Local\Programs\Python\Python312\Lib\site-packages\rest_framework\views.py", line 469, in handle_exception
    self.raise_uncaught_exception(exc)
  File "C:\Users\.-\AppData\Local\Programs\Python\Python312\Lib\site-packages\rest_framework\views.py", line 480, in raise_uncaught_exception
    raise exc
  File "C:\Users\.-\AppData\Local\Programs\Python\Python312\Lib\site-packages\rest_framework\views.py", line 506, in dispatch
    response = handler(request, *args, **kwargs)
               ^^^^^^^^^^^^^^^^^^^^^^^^^^^^^^^^^
  File "D:\fyp\Deployed apis\group_chats\api\views.py", line 15, in post
    serializer.save()
  File "C:\Users\.-\AppData\Local\Programs\Python\Python312\Lib\site-packages\rest_framework\serializers.py", line 208, in save
    self.instance = self.create(validated_data)
                    ^^^^^^^^^^^^^^^^^^^^^^^^^^^
  File "D:\fyp\Deployed apis\group_chats\api\serializers.py", line 21, in create
    new_group_chat = GroupChat.objects.create(**valiadated_data)
                     ^^^^^^^^^^^^^^^^^^^^^^^^^^^^^^^^^^^^^^^^^^^
  File "C:\Users\.-\AppData\Local\Programs\Python\Python312\Lib\site-packages\django\db\models\manager.py", line 87, in manager_method
    return getattr(self.get_queryset(), name)(*args, **kwargs)
           ^^^^^^^^^^^^^^^^^^^^^^^^^^^^^^^^^^^^^^^^^^^^^^^^^^^
  File "C:\Users\.-\AppData\Local\Programs\Python\Python312\Lib\site-packages\django\db\models\query.py", line 679, in create
    obj.save(force_insert=True, using=self.db)
  File "C:\Users\.-\AppData\Local\Programs\Python\Python312\Lib\site-packages\django\db\models\base.py", line 822, in save
    self.save_base(
  File "C:\Users\.-\AppData\Local\Programs\Python\Python312\Lib\site-packages\django\db\models\base.py", line 909, in save_base
    updated = self._save_table(
              ^^^^^^^^^^^^^^^^^
  File "C:\Users\.-\AppData\Local\Programs\Python\Python312\Lib\site-packages\django\db\models\base.py", line 1071, in _save_table
    results = self._do_insert(
              ^^^^^^^^^^^^^^^^
  File "C:\Users\.-\AppData\Local\Programs\Python\Python312\Lib\site-packages\django\db\models\base.py", line 1112, in _do_insert
    return manager._insert(
           ^^^^^^^^^^^^^^^^
  File "C:\Users\.-\AppData\Local\Programs\Python\Python312\Lib\site-packages\django\db\models\manager.py", line 87, in manager_method
    return getattr(self.get_queryset(), name)(*args, **kwargs)
           ^^^^^^^^^^^^^^^^^^^^^^^^^^^^^^^^^^^^^^^^^^^^^^^^^^^
  File "C:\Users\.-\AppData\Local\Programs\Python\Python312\Lib\site-packages\django\db\models\query.py", line 1847, in _insert
    return query.get_compiler(using=using).execute_sql(returning_fields)
           ^^^^^^^^^^^^^^^^^^^^^^^^^^^^^^^^^^^^^^^^^^^^^^^^^^^^^^^^^^^^^
  File "C:\Users\.-\AppData\Local\Programs\Python\Python312\Lib\site-packages\django\db\models\sql\compiler.py", line 1823, in execute_sql
    cursor.execute(sql, params)
  File "C:\Users\.-\AppData\Local\Programs\Python\Python312\Lib\site-packages\django\db\backends\utils.py", line 122, in execute
    return super().execute(sql, params)
           ^^^^^^^^^^^^^^^^^^^^^^^^^^^^
  File "C:\Users\.-\AppData\Local\Programs\Python\Python312\Lib\site-packages\django\db\backends\utils.py", line 79, in execute
    return self._execute_with_wrappers(
           ^^^^^^^^^^^^^^^^^^^^^^^^^^^^
  File "C:\Users\.-\AppData\Local\Programs\Python\Python312\Lib\site-packages\django\db\backends\utils.py", line 92, in _execute_with_wrappers
    return executor(sql, params, many, context)
           ^^^^^^^^^^^^^^^^^^^^^^^^^^^^^^^^^^^^
  File "C:\Users\.-\AppData\Local\Programs\Python\Python312\Lib\site-packages\django\db\backends\utils.py", line 100, in _execute
    with self.db.wrap_database_errors:
  File "C:\Users\.-\AppData\Local\Programs\Python\Python312\Lib\site-packages\django\db\utils.py", line 91, in __exit__
    raise dj_exc_value.with_traceback(traceback) from exc_value
  File "C:\Users\.-\AppData\Local\Programs\Python\Python312\Lib\site-packages\django\db\backends\utils.py", line 105, in _execute
    return self.cursor.execute(sql, params)
           ^^^^^^^^^^^^^^^^^^^^^^^^^^^^^^^^
  File "C:\Users\.-\AppData\Local\Programs\Python\Python312\Lib\site-packages\django\db\backends\sqlite3\base.py", line 329, in execute
    return super().execute(query, params)
           ^^^^^^^^^^^^^^^^^^^^^^^^^^^^^^
django.db.utils.OperationalError: no such table: group_chats_groupchat
INFO:django.utils.autoreload:D:\fyp\Deployed apis\group_chats\admin.py changed, reloading.
ERROR:django.request:Internal Server Error: /admin/accounts/customdepartmentteacher/
Traceback (most recent call last):
  File "C:\Users\.-\AppData\Local\Programs\Python\Python312\Lib\site-packages\django\core\handlers\exception.py", line 55, in inner
    response = get_response(request)
               ^^^^^^^^^^^^^^^^^^^^^
  File "C:\Users\.-\AppData\Local\Programs\Python\Python312\Lib\site-packages\django\core\handlers\base.py", line 197, in _get_response
    response = wrapped_callback(request, *callback_args, **callback_kwargs)
               ^^^^^^^^^^^^^^^^^^^^^^^^^^^^^^^^^^^^^^^^^^^^^^^^^^^^^^^^^^^^
  File "C:\Users\.-\AppData\Local\Programs\Python\Python312\Lib\site-packages\django\contrib\admin\options.py", line 716, in wrapper
    return self.admin_site.admin_view(view)(*args, **kwargs)
           ^^^^^^^^^^^^^^^^^^^^^^^^^^^^^^^^^^^^^^^^^^^^^^^^^
  File "C:\Users\.-\AppData\Local\Programs\Python\Python312\Lib\site-packages\django\utils\decorators.py", line 188, in _view_wrapper
    result = _process_exception(request, e)
             ^^^^^^^^^^^^^^^^^^^^^^^^^^^^^^
  File "C:\Users\.-\AppData\Local\Programs\Python\Python312\Lib\site-packages\django\utils\decorators.py", line 186, in _view_wrapper
    response = view_func(request, *args, **kwargs)
               ^^^^^^^^^^^^^^^^^^^^^^^^^^^^^^^^^^^
  File "C:\Users\.-\AppData\Local\Programs\Python\Python312\Lib\site-packages\django\views\decorators\cache.py", line 80, in _view_wrapper
    response = view_func(request, *args, **kwargs)
               ^^^^^^^^^^^^^^^^^^^^^^^^^^^^^^^^^^^
  File "C:\Users\.-\AppData\Local\Programs\Python\Python312\Lib\site-packages\django\contrib\admin\sites.py", line 240, in inner
    return view(request, *args, **kwargs)
           ^^^^^^^^^^^^^^^^^^^^^^^^^^^^^^
  File "C:\Users\.-\AppData\Local\Programs\Python\Python312\Lib\site-packages\django\utils\decorators.py", line 48, in _wrapper
    return bound_method(*args, **kwargs)
           ^^^^^^^^^^^^^^^^^^^^^^^^^^^^^
  File "C:\Users\.-\AppData\Local\Programs\Python\Python312\Lib\site-packages\django\utils\decorators.py", line 188, in _view_wrapper
    result = _process_exception(request, e)
             ^^^^^^^^^^^^^^^^^^^^^^^^^^^^^^
  File "C:\Users\.-\AppData\Local\Programs\Python\Python312\Lib\site-packages\django\utils\decorators.py", line 186, in _view_wrapper
    response = view_func(request, *args, **kwargs)
               ^^^^^^^^^^^^^^^^^^^^^^^^^^^^^^^^^^^
  File "C:\Users\.-\AppData\Local\Programs\Python\Python312\Lib\site-packages\django\contrib\admin\options.py", line 2122, in changelist_view
    **self.admin_site.each_context(request),
      ^^^^^^^^^^^^^^^^^^^^^^^^^^^^^^^^^^^^^
  File "C:\Users\.-\AppData\Local\Programs\Python\Python312\Lib\site-packages\django\contrib\admin\sites.py", line 335, in each_context
    "available_apps": self.get_app_list(request),
                      ^^^^^^^^^^^^^^^^^^^^^^^^^^
  File "D:\fyp\Deployed apis\accounts\models.py", line 105, in get_app_list
    app['models'].sort(key=lambda x: ordering[x['name']])
  File "D:\fyp\Deployed apis\accounts\models.py", line 105, in <lambda>
    app['models'].sort(key=lambda x: ordering[x['name']])
                                     ~~~~~~~~^^^^^^^^^^^
KeyError: 'Group chats'
INFO:django.utils.autoreload:D:\fyp\Deployed apis\group_chats\models.py changed, reloading.
WARNING:django.request:Not Found: /api/groups/
INFO:django.utils.autoreload:D:\fyp\Deployed apis\group_chats\api\urls.py changed, reloading.
INFO:django.utils.autoreload:D:\fyp\Deployed apis\group_chats\api\views.py changed, reloading.
ERROR:django.request:Internal Server Error: /api/group/
Traceback (most recent call last):
  File "C:\Users\.-\AppData\Local\Programs\Python\Python312\Lib\site-packages\django\core\handlers\exception.py", line 55, in inner
    response = get_response(request)
               ^^^^^^^^^^^^^^^^^^^^^
  File "C:\Users\.-\AppData\Local\Programs\Python\Python312\Lib\site-packages\django\core\handlers\base.py", line 197, in _get_response
    response = wrapped_callback(request, *callback_args, **callback_kwargs)
               ^^^^^^^^^^^^^^^^^^^^^^^^^^^^^^^^^^^^^^^^^^^^^^^^^^^^^^^^^^^^
  File "C:\Users\.-\AppData\Local\Programs\Python\Python312\Lib\site-packages\django\views\decorators\csrf.py", line 65, in _view_wrapper
    return view_func(request, *args, **kwargs)
           ^^^^^^^^^^^^^^^^^^^^^^^^^^^^^^^^^^^
  File "C:\Users\.-\AppData\Local\Programs\Python\Python312\Lib\site-packages\django\views\generic\base.py", line 104, in view
    return self.dispatch(request, *args, **kwargs)
           ^^^^^^^^^^^^^^^^^^^^^^^^^^^^^^^^^^^^^^^
  File "C:\Users\.-\AppData\Local\Programs\Python\Python312\Lib\site-packages\rest_framework\views.py", line 509, in dispatch
    response = self.handle_exception(exc)
               ^^^^^^^^^^^^^^^^^^^^^^^^^^
  File "C:\Users\.-\AppData\Local\Programs\Python\Python312\Lib\site-packages\rest_framework\views.py", line 469, in handle_exception
    self.raise_uncaught_exception(exc)
  File "C:\Users\.-\AppData\Local\Programs\Python\Python312\Lib\site-packages\rest_framework\views.py", line 480, in raise_uncaught_exception
    raise exc
  File "C:\Users\.-\AppData\Local\Programs\Python\Python312\Lib\site-packages\rest_framework\views.py", line 506, in dispatch
    response = handler(request, *args, **kwargs)
               ^^^^^^^^^^^^^^^^^^^^^^^^^^^^^^^^^
  File "D:\fyp\Deployed apis\group_chats\api\views.py", line 37, in patch
    if serializer.is_valid(raise_exception=True):
       ^^^^^^^^^^^^^^^^^^^^^^^^^^^^^^^^^^^^^^^^^
  File "C:\Users\.-\AppData\Local\Programs\Python\Python312\Lib\site-packages\rest_framework\serializers.py", line 223, in is_valid
    self._validated_data = self.run_validation(self.initial_data)
                           ^^^^^^^^^^^^^^^^^^^^^^^^^^^^^^^^^^^^^^
  File "C:\Users\.-\AppData\Local\Programs\Python\Python312\Lib\site-packages\rest_framework\serializers.py", line 445, in run_validation
    value = self.validate(value)
            ^^^^^^^^^^^^^^^^^^^^
  File "D:\fyp\Deployed apis\group_chats\api\serializers.py", line 13, in validate
    if teacher.role != "Teacher":
       ^^^^^^^^^^^^
AttributeError: 'NoneType' object has no attribute 'role'
INFO:django.utils.autoreload:D:\fyp\Deployed apis\group_chats\api\serializers.py changed, reloading.
INFO:django.utils.autoreload:D:\fyp\Deployed apis\group_chats\api\serializers.py changed, reloading.
INFO:django.utils.autoreload:D:\fyp\Deployed apis\group_chats\api\serializers.py changed, reloading.
INFO:django.utils.autoreload:D:\fyp\Deployed apis\group_chats\api\serializers.py changed, reloading.
INFO:django.utils.autoreload:D:\fyp\Deployed apis\group_chats\api\serializers.py changed, reloading.
WARNING:django.request:Bad Request: /api/group/
INFO:django.utils.autoreload:D:\fyp\Deployed apis\group_chats\api\serializers.py changed, reloading.
WARNING:django.request:Bad Request: /api/group/
INFO:django.utils.autoreload:D:\fyp\Deployed apis\group_chats\api\serializers.py changed, reloading.
INFO:django.utils.autoreload:D:\fyp\Deployed apis\group_chats\api\serializers.py changed, reloading.
WARNING:django.request:Bad Request: /api/group/
INFO:django.utils.autoreload:D:\fyp\Deployed apis\group_chats\api\views.py changed, reloading.
WARNING:django.request:Bad Request: /api/group/
INFO:django.utils.autoreload:D:\fyp\Deployed apis\group_chats\api\serializers.py changed, reloading.
INFO:django.utils.autoreload:D:\fyp\Deployed apis\group_chats\api\views.py changed, reloading.
INFO:django.utils.autoreload:D:\fyp\Deployed apis\group_chats\api\views.py changed, reloading.
WARNING:django.request:Unauthorized: /api/group/
ERROR:django.request:Internal Server Error: /api/group/
Traceback (most recent call last):
  File "C:\Users\.-\AppData\Local\Programs\Python\Python312\Lib\site-packages\django\core\handlers\exception.py", line 55, in inner
    response = get_response(request)
               ^^^^^^^^^^^^^^^^^^^^^
  File "C:\Users\.-\AppData\Local\Programs\Python\Python312\Lib\site-packages\django\core\handlers\base.py", line 197, in _get_response
    response = wrapped_callback(request, *callback_args, **callback_kwargs)
               ^^^^^^^^^^^^^^^^^^^^^^^^^^^^^^^^^^^^^^^^^^^^^^^^^^^^^^^^^^^^
  File "C:\Users\.-\AppData\Local\Programs\Python\Python312\Lib\site-packages\django\views\decorators\csrf.py", line 65, in _view_wrapper
    return view_func(request, *args, **kwargs)
           ^^^^^^^^^^^^^^^^^^^^^^^^^^^^^^^^^^^
  File "C:\Users\.-\AppData\Local\Programs\Python\Python312\Lib\site-packages\django\views\generic\base.py", line 104, in view
    return self.dispatch(request, *args, **kwargs)
           ^^^^^^^^^^^^^^^^^^^^^^^^^^^^^^^^^^^^^^^
  File "C:\Users\.-\AppData\Local\Programs\Python\Python312\Lib\site-packages\rest_framework\views.py", line 509, in dispatch
    response = self.handle_exception(exc)
               ^^^^^^^^^^^^^^^^^^^^^^^^^^
  File "C:\Users\.-\AppData\Local\Programs\Python\Python312\Lib\site-packages\rest_framework\views.py", line 469, in handle_exception
    self.raise_uncaught_exception(exc)
  File "C:\Users\.-\AppData\Local\Programs\Python\Python312\Lib\site-packages\rest_framework\views.py", line 480, in raise_uncaught_exception
    raise exc
  File "C:\Users\.-\AppData\Local\Programs\Python\Python312\Lib\site-packages\rest_framework\views.py", line 506, in dispatch
    response = handler(request, *args, **kwargs)
               ^^^^^^^^^^^^^^^^^^^^^^^^^^^^^^^^^
  File "D:\fyp\Deployed apis\group_chats\api\views.py", line 46, in delete
    if request.user.role == 'Teacher':
       ^^^^^^^^^^^^^^^^^
AttributeError: 'AnonymousUser' object has no attribute 'role'
INFO:django.utils.autoreload:D:\fyp\Deployed apis\group_chats\api\views.py changed, reloading.
WARNING:django.request:Unauthorized: /api/group/
INFO:django.utils.autoreload:D:\fyp\Deployed apis\group_chats\api\views.py changed, reloading.
INFO:django.utils.autoreload:D:\fyp\Deployed apis\group_chats\api\serializers.py changed, reloading.
INFO:django.utils.autoreload:D:\fyp\Deployed apis\group_chats\api\views.py changed, reloading.
INFO:django.utils.autoreload:D:\fyp\Deployed apis\group_chats\api\views.py changed, reloading.
INFO:django.utils.autoreload:D:\fyp\Deployed apis\group_chats\api\views.py changed, reloading.
ERROR:django.request:Internal Server Error: /api/group/
Traceback (most recent call last):
  File "C:\Users\.-\AppData\Local\Programs\Python\Python312\Lib\site-packages\django\core\handlers\exception.py", line 55, in inner
    response = get_response(request)
               ^^^^^^^^^^^^^^^^^^^^^
  File "C:\Users\.-\AppData\Local\Programs\Python\Python312\Lib\site-packages\django\core\handlers\base.py", line 197, in _get_response
    response = wrapped_callback(request, *callback_args, **callback_kwargs)
               ^^^^^^^^^^^^^^^^^^^^^^^^^^^^^^^^^^^^^^^^^^^^^^^^^^^^^^^^^^^^
  File "C:\Users\.-\AppData\Local\Programs\Python\Python312\Lib\site-packages\django\views\decorators\csrf.py", line 65, in _view_wrapper
    return view_func(request, *args, **kwargs)
           ^^^^^^^^^^^^^^^^^^^^^^^^^^^^^^^^^^^
  File "C:\Users\.-\AppData\Local\Programs\Python\Python312\Lib\site-packages\django\views\generic\base.py", line 104, in view
    return self.dispatch(request, *args, **kwargs)
           ^^^^^^^^^^^^^^^^^^^^^^^^^^^^^^^^^^^^^^^
  File "C:\Users\.-\AppData\Local\Programs\Python\Python312\Lib\site-packages\rest_framework\views.py", line 509, in dispatch
    response = self.handle_exception(exc)
               ^^^^^^^^^^^^^^^^^^^^^^^^^^
  File "C:\Users\.-\AppData\Local\Programs\Python\Python312\Lib\site-packages\rest_framework\views.py", line 469, in handle_exception
    self.raise_uncaught_exception(exc)
  File "C:\Users\.-\AppData\Local\Programs\Python\Python312\Lib\site-packages\rest_framework\views.py", line 480, in raise_uncaught_exception
    raise exc
  File "C:\Users\.-\AppData\Local\Programs\Python\Python312\Lib\site-packages\rest_framework\views.py", line 506, in dispatch
    response = handler(request, *args, **kwargs)
               ^^^^^^^^^^^^^^^^^^^^^^^^^^^^^^^^^
  File "D:\fyp\Deployed apis\group_chats\api\views.py", line 33, in get
    instance = GroupChat.objects.get(id=group_id, is_active=True)
               ^^^^^^^^^^^^^^^^^^^^^^^^^^^^^^^^^^^^^^^^^^^^^^^^^^
  File "C:\Users\.-\AppData\Local\Programs\Python\Python312\Lib\site-packages\django\db\models\manager.py", line 87, in manager_method
    return getattr(self.get_queryset(), name)(*args, **kwargs)
           ^^^^^^^^^^^^^^^^^^^^^^^^^^^^^^^^^^^^^^^^^^^^^^^^^^^
  File "C:\Users\.-\AppData\Local\Programs\Python\Python312\Lib\site-packages\django\db\models\query.py", line 649, in get
    raise self.model.DoesNotExist(
group_chats.models.GroupChat.DoesNotExist: GroupChat matching query does not exist.
INFO:django.utils.autoreload:D:\fyp\Deployed apis\group_chats\api\views.py changed, reloading.
ERROR:django.request:Internal Server Error: /api/group/
Traceback (most recent call last):
  File "C:\Users\.-\AppData\Local\Programs\Python\Python312\Lib\site-packages\django\core\handlers\exception.py", line 55, in inner
    response = get_response(request)
               ^^^^^^^^^^^^^^^^^^^^^
  File "C:\Users\.-\AppData\Local\Programs\Python\Python312\Lib\site-packages\django\core\handlers\base.py", line 197, in _get_response
    response = wrapped_callback(request, *callback_args, **callback_kwargs)
               ^^^^^^^^^^^^^^^^^^^^^^^^^^^^^^^^^^^^^^^^^^^^^^^^^^^^^^^^^^^^
  File "C:\Users\.-\AppData\Local\Programs\Python\Python312\Lib\site-packages\django\views\decorators\csrf.py", line 65, in _view_wrapper
    return view_func(request, *args, **kwargs)
           ^^^^^^^^^^^^^^^^^^^^^^^^^^^^^^^^^^^
  File "C:\Users\.-\AppData\Local\Programs\Python\Python312\Lib\site-packages\django\views\generic\base.py", line 104, in view
    return self.dispatch(request, *args, **kwargs)
           ^^^^^^^^^^^^^^^^^^^^^^^^^^^^^^^^^^^^^^^
  File "C:\Users\.-\AppData\Local\Programs\Python\Python312\Lib\site-packages\rest_framework\views.py", line 509, in dispatch
    response = self.handle_exception(exc)
               ^^^^^^^^^^^^^^^^^^^^^^^^^^
  File "C:\Users\.-\AppData\Local\Programs\Python\Python312\Lib\site-packages\rest_framework\views.py", line 469, in handle_exception
    self.raise_uncaught_exception(exc)
  File "C:\Users\.-\AppData\Local\Programs\Python\Python312\Lib\site-packages\rest_framework\views.py", line 480, in raise_uncaught_exception
    raise exc
  File "C:\Users\.-\AppData\Local\Programs\Python\Python312\Lib\site-packages\rest_framework\views.py", line 506, in dispatch
    response = handler(request, *args, **kwargs)
               ^^^^^^^^^^^^^^^^^^^^^^^^^^^^^^^^^
  File "D:\fyp\Deployed apis\group_chats\api\views.py", line 33, in get
    instance = GroupChat.objects.get(id=group_id, is_active=True)
               ^^^^^^^^^^^^^^^^^^^^^^^^^^^^^^^^^^^^^^^^^^^^^^^^^^
  File "C:\Users\.-\AppData\Local\Programs\Python\Python312\Lib\site-packages\django\db\models\manager.py", line 87, in manager_method
    return getattr(self.get_queryset(), name)(*args, **kwargs)
           ^^^^^^^^^^^^^^^^^^^^^^^^^^^^^^^^^^^^^^^^^^^^^^^^^^^
  File "C:\Users\.-\AppData\Local\Programs\Python\Python312\Lib\site-packages\django\db\models\query.py", line 649, in get
    raise self.model.DoesNotExist(
group_chats.models.GroupChat.DoesNotExist: GroupChat matching query does not exist.
INFO:django.utils.autoreload:D:\fyp\Deployed apis\group_chats\api\views.py changed, reloading.
ERROR:django.request:Internal Server Error: /api/group/
Traceback (most recent call last):
  File "C:\Users\.-\AppData\Local\Programs\Python\Python312\Lib\site-packages\django\core\handlers\exception.py", line 55, in inner
    response = get_response(request)
               ^^^^^^^^^^^^^^^^^^^^^
  File "C:\Users\.-\AppData\Local\Programs\Python\Python312\Lib\site-packages\django\core\handlers\base.py", line 197, in _get_response
    response = wrapped_callback(request, *callback_args, **callback_kwargs)
               ^^^^^^^^^^^^^^^^^^^^^^^^^^^^^^^^^^^^^^^^^^^^^^^^^^^^^^^^^^^^
  File "C:\Users\.-\AppData\Local\Programs\Python\Python312\Lib\site-packages\django\views\decorators\csrf.py", line 65, in _view_wrapper
    return view_func(request, *args, **kwargs)
           ^^^^^^^^^^^^^^^^^^^^^^^^^^^^^^^^^^^
  File "C:\Users\.-\AppData\Local\Programs\Python\Python312\Lib\site-packages\django\views\generic\base.py", line 104, in view
    return self.dispatch(request, *args, **kwargs)
           ^^^^^^^^^^^^^^^^^^^^^^^^^^^^^^^^^^^^^^^
  File "C:\Users\.-\AppData\Local\Programs\Python\Python312\Lib\site-packages\rest_framework\views.py", line 509, in dispatch
    response = self.handle_exception(exc)
               ^^^^^^^^^^^^^^^^^^^^^^^^^^
  File "C:\Users\.-\AppData\Local\Programs\Python\Python312\Lib\site-packages\rest_framework\views.py", line 469, in handle_exception
    self.raise_uncaught_exception(exc)
  File "C:\Users\.-\AppData\Local\Programs\Python\Python312\Lib\site-packages\rest_framework\views.py", line 480, in raise_uncaught_exception
    raise exc
  File "C:\Users\.-\AppData\Local\Programs\Python\Python312\Lib\site-packages\rest_framework\views.py", line 506, in dispatch
    response = handler(request, *args, **kwargs)
               ^^^^^^^^^^^^^^^^^^^^^^^^^^^^^^^^^
  File "D:\fyp\Deployed apis\group_chats\api\views.py", line 34, in get
    instance = GroupChat.objects.get(id=group_id, is_active=True)
               ^^^^^^^^^^^^^^^^^^^^^^^^^^^^^^^^^^^^^^^^^^^^^^^^^^
  File "C:\Users\.-\AppData\Local\Programs\Python\Python312\Lib\site-packages\django\db\models\manager.py", line 87, in manager_method
    return getattr(self.get_queryset(), name)(*args, **kwargs)
           ^^^^^^^^^^^^^^^^^^^^^^^^^^^^^^^^^^^^^^^^^^^^^^^^^^^
  File "C:\Users\.-\AppData\Local\Programs\Python\Python312\Lib\site-packages\django\db\models\query.py", line 649, in get
    raise self.model.DoesNotExist(
group_chats.models.GroupChat.DoesNotExist: GroupChat matching query does not exist.
INFO:django.utils.autoreload:D:\fyp\Deployed apis\group_chats\api\views.py changed, reloading.
ERROR:django.request:Internal Server Error: /api/group/
Traceback (most recent call last):
  File "C:\Users\.-\AppData\Local\Programs\Python\Python312\Lib\site-packages\django\core\handlers\exception.py", line 55, in inner
    response = get_response(request)
               ^^^^^^^^^^^^^^^^^^^^^
  File "C:\Users\.-\AppData\Local\Programs\Python\Python312\Lib\site-packages\django\core\handlers\base.py", line 197, in _get_response
    response = wrapped_callback(request, *callback_args, **callback_kwargs)
               ^^^^^^^^^^^^^^^^^^^^^^^^^^^^^^^^^^^^^^^^^^^^^^^^^^^^^^^^^^^^
  File "C:\Users\.-\AppData\Local\Programs\Python\Python312\Lib\site-packages\django\views\decorators\csrf.py", line 65, in _view_wrapper
    return view_func(request, *args, **kwargs)
           ^^^^^^^^^^^^^^^^^^^^^^^^^^^^^^^^^^^
  File "C:\Users\.-\AppData\Local\Programs\Python\Python312\Lib\site-packages\django\views\generic\base.py", line 104, in view
    return self.dispatch(request, *args, **kwargs)
           ^^^^^^^^^^^^^^^^^^^^^^^^^^^^^^^^^^^^^^^
  File "C:\Users\.-\AppData\Local\Programs\Python\Python312\Lib\site-packages\rest_framework\views.py", line 509, in dispatch
    response = self.handle_exception(exc)
               ^^^^^^^^^^^^^^^^^^^^^^^^^^
  File "C:\Users\.-\AppData\Local\Programs\Python\Python312\Lib\site-packages\rest_framework\views.py", line 469, in handle_exception
    self.raise_uncaught_exception(exc)
  File "C:\Users\.-\AppData\Local\Programs\Python\Python312\Lib\site-packages\rest_framework\views.py", line 480, in raise_uncaught_exception
    raise exc
  File "C:\Users\.-\AppData\Local\Programs\Python\Python312\Lib\site-packages\rest_framework\views.py", line 506, in dispatch
    response = handler(request, *args, **kwargs)
               ^^^^^^^^^^^^^^^^^^^^^^^^^^^^^^^^^
  File "D:\fyp\Deployed apis\group_chats\api\views.py", line 35, in get
    instance = GroupChat.objects.get(id=group_id, is_active=True)
               ^^^^^^^^^^^^^^^^^^^^^^^^^^^^^^^^^^^^^^^^^^^^^^^^^^
  File "C:\Users\.-\AppData\Local\Programs\Python\Python312\Lib\site-packages\django\db\models\manager.py", line 87, in manager_method
    return getattr(self.get_queryset(), name)(*args, **kwargs)
           ^^^^^^^^^^^^^^^^^^^^^^^^^^^^^^^^^^^^^^^^^^^^^^^^^^^
  File "C:\Users\.-\AppData\Local\Programs\Python\Python312\Lib\site-packages\django\db\models\query.py", line 649, in get
    raise self.model.DoesNotExist(
group_chats.models.GroupChat.DoesNotExist: GroupChat matching query does not exist.
INFO:django.utils.autoreload:D:\fyp\Deployed apis\group_chats\api\urls.py changed, reloading.
INFO:django.utils.autoreload:D:\fyp\Deployed apis\group_chats\api\views.py changed, reloading.
ERROR:django.request:Internal Server Error: /api/create-group/
Traceback (most recent call last):
  File "C:\Users\.-\AppData\Local\Programs\Python\Python312\Lib\site-packages\django\core\handlers\exception.py", line 55, in inner
    response = get_response(request)
               ^^^^^^^^^^^^^^^^^^^^^
  File "C:\Users\.-\AppData\Local\Programs\Python\Python312\Lib\site-packages\django\core\handlers\base.py", line 197, in _get_response
    response = wrapped_callback(request, *callback_args, **callback_kwargs)
               ^^^^^^^^^^^^^^^^^^^^^^^^^^^^^^^^^^^^^^^^^^^^^^^^^^^^^^^^^^^^
  File "C:\Users\.-\AppData\Local\Programs\Python\Python312\Lib\site-packages\django\views\decorators\csrf.py", line 65, in _view_wrapper
    return view_func(request, *args, **kwargs)
           ^^^^^^^^^^^^^^^^^^^^^^^^^^^^^^^^^^^
  File "C:\Users\.-\AppData\Local\Programs\Python\Python312\Lib\site-packages\django\views\generic\base.py", line 104, in view
    return self.dispatch(request, *args, **kwargs)
           ^^^^^^^^^^^^^^^^^^^^^^^^^^^^^^^^^^^^^^^
  File "C:\Users\.-\AppData\Local\Programs\Python\Python312\Lib\site-packages\rest_framework\views.py", line 509, in dispatch
    response = self.handle_exception(exc)
               ^^^^^^^^^^^^^^^^^^^^^^^^^^
  File "C:\Users\.-\AppData\Local\Programs\Python\Python312\Lib\site-packages\rest_framework\views.py", line 469, in handle_exception
    self.raise_uncaught_exception(exc)
  File "C:\Users\.-\AppData\Local\Programs\Python\Python312\Lib\site-packages\rest_framework\views.py", line 480, in raise_uncaught_exception
    raise exc
  File "C:\Users\.-\AppData\Local\Programs\Python\Python312\Lib\site-packages\rest_framework\views.py", line 506, in dispatch
    response = handler(request, *args, **kwargs)
               ^^^^^^^^^^^^^^^^^^^^^^^^^^^^^^^^^
  File "D:\fyp\Deployed apis\group_chats\api\views.py", line 14, in post
    if serializer.is_valid(raise_exception=True):
       ^^^^^^^^^^^^^^^^^^^^^^^^^^^^^^^^^^^^^^^^^
  File "C:\Users\.-\AppData\Local\Programs\Python\Python312\Lib\site-packages\rest_framework\serializers.py", line 223, in is_valid
    self._validated_data = self.run_validation(self.initial_data)
                           ^^^^^^^^^^^^^^^^^^^^^^^^^^^^^^^^^^^^^^
  File "C:\Users\.-\AppData\Local\Programs\Python\Python312\Lib\site-packages\rest_framework\serializers.py", line 445, in run_validation
    value = self.validate(value)
            ^^^^^^^^^^^^^^^^^^^^
  File "D:\fyp\Deployed apis\group_chats\api\serializers.py", line 13, in validate
    admin_of_chat = attrs.get('admin_of_chat', self.instance.admin_of_chat)
                                               ^^^^^^^^^^^^^^^^^^^^^^^^^^^
AttributeError: 'NoneType' object has no attribute 'admin_of_chat'
INFO:django.utils.autoreload:D:\fyp\Deployed apis\group_chats\api\serializers.py changed, reloading.
INFO:django.utils.autoreload:D:\fyp\Deployed apis\group_chats\api\serializers.py changed, reloading.
INFO:django.utils.autoreload:D:\fyp\Deployed apis\group_chats\api\views.py changed, reloading.
INFO:django.utils.autoreload:D:\fyp\Deployed apis\group_chats\api\views.py changed, reloading.
INFO:django.utils.autoreload:D:\fyp\Deployed apis\group_chats\api\views.py changed, reloading.
WARNING:django.request:Not Found: /api/send-message/
INFO:django.utils.autoreload:D:\fyp\Deployed apis\group_chats\api\views.py changed, reloading.
INFO:django.utils.autoreload:D:\fyp\Deployed apis\group_chats\api\urls.py changed, reloading.
WARNING:django.request:Not Found: /favicon.ico
WARNING:django.request:Not Found: /api/get-message/
WARNING:django.request:Unauthorized: /api/get-messages/
WARNING:django.request:Unauthorized: /api/get-messages/
INFO:django.utils.autoreload:D:\fyp\Deployed apis\group_chats\api\views.py changed, reloading.
INFO:django.utils.autoreload:D:\fyp\Deployed apis\group_chats\api\views.py changed, reloading.
WARNING:django.request:Not Found: /api/get-messages/
INFO:django.utils.autoreload:D:\fyp\Deployed apis\group_chats\api\views.py changed, reloading.
WARNING:django.request:Not Found: /api/get-messages/
INFO:django.utils.autoreload:D:\fyp\Deployed apis\group_chats\api\views.py changed, reloading.
INFO:django.utils.autoreload:D:\fyp\Deployed apis\group_chats\admin.py changed, reloading.
ERROR:django.request:Internal Server Error: /admin/group_chats/groupchat/
Traceback (most recent call last):
  File "C:\Users\.-\AppData\Local\Programs\Python\Python312\Lib\site-packages\django\core\handlers\exception.py", line 55, in inner
    response = get_response(request)
               ^^^^^^^^^^^^^^^^^^^^^
  File "C:\Users\.-\AppData\Local\Programs\Python\Python312\Lib\site-packages\django\core\handlers\base.py", line 197, in _get_response
    response = wrapped_callback(request, *callback_args, **callback_kwargs)
               ^^^^^^^^^^^^^^^^^^^^^^^^^^^^^^^^^^^^^^^^^^^^^^^^^^^^^^^^^^^^
  File "C:\Users\.-\AppData\Local\Programs\Python\Python312\Lib\site-packages\django\contrib\admin\options.py", line 716, in wrapper
    return self.admin_site.admin_view(view)(*args, **kwargs)
           ^^^^^^^^^^^^^^^^^^^^^^^^^^^^^^^^^^^^^^^^^^^^^^^^^
  File "C:\Users\.-\AppData\Local\Programs\Python\Python312\Lib\site-packages\django\utils\decorators.py", line 188, in _view_wrapper
    result = _process_exception(request, e)
             ^^^^^^^^^^^^^^^^^^^^^^^^^^^^^^
  File "C:\Users\.-\AppData\Local\Programs\Python\Python312\Lib\site-packages\django\utils\decorators.py", line 186, in _view_wrapper
    response = view_func(request, *args, **kwargs)
               ^^^^^^^^^^^^^^^^^^^^^^^^^^^^^^^^^^^
  File "C:\Users\.-\AppData\Local\Programs\Python\Python312\Lib\site-packages\django\views\decorators\cache.py", line 80, in _view_wrapper
    response = view_func(request, *args, **kwargs)
               ^^^^^^^^^^^^^^^^^^^^^^^^^^^^^^^^^^^
  File "C:\Users\.-\AppData\Local\Programs\Python\Python312\Lib\site-packages\django\contrib\admin\sites.py", line 240, in inner
    return view(request, *args, **kwargs)
           ^^^^^^^^^^^^^^^^^^^^^^^^^^^^^^
  File "C:\Users\.-\AppData\Local\Programs\Python\Python312\Lib\site-packages\django\utils\decorators.py", line 48, in _wrapper
    return bound_method(*args, **kwargs)
           ^^^^^^^^^^^^^^^^^^^^^^^^^^^^^
  File "C:\Users\.-\AppData\Local\Programs\Python\Python312\Lib\site-packages\django\utils\decorators.py", line 188, in _view_wrapper
    result = _process_exception(request, e)
             ^^^^^^^^^^^^^^^^^^^^^^^^^^^^^^
  File "C:\Users\.-\AppData\Local\Programs\Python\Python312\Lib\site-packages\django\utils\decorators.py", line 186, in _view_wrapper
    response = view_func(request, *args, **kwargs)
               ^^^^^^^^^^^^^^^^^^^^^^^^^^^^^^^^^^^
  File "C:\Users\.-\AppData\Local\Programs\Python\Python312\Lib\site-packages\django\contrib\admin\options.py", line 2122, in changelist_view
    **self.admin_site.each_context(request),
      ^^^^^^^^^^^^^^^^^^^^^^^^^^^^^^^^^^^^^
  File "C:\Users\.-\AppData\Local\Programs\Python\Python312\Lib\site-packages\django\contrib\admin\sites.py", line 335, in each_context
    "available_apps": self.get_app_list(request),
                      ^^^^^^^^^^^^^^^^^^^^^^^^^^
  File "D:\fyp\Deployed apis\accounts\models.py", line 106, in get_app_list
    app['models'].sort(key=lambda x: ordering[x['name']])
  File "D:\fyp\Deployed apis\accounts\models.py", line 106, in <lambda>
    app['models'].sort(key=lambda x: ordering[x['name']])
                                     ~~~~~~~~^^^^^^^^^^^
KeyError: 'Messages'
INFO:django.utils.autoreload:D:\fyp\Deployed apis\accounts\models.py changed, reloading.
ERROR:django.request:Internal Server Error: /admin/group_chats/groupchat/
Traceback (most recent call last):
  File "C:\Users\.-\AppData\Local\Programs\Python\Python312\Lib\site-packages\django\core\handlers\exception.py", line 55, in inner
    response = get_response(request)
               ^^^^^^^^^^^^^^^^^^^^^
  File "C:\Users\.-\AppData\Local\Programs\Python\Python312\Lib\site-packages\django\core\handlers\base.py", line 197, in _get_response
    response = wrapped_callback(request, *callback_args, **callback_kwargs)
               ^^^^^^^^^^^^^^^^^^^^^^^^^^^^^^^^^^^^^^^^^^^^^^^^^^^^^^^^^^^^
  File "C:\Users\.-\AppData\Local\Programs\Python\Python312\Lib\site-packages\django\contrib\admin\options.py", line 716, in wrapper
    return self.admin_site.admin_view(view)(*args, **kwargs)
           ^^^^^^^^^^^^^^^^^^^^^^^^^^^^^^^^^^^^^^^^^^^^^^^^^
  File "C:\Users\.-\AppData\Local\Programs\Python\Python312\Lib\site-packages\django\utils\decorators.py", line 188, in _view_wrapper
    result = _process_exception(request, e)
             ^^^^^^^^^^^^^^^^^^^^^^^^^^^^^^
  File "C:\Users\.-\AppData\Local\Programs\Python\Python312\Lib\site-packages\django\utils\decorators.py", line 186, in _view_wrapper
    response = view_func(request, *args, **kwargs)
               ^^^^^^^^^^^^^^^^^^^^^^^^^^^^^^^^^^^
  File "C:\Users\.-\AppData\Local\Programs\Python\Python312\Lib\site-packages\django\views\decorators\cache.py", line 80, in _view_wrapper
    response = view_func(request, *args, **kwargs)
               ^^^^^^^^^^^^^^^^^^^^^^^^^^^^^^^^^^^
  File "C:\Users\.-\AppData\Local\Programs\Python\Python312\Lib\site-packages\django\contrib\admin\sites.py", line 240, in inner
    return view(request, *args, **kwargs)
           ^^^^^^^^^^^^^^^^^^^^^^^^^^^^^^
  File "C:\Users\.-\AppData\Local\Programs\Python\Python312\Lib\site-packages\django\utils\decorators.py", line 48, in _wrapper
    return bound_method(*args, **kwargs)
           ^^^^^^^^^^^^^^^^^^^^^^^^^^^^^
  File "C:\Users\.-\AppData\Local\Programs\Python\Python312\Lib\site-packages\django\utils\decorators.py", line 188, in _view_wrapper
    result = _process_exception(request, e)
             ^^^^^^^^^^^^^^^^^^^^^^^^^^^^^^
  File "C:\Users\.-\AppData\Local\Programs\Python\Python312\Lib\site-packages\django\utils\decorators.py", line 186, in _view_wrapper
    response = view_func(request, *args, **kwargs)
               ^^^^^^^^^^^^^^^^^^^^^^^^^^^^^^^^^^^
  File "C:\Users\.-\AppData\Local\Programs\Python\Python312\Lib\site-packages\django\contrib\admin\options.py", line 2122, in changelist_view
    **self.admin_site.each_context(request),
      ^^^^^^^^^^^^^^^^^^^^^^^^^^^^^^^^^^^^^
  File "C:\Users\.-\AppData\Local\Programs\Python\Python312\Lib\site-packages\django\contrib\admin\sites.py", line 335, in each_context
    "available_apps": self.get_app_list(request),
                      ^^^^^^^^^^^^^^^^^^^^^^^^^^
  File "D:\fyp\Deployed apis\accounts\models.py", line 107, in get_app_list
    app['models'].sort(key=lambda x: ordering[x['name']])
  File "D:\fyp\Deployed apis\accounts\models.py", line 107, in <lambda>
    app['models'].sort(key=lambda x: ordering[x['name']])
                                     ~~~~~~~~^^^^^^^^^^^
KeyError: 'Messages'
INFO:django.utils.autoreload:D:\fyp\Deployed apis\group_chats\models.py changed, reloading.
INFO:django.utils.autoreload:D:\fyp\Deployed apis\group_chats\api\views.py changed, reloading.
INFO:django.utils.autoreload:D:\fyp\Deployed apis\smartsuite\settings.py changed, reloading.
WARNING:django.request:Not Found: /ws/chat/a1798b25-5745-437b-b7db-06a7005e0ac9
WARNING:django.request:Not Found: /api/ws/chat/a1798b25-5745-437b-b7db-06a7005e0ac9
WARNING:django.request:Not Found: /api/ws/chat/a1798b25-5745-437b-b7db-06a7005e0ac9/
INFO:django.utils.autoreload:D:\fyp\Deployed apis\smartsuite\settings.py changed, reloading.
WARNING:django.request:Not Found: /favicon.ico
INFO:django.utils.autoreload:D:\fyp\Deployed apis\smartsuite\urls.py changed, reloading.
INFO:django.utils.autoreload:D:\fyp\Deployed apis\admin_support\api\views.py changed, reloading.
WARNING:django.request:Not Found: /api/create-ticket/
WARNING:django.request:Bad Request: /api/create-ticket/
WARNING:django.request:Bad Request: /api/create-ticket/
INFO:django.utils.autoreload:D:\fyp\Deployed apis\admin_support\api\serializers.py changed, reloading.
WARNING:django.request:Bad Request: /api/create-ticket/
WARNING:django.request:Bad Request: /api/create-ticket/
WARNING:django.request:Bad Request: /api/create-ticket/
INFO:django.utils.autoreload:D:\fyp\Deployed apis\admin_support\models.py changed, reloading.
ERROR:django.request:Internal Server Error: /api/get-tickets/
Traceback (most recent call last):
  File "C:\Users\.-\AppData\Local\Programs\Python\Python312\Lib\site-packages\django\db\models\fields\__init__.py", line 2752, in to_python
    return uuid.UUID(**{input_form: value})
           ^^^^^^^^^^^^^^^^^^^^^^^^^^^^^^^^
  File "C:\Users\.-\AppData\Local\Programs\Python\Python312\Lib\uuid.py", line 175, in __init__
    hex = hex.replace('urn:', '').replace('uuid:', '')
          ^^^^^^^^^^^
AttributeError: 'AnonymousUser' object has no attribute 'replace'

During handling of the above exception, another exception occurred:

Traceback (most recent call last):
  File "C:\Users\.-\AppData\Local\Programs\Python\Python312\Lib\site-packages\django\core\handlers\exception.py", line 55, in inner
    response = get_response(request)
               ^^^^^^^^^^^^^^^^^^^^^
  File "C:\Users\.-\AppData\Local\Programs\Python\Python312\Lib\site-packages\django\core\handlers\base.py", line 197, in _get_response
    response = wrapped_callback(request, *callback_args, **callback_kwargs)
               ^^^^^^^^^^^^^^^^^^^^^^^^^^^^^^^^^^^^^^^^^^^^^^^^^^^^^^^^^^^^
  File "C:\Users\.-\AppData\Local\Programs\Python\Python312\Lib\site-packages\django\views\decorators\csrf.py", line 65, in _view_wrapper
    return view_func(request, *args, **kwargs)
           ^^^^^^^^^^^^^^^^^^^^^^^^^^^^^^^^^^^
  File "C:\Users\.-\AppData\Local\Programs\Python\Python312\Lib\site-packages\django\views\generic\base.py", line 104, in view
    return self.dispatch(request, *args, **kwargs)
           ^^^^^^^^^^^^^^^^^^^^^^^^^^^^^^^^^^^^^^^
  File "C:\Users\.-\AppData\Local\Programs\Python\Python312\Lib\site-packages\rest_framework\views.py", line 509, in dispatch
    response = self.handle_exception(exc)
               ^^^^^^^^^^^^^^^^^^^^^^^^^^
  File "C:\Users\.-\AppData\Local\Programs\Python\Python312\Lib\site-packages\rest_framework\views.py", line 469, in handle_exception
    self.raise_uncaught_exception(exc)
  File "C:\Users\.-\AppData\Local\Programs\Python\Python312\Lib\site-packages\rest_framework\views.py", line 480, in raise_uncaught_exception
    raise exc
  File "C:\Users\.-\AppData\Local\Programs\Python\Python312\Lib\site-packages\rest_framework\views.py", line 506, in dispatch
    response = handler(request, *args, **kwargs)
               ^^^^^^^^^^^^^^^^^^^^^^^^^^^^^^^^^
  File "D:\fyp\Deployed apis\admin_support\api\views.py", line 18, in get
    tickets = AdminSupport.objects.filter(submit_by=request.user)
              ^^^^^^^^^^^^^^^^^^^^^^^^^^^^^^^^^^^^^^^^^^^^^^^^^^^
  File "C:\Users\.-\AppData\Local\Programs\Python\Python312\Lib\site-packages\django\db\models\manager.py", line 87, in manager_method
    return getattr(self.get_queryset(), name)(*args, **kwargs)
           ^^^^^^^^^^^^^^^^^^^^^^^^^^^^^^^^^^^^^^^^^^^^^^^^^^^
  File "C:\Users\.-\AppData\Local\Programs\Python\Python312\Lib\site-packages\django\db\models\query.py", line 1476, in filter
    return self._filter_or_exclude(False, args, kwargs)
           ^^^^^^^^^^^^^^^^^^^^^^^^^^^^^^^^^^^^^^^^^^^^
  File "C:\Users\.-\AppData\Local\Programs\Python\Python312\Lib\site-packages\django\db\models\query.py", line 1494, in _filter_or_exclude
    clone._filter_or_exclude_inplace(negate, args, kwargs)
  File "C:\Users\.-\AppData\Local\Programs\Python\Python312\Lib\site-packages\django\db\models\query.py", line 1501, in _filter_or_exclude_inplace
    self._query.add_q(Q(*args, **kwargs))
  File "C:\Users\.-\AppData\Local\Programs\Python\Python312\Lib\site-packages\django\db\models\sql\query.py", line 1613, in add_q
    clause, _ = self._add_q(q_object, self.used_aliases)
                ^^^^^^^^^^^^^^^^^^^^^^^^^^^^^^^^^^^^^^^^
  File "C:\Users\.-\AppData\Local\Programs\Python\Python312\Lib\site-packages\django\db\models\sql\query.py", line 1645, in _add_q
    child_clause, needed_inner = self.build_filter(
                                 ^^^^^^^^^^^^^^^^^^
  File "C:\Users\.-\AppData\Local\Programs\Python\Python312\Lib\site-packages\django\db\models\sql\query.py", line 1559, in build_filter
    condition = self.build_lookup(lookups, col, value)
                ^^^^^^^^^^^^^^^^^^^^^^^^^^^^^^^^^^^^^^
  File "C:\Users\.-\AppData\Local\Programs\Python\Python312\Lib\site-packages\django\db\models\sql\query.py", line 1389, in build_lookup
    lookup = lookup_class(lhs, rhs)
             ^^^^^^^^^^^^^^^^^^^^^^
  File "C:\Users\.-\AppData\Local\Programs\Python\Python312\Lib\site-packages\django\db\models\lookups.py", line 30, in __init__
    self.rhs = self.get_prep_lookup()
               ^^^^^^^^^^^^^^^^^^^^^^
  File "C:\Users\.-\AppData\Local\Programs\Python\Python312\Lib\site-packages\django\db\models\fields\related_lookups.py", line 156, in get_prep_lookup
    self.rhs = target_field.get_prep_value(self.rhs)
               ^^^^^^^^^^^^^^^^^^^^^^^^^^^^^^^^^^^^^
  File "C:\Users\.-\AppData\Local\Programs\Python\Python312\Lib\site-packages\django\db\models\fields\__init__.py", line 2736, in get_prep_value
    return self.to_python(value)
           ^^^^^^^^^^^^^^^^^^^^^
  File "C:\Users\.-\AppData\Local\Programs\Python\Python312\Lib\site-packages\django\db\models\fields\__init__.py", line 2754, in to_python
    raise exceptions.ValidationError(
django.core.exceptions.ValidationError: ['AnonymousUser is not a valid UUID.']
INFO:django.utils.autoreload:D:\fyp\Deployed apis\admin_support\api\serializers.py changed, reloading.
INFO:django.utils.autoreload:D:\fyp\Deployed apis\admin_support\api\serializers.py changed, reloading.
WARNING:django.request:Not Found: /api/create-message
WARNING:django.request:Not Found: /api/create-ticket-chat/
WARNING:django.request:Bad Request: /api/create-ticket-chat/
INFO:django.utils.autoreload:D:\fyp\Deployed apis\admin_support\api\serializers.py changed, reloading.
ERROR:django.request:Internal Server Error: /api/create-ticket-chat/
Traceback (most recent call last):
  File "C:\Users\.-\AppData\Local\Programs\Python\Python312\Lib\site-packages\django\core\handlers\exception.py", line 55, in inner
    response = get_response(request)
               ^^^^^^^^^^^^^^^^^^^^^
  File "C:\Users\.-\AppData\Local\Programs\Python\Python312\Lib\site-packages\django\core\handlers\base.py", line 197, in _get_response
    response = wrapped_callback(request, *callback_args, **callback_kwargs)
               ^^^^^^^^^^^^^^^^^^^^^^^^^^^^^^^^^^^^^^^^^^^^^^^^^^^^^^^^^^^^
  File "C:\Users\.-\AppData\Local\Programs\Python\Python312\Lib\site-packages\django\views\decorators\csrf.py", line 65, in _view_wrapper
    return view_func(request, *args, **kwargs)
           ^^^^^^^^^^^^^^^^^^^^^^^^^^^^^^^^^^^
  File "C:\Users\.-\AppData\Local\Programs\Python\Python312\Lib\site-packages\django\views\generic\base.py", line 104, in view
    return self.dispatch(request, *args, **kwargs)
           ^^^^^^^^^^^^^^^^^^^^^^^^^^^^^^^^^^^^^^^
  File "C:\Users\.-\AppData\Local\Programs\Python\Python312\Lib\site-packages\rest_framework\views.py", line 509, in dispatch
    response = self.handle_exception(exc)
               ^^^^^^^^^^^^^^^^^^^^^^^^^^
  File "C:\Users\.-\AppData\Local\Programs\Python\Python312\Lib\site-packages\rest_framework\views.py", line 469, in handle_exception
    self.raise_uncaught_exception(exc)
  File "C:\Users\.-\AppData\Local\Programs\Python\Python312\Lib\site-packages\rest_framework\views.py", line 480, in raise_uncaught_exception
    raise exc
  File "C:\Users\.-\AppData\Local\Programs\Python\Python312\Lib\site-packages\rest_framework\views.py", line 506, in dispatch
    response = handler(request, *args, **kwargs)
               ^^^^^^^^^^^^^^^^^^^^^^^^^^^^^^^^^
  File "D:\fyp\Deployed apis\admin_support\api\views.py", line 32, in post
    serializer.save(sender=request.user)
  File "C:\Users\.-\AppData\Local\Programs\Python\Python312\Lib\site-packages\rest_framework\serializers.py", line 208, in save
    self.instance = self.create(validated_data)
                    ^^^^^^^^^^^^^^^^^^^^^^^^^^^
  File "D:\fyp\Deployed apis\admin_support\api\serializers.py", line 25, in create
    user = self.context.get('request').user
           ^^^^^^^^^^^^^^^^^^^^^^^^^^^^^^^^
AttributeError: 'NoneType' object has no attribute 'user'
INFO:django.utils.autoreload:D:\fyp\Deployed apis\admin_support\api\views.py changed, reloading.
WARNING:django.request:Not Found: /api/get-ticket-chat/
INFO:django.utils.autoreload:D:\fyp\Deployed apis\admin_support\api\views.py changed, reloading.
WARNING:django.request:Not Found: /api/get-ticket-chat/
INFO:django.utils.autoreload:D:\fyp\Deployed apis\admin_support\api\views.py changed, reloading.
ERROR:django.request:Internal Server Error: /api/create-ticket-chat/
Traceback (most recent call last):
  File "C:\Users\.-\AppData\Local\Programs\Python\Python312\Lib\site-packages\django\core\handlers\exception.py", line 55, in inner
    response = get_response(request)
               ^^^^^^^^^^^^^^^^^^^^^
  File "C:\Users\.-\AppData\Local\Programs\Python\Python312\Lib\site-packages\django\core\handlers\base.py", line 197, in _get_response
    response = wrapped_callback(request, *callback_args, **callback_kwargs)
               ^^^^^^^^^^^^^^^^^^^^^^^^^^^^^^^^^^^^^^^^^^^^^^^^^^^^^^^^^^^^
  File "C:\Users\.-\AppData\Local\Programs\Python\Python312\Lib\site-packages\django\views\decorators\csrf.py", line 65, in _view_wrapper
    return view_func(request, *args, **kwargs)
           ^^^^^^^^^^^^^^^^^^^^^^^^^^^^^^^^^^^
  File "C:\Users\.-\AppData\Local\Programs\Python\Python312\Lib\site-packages\django\views\generic\base.py", line 104, in view
    return self.dispatch(request, *args, **kwargs)
           ^^^^^^^^^^^^^^^^^^^^^^^^^^^^^^^^^^^^^^^
  File "C:\Users\.-\AppData\Local\Programs\Python\Python312\Lib\site-packages\rest_framework\views.py", line 509, in dispatch
    response = self.handle_exception(exc)
               ^^^^^^^^^^^^^^^^^^^^^^^^^^
  File "C:\Users\.-\AppData\Local\Programs\Python\Python312\Lib\site-packages\rest_framework\views.py", line 469, in handle_exception
    self.raise_uncaught_exception(exc)
  File "C:\Users\.-\AppData\Local\Programs\Python\Python312\Lib\site-packages\rest_framework\views.py", line 480, in raise_uncaught_exception
    raise exc
  File "C:\Users\.-\AppData\Local\Programs\Python\Python312\Lib\site-packages\rest_framework\views.py", line 506, in dispatch
    response = handler(request, *args, **kwargs)
               ^^^^^^^^^^^^^^^^^^^^^^^^^^^^^^^^^
  File "D:\fyp\Deployed apis\admin_support\api\views.py", line 32, in post
    serializer.save(sender=request.user)
  File "C:\Users\.-\AppData\Local\Programs\Python\Python312\Lib\site-packages\rest_framework\serializers.py", line 208, in save
    self.instance = self.create(validated_data)
                    ^^^^^^^^^^^^^^^^^^^^^^^^^^^
  File "D:\fyp\Deployed apis\admin_support\api\serializers.py", line 28, in create
    ticket = AdminSupport.objects.get(ticket_id=ticket_id)
             ^^^^^^^^^^^^^^^^^^^^^^^^^^^^^^^^^^^^^^^^^^^^^
  File "C:\Users\.-\AppData\Local\Programs\Python\Python312\Lib\site-packages\django\db\models\manager.py", line 87, in manager_method
    return getattr(self.get_queryset(), name)(*args, **kwargs)
           ^^^^^^^^^^^^^^^^^^^^^^^^^^^^^^^^^^^^^^^^^^^^^^^^^^^
  File "C:\Users\.-\AppData\Local\Programs\Python\Python312\Lib\site-packages\django\db\models\query.py", line 649, in get
    raise self.model.DoesNotExist(
admin_support.models.AdminSupport.DoesNotExist: AdminSupport matching query does not exist.
INFO:django.utils.autoreload:D:\fyp\Deployed apis\admin_support\api\serializers.py changed, reloading.
ERROR:django.request:Internal Server Error: /api/create-ticket-chat/
Traceback (most recent call last):
  File "C:\Users\.-\AppData\Local\Programs\Python\Python312\Lib\site-packages\django\core\handlers\exception.py", line 55, in inner
    response = get_response(request)
               ^^^^^^^^^^^^^^^^^^^^^
  File "C:\Users\.-\AppData\Local\Programs\Python\Python312\Lib\site-packages\django\core\handlers\base.py", line 197, in _get_response
    response = wrapped_callback(request, *callback_args, **callback_kwargs)
               ^^^^^^^^^^^^^^^^^^^^^^^^^^^^^^^^^^^^^^^^^^^^^^^^^^^^^^^^^^^^
  File "C:\Users\.-\AppData\Local\Programs\Python\Python312\Lib\site-packages\django\views\decorators\csrf.py", line 65, in _view_wrapper
    return view_func(request, *args, **kwargs)
           ^^^^^^^^^^^^^^^^^^^^^^^^^^^^^^^^^^^
  File "C:\Users\.-\AppData\Local\Programs\Python\Python312\Lib\site-packages\django\views\generic\base.py", line 104, in view
    return self.dispatch(request, *args, **kwargs)
           ^^^^^^^^^^^^^^^^^^^^^^^^^^^^^^^^^^^^^^^
  File "C:\Users\.-\AppData\Local\Programs\Python\Python312\Lib\site-packages\rest_framework\views.py", line 509, in dispatch
    response = self.handle_exception(exc)
               ^^^^^^^^^^^^^^^^^^^^^^^^^^
  File "C:\Users\.-\AppData\Local\Programs\Python\Python312\Lib\site-packages\rest_framework\views.py", line 469, in handle_exception
    self.raise_uncaught_exception(exc)
  File "C:\Users\.-\AppData\Local\Programs\Python\Python312\Lib\site-packages\rest_framework\views.py", line 480, in raise_uncaught_exception
    raise exc
  File "C:\Users\.-\AppData\Local\Programs\Python\Python312\Lib\site-packages\rest_framework\views.py", line 506, in dispatch
    response = handler(request, *args, **kwargs)
               ^^^^^^^^^^^^^^^^^^^^^^^^^^^^^^^^^
  File "D:\fyp\Deployed apis\admin_support\api\views.py", line 32, in post
    serializer.save(sender=request.user)
  File "C:\Users\.-\AppData\Local\Programs\Python\Python312\Lib\site-packages\rest_framework\serializers.py", line 208, in save
    self.instance = self.create(validated_data)
                    ^^^^^^^^^^^^^^^^^^^^^^^^^^^
  File "D:\fyp\Deployed apis\admin_support\api\serializers.py", line 29, in create
    ticket = AdminSupport.objects.get(id=ticket_id)
             ^^^^^^^^^^^^^^^^^^^^^^^^^^^^^^^^^^^^^^
  File "C:\Users\.-\AppData\Local\Programs\Python\Python312\Lib\site-packages\django\db\models\manager.py", line 87, in manager_method
    return getattr(self.get_queryset(), name)(*args, **kwargs)
           ^^^^^^^^^^^^^^^^^^^^^^^^^^^^^^^^^^^^^^^^^^^^^^^^^^^
  File "C:\Users\.-\AppData\Local\Programs\Python\Python312\Lib\site-packages\django\db\models\query.py", line 649, in get
    raise self.model.DoesNotExist(
admin_support.models.AdminSupport.DoesNotExist: AdminSupport matching query does not exist.
INFO:django.utils.autoreload:D:\fyp\Deployed apis\admin_support\api\serializers.py changed, reloading.
ERROR:django.request:Internal Server Error: /api/create-ticket-chat/
Traceback (most recent call last):
  File "C:\Users\.-\AppData\Local\Programs\Python\Python312\Lib\site-packages\django\core\handlers\exception.py", line 55, in inner
    response = get_response(request)
               ^^^^^^^^^^^^^^^^^^^^^
  File "C:\Users\.-\AppData\Local\Programs\Python\Python312\Lib\site-packages\django\core\handlers\base.py", line 197, in _get_response
    response = wrapped_callback(request, *callback_args, **callback_kwargs)
               ^^^^^^^^^^^^^^^^^^^^^^^^^^^^^^^^^^^^^^^^^^^^^^^^^^^^^^^^^^^^
  File "C:\Users\.-\AppData\Local\Programs\Python\Python312\Lib\site-packages\django\views\decorators\csrf.py", line 65, in _view_wrapper
    return view_func(request, *args, **kwargs)
           ^^^^^^^^^^^^^^^^^^^^^^^^^^^^^^^^^^^
  File "C:\Users\.-\AppData\Local\Programs\Python\Python312\Lib\site-packages\django\views\generic\base.py", line 104, in view
    return self.dispatch(request, *args, **kwargs)
           ^^^^^^^^^^^^^^^^^^^^^^^^^^^^^^^^^^^^^^^
  File "C:\Users\.-\AppData\Local\Programs\Python\Python312\Lib\site-packages\rest_framework\views.py", line 509, in dispatch
    response = self.handle_exception(exc)
               ^^^^^^^^^^^^^^^^^^^^^^^^^^
  File "C:\Users\.-\AppData\Local\Programs\Python\Python312\Lib\site-packages\rest_framework\views.py", line 469, in handle_exception
    self.raise_uncaught_exception(exc)
  File "C:\Users\.-\AppData\Local\Programs\Python\Python312\Lib\site-packages\rest_framework\views.py", line 480, in raise_uncaught_exception
    raise exc
  File "C:\Users\.-\AppData\Local\Programs\Python\Python312\Lib\site-packages\rest_framework\views.py", line 506, in dispatch
    response = handler(request, *args, **kwargs)
               ^^^^^^^^^^^^^^^^^^^^^^^^^^^^^^^^^
  File "D:\fyp\Deployed apis\admin_support\api\views.py", line 32, in post
    serializer.save(sender=request.user)
  File "C:\Users\.-\AppData\Local\Programs\Python\Python312\Lib\site-packages\rest_framework\serializers.py", line 208, in save
    self.instance = self.create(validated_data)
                    ^^^^^^^^^^^^^^^^^^^^^^^^^^^
  File "D:\fyp\Deployed apis\admin_support\api\serializers.py", line 29, in create
    ticket = AdminSupport.objects.get(id=ticket_id)
             ^^^^^^^^^^^^^^^^^^^^^^^^^^^^^^^^^^^^^^
  File "C:\Users\.-\AppData\Local\Programs\Python\Python312\Lib\site-packages\django\db\models\manager.py", line 87, in manager_method
    return getattr(self.get_queryset(), name)(*args, **kwargs)
           ^^^^^^^^^^^^^^^^^^^^^^^^^^^^^^^^^^^^^^^^^^^^^^^^^^^
  File "C:\Users\.-\AppData\Local\Programs\Python\Python312\Lib\site-packages\django\db\models\query.py", line 649, in get
    raise self.model.DoesNotExist(
admin_support.models.AdminSupport.DoesNotExist: AdminSupport matching query does not exist.
INFO:django.utils.autoreload:D:\fyp\Deployed apis\admin_support\api\serializers.py changed, reloading.
ERROR:django.request:Internal Server Error: /api/create-ticket-chat/
Traceback (most recent call last):
  File "C:\Users\.-\AppData\Local\Programs\Python\Python312\Lib\site-packages\django\db\models\fields\__init__.py", line 2752, in to_python
    return uuid.UUID(**{input_form: value})
           ^^^^^^^^^^^^^^^^^^^^^^^^^^^^^^^^
  File "C:\Users\.-\AppData\Local\Programs\Python\Python312\Lib\uuid.py", line 175, in __init__
    hex = hex.replace('urn:', '').replace('uuid:', '')
          ^^^^^^^^^^^
AttributeError: 'AdminSupport' object has no attribute 'replace'

During handling of the above exception, another exception occurred:

Traceback (most recent call last):
  File "C:\Users\.-\AppData\Local\Programs\Python\Python312\Lib\site-packages\django\core\handlers\exception.py", line 55, in inner
    response = get_response(request)
               ^^^^^^^^^^^^^^^^^^^^^
  File "C:\Users\.-\AppData\Local\Programs\Python\Python312\Lib\site-packages\django\core\handlers\base.py", line 197, in _get_response
    response = wrapped_callback(request, *callback_args, **callback_kwargs)
               ^^^^^^^^^^^^^^^^^^^^^^^^^^^^^^^^^^^^^^^^^^^^^^^^^^^^^^^^^^^^
  File "C:\Users\.-\AppData\Local\Programs\Python\Python312\Lib\site-packages\django\views\decorators\csrf.py", line 65, in _view_wrapper
    return view_func(request, *args, **kwargs)
           ^^^^^^^^^^^^^^^^^^^^^^^^^^^^^^^^^^^
  File "C:\Users\.-\AppData\Local\Programs\Python\Python312\Lib\site-packages\django\views\generic\base.py", line 104, in view
    return self.dispatch(request, *args, **kwargs)
           ^^^^^^^^^^^^^^^^^^^^^^^^^^^^^^^^^^^^^^^
  File "C:\Users\.-\AppData\Local\Programs\Python\Python312\Lib\site-packages\rest_framework\views.py", line 509, in dispatch
    response = self.handle_exception(exc)
               ^^^^^^^^^^^^^^^^^^^^^^^^^^
  File "C:\Users\.-\AppData\Local\Programs\Python\Python312\Lib\site-packages\rest_framework\views.py", line 469, in handle_exception
    self.raise_uncaught_exception(exc)
  File "C:\Users\.-\AppData\Local\Programs\Python\Python312\Lib\site-packages\rest_framework\views.py", line 480, in raise_uncaught_exception
    raise exc
  File "C:\Users\.-\AppData\Local\Programs\Python\Python312\Lib\site-packages\rest_framework\views.py", line 506, in dispatch
    response = handler(request, *args, **kwargs)
               ^^^^^^^^^^^^^^^^^^^^^^^^^^^^^^^^^
  File "D:\fyp\Deployed apis\admin_support\api\views.py", line 32, in post
    serializer.save(sender=request.user)
  File "C:\Users\.-\AppData\Local\Programs\Python\Python312\Lib\site-packages\rest_framework\serializers.py", line 208, in save
    self.instance = self.create(validated_data)
                    ^^^^^^^^^^^^^^^^^^^^^^^^^^^
  File "D:\fyp\Deployed apis\admin_support\api\serializers.py", line 29, in create
    ticket = AdminSupport.objects.get(id=ticket_id)
             ^^^^^^^^^^^^^^^^^^^^^^^^^^^^^^^^^^^^^^
  File "C:\Users\.-\AppData\Local\Programs\Python\Python312\Lib\site-packages\django\db\models\manager.py", line 87, in manager_method
    return getattr(self.get_queryset(), name)(*args, **kwargs)
           ^^^^^^^^^^^^^^^^^^^^^^^^^^^^^^^^^^^^^^^^^^^^^^^^^^^
  File "C:\Users\.-\AppData\Local\Programs\Python\Python312\Lib\site-packages\django\db\models\query.py", line 635, in get
    clone = self._chain() if self.query.combinator else self.filter(*args, **kwargs)
                                                        ^^^^^^^^^^^^^^^^^^^^^^^^^^^^
  File "C:\Users\.-\AppData\Local\Programs\Python\Python312\Lib\site-packages\django\db\models\query.py", line 1476, in filter
    return self._filter_or_exclude(False, args, kwargs)
           ^^^^^^^^^^^^^^^^^^^^^^^^^^^^^^^^^^^^^^^^^^^^
  File "C:\Users\.-\AppData\Local\Programs\Python\Python312\Lib\site-packages\django\db\models\query.py", line 1494, in _filter_or_exclude
    clone._filter_or_exclude_inplace(negate, args, kwargs)
  File "C:\Users\.-\AppData\Local\Programs\Python\Python312\Lib\site-packages\django\db\models\query.py", line 1501, in _filter_or_exclude_inplace
    self._query.add_q(Q(*args, **kwargs))
  File "C:\Users\.-\AppData\Local\Programs\Python\Python312\Lib\site-packages\django\db\models\sql\query.py", line 1613, in add_q
    clause, _ = self._add_q(q_object, self.used_aliases)
                ^^^^^^^^^^^^^^^^^^^^^^^^^^^^^^^^^^^^^^^^
  File "C:\Users\.-\AppData\Local\Programs\Python\Python312\Lib\site-packages\django\db\models\sql\query.py", line 1645, in _add_q
    child_clause, needed_inner = self.build_filter(
                                 ^^^^^^^^^^^^^^^^^^
  File "C:\Users\.-\AppData\Local\Programs\Python\Python312\Lib\site-packages\django\db\models\sql\query.py", line 1559, in build_filter
    condition = self.build_lookup(lookups, col, value)
                ^^^^^^^^^^^^^^^^^^^^^^^^^^^^^^^^^^^^^^
  File "C:\Users\.-\AppData\Local\Programs\Python\Python312\Lib\site-packages\django\db\models\sql\query.py", line 1389, in build_lookup
    lookup = lookup_class(lhs, rhs)
             ^^^^^^^^^^^^^^^^^^^^^^
  File "C:\Users\.-\AppData\Local\Programs\Python\Python312\Lib\site-packages\django\db\models\lookups.py", line 30, in __init__
    self.rhs = self.get_prep_lookup()
               ^^^^^^^^^^^^^^^^^^^^^^
  File "C:\Users\.-\AppData\Local\Programs\Python\Python312\Lib\site-packages\django\db\models\lookups.py", line 364, in get_prep_lookup
    return super().get_prep_lookup()
           ^^^^^^^^^^^^^^^^^^^^^^^^^
  File "C:\Users\.-\AppData\Local\Programs\Python\Python312\Lib\site-packages\django\db\models\lookups.py", line 88, in get_prep_lookup
    return self.lhs.output_field.get_prep_value(self.rhs)
           ^^^^^^^^^^^^^^^^^^^^^^^^^^^^^^^^^^^^^^^^^^^^^^
  File "C:\Users\.-\AppData\Local\Programs\Python\Python312\Lib\site-packages\django\db\models\fields\__init__.py", line 2736, in get_prep_value
    return self.to_python(value)
           ^^^^^^^^^^^^^^^^^^^^^
  File "C:\Users\.-\AppData\Local\Programs\Python\Python312\Lib\site-packages\django\db\models\fields\__init__.py", line 2754, in to_python
    raise exceptions.ValidationError(
django.core.exceptions.ValidationError: ['TK#1212 has status Pending is not a valid UUID.']
INFO:django.utils.autoreload:D:\fyp\Deployed apis\admin_support\api\serializers.py changed, reloading.
INFO:django.utils.autoreload:D:\fyp\Deployed apis\admin_support\api\serializers.py changed, reloading.

INFO:django.utils.autoreload:D:\fyp\Deployed apis\admin_support\api\views.py changed, reloading.
INFO:django.utils.autoreload:D:\fyp\Deployed apis\admin_support\api\views.py changed, reloading.
INFO:django.utils.autoreload:D:\fyp\Deployed apis\admin_support\api\views.py changed, reloading.
WARNING:django.request:Not Found: /ws/chat/a1798b25-5745-437b-b7db-06a7005e0ac9/
WARNING:django.request:Not Found: /favicon.ico/
WARNING:django.request:Unauthorized: /api/create-group/
WARNING:django.request:Unauthorized: /api/login/
WARNING:django.request:Bad Request: /api/create-group/
WARNING:django.request:Not Found: /ws/chat/e6190b4e-907c-4494-a619-ccbfd05e76ac/
WARNING:django.request:Not Found: /ws/chat/e6190b4e-907c-4494-a619-ccbfd05e76ac/
WARNING:django.request:Not Found: /ws/chat/e6190b4e-907c-4494-a619-ccbfd05e76ac/
WARNING:django.request:Not Found: /ws/chat/e6190b4e-907c-4494-a619-ccbfd05e76ac/
WARNING:django.request:Not Found: /ws/chat/e6190b4e-907c-4494-a619-ccbfd05e76ac/
INFO:django.utils.autoreload:/home/shariq/HS/smartsuiteapisdeployment/smartsuite/settings.py changed, reloading.
INFO:django.utils.autoreload:D:\fyp\Deployed apis\group_chats\api\serializers.py changed, reloading.
INFO:django.utils.autoreload:D:\fyp\Deployed apis\group_chats\api\serializers.py changed, reloading.
INFO:django.utils.autoreload:D:\fyp\Deployed apis\group_chats\api\views.py changed, reloading.
INFO:django.utils.autoreload:D:\fyp\Deployed apis\group_chats\api\views.py changed, reloading.
INFO:django.utils.autoreload:D:\fyp\Deployed apis\group_chats\api\views.py changed, reloading.
INFO:django.utils.autoreload:D:\fyp\Deployed apis\group_chats\api\urls.py changed, reloading.
INFO:django.utils.autoreload:D:\fyp\Deployed apis\group_chats\api\views.py changed, reloading.
INFO:django.utils.autoreload:D:\fyp\Deployed apis\group_chats\api\views.py changed, reloading.
INFO:django.utils.autoreload:D:\fyp\Deployed apis\group_chats\api\serializers.py changed, reloading.
INFO:django.utils.autoreload:D:\fyp\Deployed apis\group_chats\api\serializers.py changed, reloading.
INFO:django.utils.autoreload:D:\fyp\Deployed apis\group_chats\api\serializers.py changed, reloading.
WARNING:django.request:Bad Request: /api/select-group-members/
INFO:django.utils.autoreload:D:\fyp\Deployed apis\group_chats\api\views.py changed, reloading.
INFO:django.utils.autoreload:D:\fyp\Deployed apis\subjects\api\serializers.py changed, reloading.
INFO:django.utils.autoreload:D:\fyp\Deployed apis\subjects\api\serializers.py changed, reloading.
INFO:django.utils.autoreload:D:\fyp\Deployed apis\subjects\api\serializers.py changed, reloading.
INFO:django.utils.autoreload:D:\fyp\Deployed apis\group_chats\api\serializers.py changed, reloading.
INFO:django.utils.autoreload:D:\fyp\Deployed apis\group_chats\api\serializers.py changed, reloading.
INFO:django.utils.autoreload:D:\fyp\Deployed apis\group_chats\api\serializers.py changed, reloading.
INFO:django.utils.autoreload:D:\fyp\Deployed apis\notifications\models.py changed, reloading.
INFO:django.utils.autoreload:D:\fyp\Deployed apis\smartsuite\urls.py changed, reloading.
INFO:django.utils.autoreload:D:\fyp\Deployed apis\notifications\api\views.py changed, reloading.
INFO:django.utils.autoreload:D:\fyp\Deployed apis\subjects\api\views.py changed, reloading.
INFO:django.utils.autoreload:D:\fyp\Deployed apis\subjects\api\thread.py changed, reloading.
INFO:django.utils.autoreload:D:\fyp\Deployed apis\subjects\api\views.py changed, reloading.
                                                                                                                                                                                                                                                                                                                                                                                      INFO:django.utils.autoreload:D:\fyp\Deployed apis\subjects\api\views.py changed, reloading.
INFO:django.utils.autoreload:D:\fyp\Deployed apis\group_chats\api\serializers.py changed, reloading.
INFO:django.utils.autoreload:D:\fyp\Deployed apis\group_chats\api\serializers.py changed, reloading.
INFO:django.utils.autoreload:D:\fyp\Deployed apis\group_chats\api\serializers.py changed, reloading.
INFO:django.utils.autoreload:D:\fyp\Deployed apis\group_chats\api\serializers.py changed, reloading.
INFO:django.utils.autoreload:D:\fyp\Deployed apis\group_chats\api\serializers.py changed, reloading.
INFO:django.utils.autoreload:D:\fyp\Deployed apis\group_chats\api\serializers.py changed, reloading.
INFO:django.utils.autoreload:D:\fyp\Deployed apis\group_chats\api\views.py changed, reloading.
ERROR:django.request:Internal Server Error: /api/groups/
Traceback (most recent call last):
  File "C:\Users\.-\AppData\Local\Programs\Python\Python312\Lib\site-packages\django\core\handlers\exception.py", line 55, in inner
    response = get_response(request)
               ^^^^^^^^^^^^^^^^^^^^^
  File "C:\Users\.-\AppData\Local\Programs\Python\Python312\Lib\site-packages\django\core\handlers\base.py", line 197, in _get_response
    response = wrapped_callback(request, *callback_args, **callback_kwargs)
               ^^^^^^^^^^^^^^^^^^^^^^^^^^^^^^^^^^^^^^^^^^^^^^^^^^^^^^^^^^^^
  File "C:\Users\.-\AppData\Local\Programs\Python\Python312\Lib\site-packages\django\views\decorators\csrf.py", line 65, in _view_wrapper
    return view_func(request, *args, **kwargs)
           ^^^^^^^^^^^^^^^^^^^^^^^^^^^^^^^^^^^
  File "C:\Users\.-\AppData\Local\Programs\Python\Python312\Lib\site-packages\django\views\generic\base.py", line 104, in view
    return self.dispatch(request, *args, **kwargs)
           ^^^^^^^^^^^^^^^^^^^^^^^^^^^^^^^^^^^^^^^
  File "C:\Users\.-\AppData\Local\Programs\Python\Python312\Lib\site-packages\rest_framework\views.py", line 509, in dispatch
    response = self.handle_exception(exc)
               ^^^^^^^^^^^^^^^^^^^^^^^^^^
  File "C:\Users\.-\AppData\Local\Programs\Python\Python312\Lib\site-packages\rest_framework\views.py", line 469, in handle_exception
    self.raise_uncaught_exception(exc)
  File "C:\Users\.-\AppData\Local\Programs\Python\Python312\Lib\site-packages\rest_framework\views.py", line 480, in raise_uncaught_exception
    raise exc
  File "C:\Users\.-\AppData\Local\Programs\Python\Python312\Lib\site-packages\rest_framework\views.py", line 506, in dispatch
    response = handler(request, *args, **kwargs)
               ^^^^^^^^^^^^^^^^^^^^^^^^^^^^^^^^^
  File "D:\fyp\Deployed apis\group_chats\api\views.py", line 33, in get
    response = serializer.get(query_set, many=True)
               ^^^^^^^^^^^^^^^^^^^^^^^^^^^^^^^^^^^^
TypeError: ChatGroupSerializer.get() got an unexpected keyword argument 'many'
INFO:django.utils.autoreload:D:\fyp\Deployed apis\group_chats\api\views.py changed, reloading.
INFO:django.utils.autoreload:D:\fyp\Deployed apis\group_chats\api\views.py changed, reloading.
ERROR:django.request:Internal Server Error: /api/group/
Traceback (most recent call last):
  File "C:\Users\.-\AppData\Local\Programs\Python\Python312\Lib\site-packages\django\core\handlers\exception.py", line 55, in inner
    response = get_response(request)
               ^^^^^^^^^^^^^^^^^^^^^
  File "C:\Users\.-\AppData\Local\Programs\Python\Python312\Lib\site-packages\django\core\handlers\base.py", line 197, in _get_response
    response = wrapped_callback(request, *callback_args, **callback_kwargs)
               ^^^^^^^^^^^^^^^^^^^^^^^^^^^^^^^^^^^^^^^^^^^^^^^^^^^^^^^^^^^^
  File "C:\Users\.-\AppData\Local\Programs\Python\Python312\Lib\site-packages\django\views\decorators\csrf.py", line 65, in _view_wrapper
    return view_func(request, *args, **kwargs)
           ^^^^^^^^^^^^^^^^^^^^^^^^^^^^^^^^^^^
  File "C:\Users\.-\AppData\Local\Programs\Python\Python312\Lib\site-packages\django\views\generic\base.py", line 104, in view
    return self.dispatch(request, *args, **kwargs)
           ^^^^^^^^^^^^^^^^^^^^^^^^^^^^^^^^^^^^^^^
  File "C:\Users\.-\AppData\Local\Programs\Python\Python312\Lib\site-packages\rest_framework\views.py", line 509, in dispatch
    response = self.handle_exception(exc)
               ^^^^^^^^^^^^^^^^^^^^^^^^^^
  File "C:\Users\.-\AppData\Local\Programs\Python\Python312\Lib\site-packages\rest_framework\views.py", line 469, in handle_exception
    self.raise_uncaught_exception(exc)
  File "C:\Users\.-\AppData\Local\Programs\Python\Python312\Lib\site-packages\rest_framework\views.py", line 480, in raise_uncaught_exception
    raise exc
  File "C:\Users\.-\AppData\Local\Programs\Python\Python312\Lib\site-packages\rest_framework\views.py", line 506, in dispatch
    response = handler(request, *args, **kwargs)
               ^^^^^^^^^^^^^^^^^^^^^^^^^^^^^^^^^
  File "D:\fyp\Deployed apis\group_chats\api\views.py", line 44, in get
    instance = GroupChat.objects.get(id=group_id, is_active=True)
               ^^^^^^^^^^^^^^^^^^^^^^^^^^^^^^^^^^^^^^^^^^^^^^^^^^
  File "C:\Users\.-\AppData\Local\Programs\Python\Python312\Lib\site-packages\django\db\models\manager.py", line 87, in manager_method
    return getattr(self.get_queryset(), name)(*args, **kwargs)
           ^^^^^^^^^^^^^^^^^^^^^^^^^^^^^^^^^^^^^^^^^^^^^^^^^^^
  File "C:\Users\.-\AppData\Local\Programs\Python\Python312\Lib\site-packages\django\db\models\query.py", line 649, in get
    raise self.model.DoesNotExist(
group_chats.models.GroupChat.DoesNotExist: GroupChat matching query does not exist.
INFO:django.utils.autoreload:D:\fyp\Deployed apis\group_chats\api\views.py changed, reloading.
ERROR:django.request:Internal Server Error: /api/group/
Traceback (most recent call last):
  File "C:\Users\.-\AppData\Local\Programs\Python\Python312\Lib\site-packages\django\core\handlers\exception.py", line 55, in inner
    response = get_response(request)
               ^^^^^^^^^^^^^^^^^^^^^
  File "C:\Users\.-\AppData\Local\Programs\Python\Python312\Lib\site-packages\django\core\handlers\base.py", line 197, in _get_response
    response = wrapped_callback(request, *callback_args, **callback_kwargs)
               ^^^^^^^^^^^^^^^^^^^^^^^^^^^^^^^^^^^^^^^^^^^^^^^^^^^^^^^^^^^^
  File "C:\Users\.-\AppData\Local\Programs\Python\Python312\Lib\site-packages\django\views\decorators\csrf.py", line 65, in _view_wrapper
    return view_func(request, *args, **kwargs)
           ^^^^^^^^^^^^^^^^^^^^^^^^^^^^^^^^^^^
  File "C:\Users\.-\AppData\Local\Programs\Python\Python312\Lib\site-packages\django\views\generic\base.py", line 104, in view
    return self.dispatch(request, *args, **kwargs)
           ^^^^^^^^^^^^^^^^^^^^^^^^^^^^^^^^^^^^^^^
  File "C:\Users\.-\AppData\Local\Programs\Python\Python312\Lib\site-packages\rest_framework\views.py", line 509, in dispatch
    response = self.handle_exception(exc)
               ^^^^^^^^^^^^^^^^^^^^^^^^^^
  File "C:\Users\.-\AppData\Local\Programs\Python\Python312\Lib\site-packages\rest_framework\views.py", line 469, in handle_exception
    self.raise_uncaught_exception(exc)
  File "C:\Users\.-\AppData\Local\Programs\Python\Python312\Lib\site-packages\rest_framework\views.py", line 480, in raise_uncaught_exception
    raise exc
  File "C:\Users\.-\AppData\Local\Programs\Python\Python312\Lib\site-packages\rest_framework\views.py", line 506, in dispatch
    response = handler(request, *args, **kwargs)
               ^^^^^^^^^^^^^^^^^^^^^^^^^^^^^^^^^
  File "D:\fyp\Deployed apis\group_chats\api\views.py", line 45, in get
    instance = GroupChat.objects.get(id=group_id, is_active=True)
               ^^^^^^^^^^^^^^^^^^^^^^^^^^^^^^^^^^^^^^^^^^^^^^^^^^
  File "C:\Users\.-\AppData\Local\Programs\Python\Python312\Lib\site-packages\django\db\models\manager.py", line 87, in manager_method
    return getattr(self.get_queryset(), name)(*args, **kwargs)
           ^^^^^^^^^^^^^^^^^^^^^^^^^^^^^^^^^^^^^^^^^^^^^^^^^^^
  File "C:\Users\.-\AppData\Local\Programs\Python\Python312\Lib\site-packages\django\db\models\query.py", line 649, in get
    raise self.model.DoesNotExist(
group_chats.models.GroupChat.DoesNotExist: GroupChat matching query does not exist.
INFO:django.utils.autoreload:D:\fyp\Deployed apis\group_chats\api\views.py changed, reloading.
ERROR:django.request:Internal Server Error: /api/group/
Traceback (most recent call last):
  File "C:\Users\.-\AppData\Local\Programs\Python\Python312\Lib\site-packages\django\core\handlers\exception.py", line 55, in inner
    response = get_response(request)
               ^^^^^^^^^^^^^^^^^^^^^
  File "C:\Users\.-\AppData\Local\Programs\Python\Python312\Lib\site-packages\django\core\handlers\base.py", line 220, in _get_response
    response = response.render()
               ^^^^^^^^^^^^^^^^^
  File "C:\Users\.-\AppData\Local\Programs\Python\Python312\Lib\site-packages\django\template\response.py", line 114, in render
    self.content = self.rendered_content
                   ^^^^^^^^^^^^^^^^^^^^^
  File "C:\Users\.-\AppData\Local\Programs\Python\Python312\Lib\site-packages\rest_framework\response.py", line 74, in rendered_content
    ret = renderer.render(self.data, accepted_media_type, context)
          ^^^^^^^^^^^^^^^^^^^^^^^^^^^^^^^^^^^^^^^^^^^^^^^^^^^^^^^^
  File "C:\Users\.-\AppData\Local\Programs\Python\Python312\Lib\site-packages\rest_framework\renderers.py", line 100, in render
    ret = json.dumps(
          ^^^^^^^^^^^
  File "C:\Users\.-\AppData\Local\Programs\Python\Python312\Lib\site-packages\rest_framework\utils\json.py", line 25, in dumps
    return json.dumps(*args, **kwargs)
           ^^^^^^^^^^^^^^^^^^^^^^^^^^^
  File "C:\Users\.-\AppData\Local\Programs\Python\Python312\Lib\json\__init__.py", line 238, in dumps
    **kw).encode(obj)
          ^^^^^^^^^^^
  File "C:\Users\.-\AppData\Local\Programs\Python\Python312\Lib\json\encoder.py", line 200, in encode
    chunks = self.iterencode(o, _one_shot=True)
             ^^^^^^^^^^^^^^^^^^^^^^^^^^^^^^^^^^
  File "C:\Users\.-\AppData\Local\Programs\Python\Python312\Lib\json\encoder.py", line 258, in iterencode
    return _iterencode(o, 0)
           ^^^^^^^^^^^^^^^^^
  File "C:\Users\.-\AppData\Local\Programs\Python\Python312\Lib\site-packages\rest_framework\utils\encoders.py", line 67, in default
    return super().default(obj)
           ^^^^^^^^^^^^^^^^^^^^
  File "C:\Users\.-\AppData\Local\Programs\Python\Python312\Lib\json\encoder.py", line 180, in default
    raise TypeError(f'Object of type {o.__class__.__name__} '
TypeError: Object of type ListSerializer is not JSON serializable
INFO:django.utils.autoreload:D:\fyp\Deployed apis\group_chats\api\views.py changed, reloading.
ERROR:django.request:Internal Server Error: /api/group/
Traceback (most recent call last):
  File "C:\Users\.-\AppData\Local\Programs\Python\Python312\Lib\site-packages\django\core\handlers\exception.py", line 55, in inner
    response = get_response(request)
               ^^^^^^^^^^^^^^^^^^^^^
  File "C:\Users\.-\AppData\Local\Programs\Python\Python312\Lib\site-packages\django\core\handlers\base.py", line 197, in _get_response
    response = wrapped_callback(request, *callback_args, **callback_kwargs)
               ^^^^^^^^^^^^^^^^^^^^^^^^^^^^^^^^^^^^^^^^^^^^^^^^^^^^^^^^^^^^
  File "C:\Users\.-\AppData\Local\Programs\Python\Python312\Lib\site-packages\django\views\decorators\csrf.py", line 65, in _view_wrapper
    return view_func(request, *args, **kwargs)
           ^^^^^^^^^^^^^^^^^^^^^^^^^^^^^^^^^^^
  File "C:\Users\.-\AppData\Local\Programs\Python\Python312\Lib\site-packages\django\views\generic\base.py", line 104, in view
    return self.dispatch(request, *args, **kwargs)
           ^^^^^^^^^^^^^^^^^^^^^^^^^^^^^^^^^^^^^^^
  File "C:\Users\.-\AppData\Local\Programs\Python\Python312\Lib\site-packages\rest_framework\views.py", line 509, in dispatch
    response = self.handle_exception(exc)
               ^^^^^^^^^^^^^^^^^^^^^^^^^^
  File "C:\Users\.-\AppData\Local\Programs\Python\Python312\Lib\site-packages\rest_framework\views.py", line 469, in handle_exception
    self.raise_uncaught_exception(exc)
  File "C:\Users\.-\AppData\Local\Programs\Python\Python312\Lib\site-packages\rest_framework\views.py", line 480, in raise_uncaught_exception
    raise exc
  File "C:\Users\.-\AppData\Local\Programs\Python\Python312\Lib\site-packages\rest_framework\views.py", line 506, in dispatch
    response = handler(request, *args, **kwargs)
               ^^^^^^^^^^^^^^^^^^^^^^^^^^^^^^^^^
  File "D:\fyp\Deployed apis\group_chats\api\views.py", line 47, in get
    return Response(response, status=status.HTTP_200_OK)
                    ^^^^^^^^
NameError: name 'response' is not defined. Did you mean: 'Response'?
INFO:django.utils.autoreload:D:\fyp\Deployed apis\group_chats\api\views.py changed, reloading.
INFO:django.utils.autoreload:D:\fyp\Deployed apis\group_chats\api\views.py changed, reloading.
INFO:django.utils.autoreload:D:\fyp\Deployed apis\group_chats\api\views.py changed, reloading.
ERROR:django.request:Internal Server Error: /api/group/
Traceback (most recent call last):
  File "C:\Users\.-\AppData\Local\Programs\Python\Python312\Lib\site-packages\django\core\handlers\exception.py", line 55, in inner
    response = get_response(request)
               ^^^^^^^^^^^^^^^^^^^^^
  File "C:\Users\.-\AppData\Local\Programs\Python\Python312\Lib\site-packages\django\core\handlers\base.py", line 197, in _get_response
    response = wrapped_callback(request, *callback_args, **callback_kwargs)
               ^^^^^^^^^^^^^^^^^^^^^^^^^^^^^^^^^^^^^^^^^^^^^^^^^^^^^^^^^^^^
  File "C:\Users\.-\AppData\Local\Programs\Python\Python312\Lib\site-packages\django\views\decorators\csrf.py", line 65, in _view_wrapper
    return view_func(request, *args, **kwargs)
           ^^^^^^^^^^^^^^^^^^^^^^^^^^^^^^^^^^^
  File "C:\Users\.-\AppData\Local\Programs\Python\Python312\Lib\site-packages\django\views\generic\base.py", line 104, in view
    return self.dispatch(request, *args, **kwargs)
           ^^^^^^^^^^^^^^^^^^^^^^^^^^^^^^^^^^^^^^^
  File "C:\Users\.-\AppData\Local\Programs\Python\Python312\Lib\site-packages\rest_framework\views.py", line 509, in dispatch
    response = self.handle_exception(exc)
               ^^^^^^^^^^^^^^^^^^^^^^^^^^
  File "C:\Users\.-\AppData\Local\Programs\Python\Python312\Lib\site-packages\rest_framework\views.py", line 469, in handle_exception
    self.raise_uncaught_exception(exc)
  File "C:\Users\.-\AppData\Local\Programs\Python\Python312\Lib\site-packages\rest_framework\views.py", line 480, in raise_uncaught_exception
    raise exc
  File "C:\Users\.-\AppData\Local\Programs\Python\Python312\Lib\site-packages\rest_framework\views.py", line 506, in dispatch
    response = handler(request, *args, **kwargs)
               ^^^^^^^^^^^^^^^^^^^^^^^^^^^^^^^^^
  File "D:\fyp\Deployed apis\group_chats\api\views.py", line 45, in get
    instance = GroupChat.objects.get(id=group_id, is_active=True)
               ^^^^^^^^^^^^^^^^^^^^^^^^^^^^^^^^^^^^^^^^^^^^^^^^^^
  File "C:\Users\.-\AppData\Local\Programs\Python\Python312\Lib\site-packages\django\db\models\manager.py", line 87, in manager_method
    return getattr(self.get_queryset(), name)(*args, **kwargs)
           ^^^^^^^^^^^^^^^^^^^^^^^^^^^^^^^^^^^^^^^^^^^^^^^^^^^
  File "C:\Users\.-\AppData\Local\Programs\Python\Python312\Lib\site-packages\django\db\models\query.py", line 649, in get
    raise self.model.DoesNotExist(
group_chats.models.GroupChat.DoesNotExist: GroupChat matching query does not exist.
INFO:django.utils.autoreload:D:\fyp\Deployed apis\group_chats\api\views.py changed, reloading.
WARNING:django.request:Not Found: /api/group/
INFO:django.utils.autoreload:D:\fyp\Deployed apis\group_chats\api\serializers.py changed, reloading.
INFO:django.utils.autoreload:D:\fyp\Deployed apis\accounts\models.py changed, reloading.
INFO:django.utils.autoreload:/home/shariq/HS/smartsuiteapisdeployment/smartsuite/urls.py changed, reloading.
INFO:django.utils.autoreload:/home/shariq/HS/smartsuiteapisdeployment/smartsuite/settings.py changed, reloading.
INFO:django.utils.autoreload:/home/shariq/HS/smartsuiteapisdeployment/announcement/api/serializers.py changed, reloading.
INFO:django.utils.autoreload:/home/shariq/HS/smartsuiteapisdeployment/announcement/api/serializers.py changed, reloading.
INFO:django.utils.autoreload:/home/shariq/HS/smartsuiteapisdeployment/announcement/api/views.py changed, reloading.
INFO:django.utils.autoreload:/home/shariq/HS/smartsuiteapisdeployment/announcement/api/views.py changed, reloading.
INFO:django.utils.autoreload:/home/shariq/HS/smartsuiteapisdeployment/announcement/models.py changed, reloading.
ERROR:django.request:Internal Server Error: /api/announcement/
Traceback (most recent call last):
  File "/home/shariq/HS/smartsuiteapisdeployment/.venv/lib/python3.10/site-packages/django/db/backends/utils.py", line 105, in _execute
    return self.cursor.execute(sql, params)
  File "/home/shariq/HS/smartsuiteapisdeployment/.venv/lib/python3.10/site-packages/django/db/backends/sqlite3/base.py", line 354, in execute
    return super().execute(query, params)
sqlite3.OperationalError: no such table: announcement_accouncements

The above exception was the direct cause of the following exception:

Traceback (most recent call last):
  File "/home/shariq/HS/smartsuiteapisdeployment/.venv/lib/python3.10/site-packages/django/core/handlers/exception.py", line 55, in inner
    response = get_response(request)
  File "/home/shariq/HS/smartsuiteapisdeployment/.venv/lib/python3.10/site-packages/django/core/handlers/base.py", line 197, in _get_response
    response = wrapped_callback(request, *callback_args, **callback_kwargs)
  File "/home/shariq/HS/smartsuiteapisdeployment/.venv/lib/python3.10/site-packages/django/views/decorators/csrf.py", line 65, in _view_wrapper
    return view_func(request, *args, **kwargs)
  File "/home/shariq/HS/smartsuiteapisdeployment/.venv/lib/python3.10/site-packages/django/views/generic/base.py", line 104, in view
    return self.dispatch(request, *args, **kwargs)
  File "/home/shariq/HS/smartsuiteapisdeployment/.venv/lib/python3.10/site-packages/rest_framework/views.py", line 509, in dispatch
    response = self.handle_exception(exc)
  File "/home/shariq/HS/smartsuiteapisdeployment/.venv/lib/python3.10/site-packages/rest_framework/views.py", line 469, in handle_exception
    self.raise_uncaught_exception(exc)
  File "/home/shariq/HS/smartsuiteapisdeployment/.venv/lib/python3.10/site-packages/rest_framework/views.py", line 480, in raise_uncaught_exception
    raise exc
  File "/home/shariq/HS/smartsuiteapisdeployment/.venv/lib/python3.10/site-packages/rest_framework/views.py", line 506, in dispatch
    response = handler(request, *args, **kwargs)
  File "/home/shariq/HS/smartsuiteapisdeployment/announcement/api/views.py", line 19, in get
    if instances:
  File "/home/shariq/HS/smartsuiteapisdeployment/.venv/lib/python3.10/site-packages/django/db/models/query.py", line 414, in __bool__
    self._fetch_all()
  File "/home/shariq/HS/smartsuiteapisdeployment/.venv/lib/python3.10/site-packages/django/db/models/query.py", line 1928, in _fetch_all
    self._result_cache = list(self._iterable_class(self))
  File "/home/shariq/HS/smartsuiteapisdeployment/.venv/lib/python3.10/site-packages/django/db/models/query.py", line 91, in __iter__
    results = compiler.execute_sql(
  File "/home/shariq/HS/smartsuiteapisdeployment/.venv/lib/python3.10/site-packages/django/db/models/sql/compiler.py", line 1574, in execute_sql
    cursor.execute(sql, params)
  File "/home/shariq/HS/smartsuiteapisdeployment/.venv/lib/python3.10/site-packages/django/db/backends/utils.py", line 122, in execute
    return super().execute(sql, params)
  File "/home/shariq/HS/smartsuiteapisdeployment/.venv/lib/python3.10/site-packages/django/db/backends/utils.py", line 79, in execute
    return self._execute_with_wrappers(
  File "/home/shariq/HS/smartsuiteapisdeployment/.venv/lib/python3.10/site-packages/django/db/backends/utils.py", line 92, in _execute_with_wrappers
    return executor(sql, params, many, context)
  File "/home/shariq/HS/smartsuiteapisdeployment/.venv/lib/python3.10/site-packages/django/db/backends/utils.py", line 100, in _execute
    with self.db.wrap_database_errors:
  File "/home/shariq/HS/smartsuiteapisdeployment/.venv/lib/python3.10/site-packages/django/db/utils.py", line 91, in __exit__
    raise dj_exc_value.with_traceback(traceback) from exc_value
  File "/home/shariq/HS/smartsuiteapisdeployment/.venv/lib/python3.10/site-packages/django/db/backends/utils.py", line 105, in _execute
    return self.cursor.execute(sql, params)
  File "/home/shariq/HS/smartsuiteapisdeployment/.venv/lib/python3.10/site-packages/django/db/backends/sqlite3/base.py", line 354, in execute
    return super().execute(query, params)
django.db.utils.OperationalError: no such table: announcement_accouncements
ERROR:django.request:Internal Server Error: /api/announcement/
Traceback (most recent call last):
  File "/home/shariq/HS/smartsuiteapisdeployment/.venv/lib/python3.10/site-packages/django/core/handlers/exception.py", line 55, in inner
    response = get_response(request)
  File "/home/shariq/HS/smartsuiteapisdeployment/.venv/lib/python3.10/site-packages/django/core/handlers/base.py", line 197, in _get_response
    response = wrapped_callback(request, *callback_args, **callback_kwargs)
  File "/home/shariq/HS/smartsuiteapisdeployment/.venv/lib/python3.10/site-packages/django/views/decorators/csrf.py", line 65, in _view_wrapper
    return view_func(request, *args, **kwargs)
  File "/home/shariq/HS/smartsuiteapisdeployment/.venv/lib/python3.10/site-packages/django/views/generic/base.py", line 104, in view
    return self.dispatch(request, *args, **kwargs)
  File "/home/shariq/HS/smartsuiteapisdeployment/.venv/lib/python3.10/site-packages/rest_framework/views.py", line 509, in dispatch
    response = self.handle_exception(exc)
  File "/home/shariq/HS/smartsuiteapisdeployment/.venv/lib/python3.10/site-packages/rest_framework/views.py", line 469, in handle_exception
    self.raise_uncaught_exception(exc)
  File "/home/shariq/HS/smartsuiteapisdeployment/.venv/lib/python3.10/site-packages/rest_framework/views.py", line 480, in raise_uncaught_exception
    raise exc
  File "/home/shariq/HS/smartsuiteapisdeployment/.venv/lib/python3.10/site-packages/rest_framework/views.py", line 506, in dispatch
    response = handler(request, *args, **kwargs)
  File "/home/shariq/HS/smartsuiteapisdeployment/announcement/api/views.py", line 22, in get
    return Response({'message':"No Record Found"},status=status.HTTP_404_NOT_FOUND)
NameError: name 'status' is not defined
INFO:django.utils.autoreload:/home/shariq/HS/smartsuiteapisdeployment/announcement/api/views.py changed, reloading.
WARNING:django.request:Not Found: /api/announcement/
INFO:django.utils.autoreload:/home/shariq/HS/smartsuiteapisdeployment/announcement/api/views.py changed, reloading.
WARNING:django.request:Bad Request: /api/announcement/
WARNING:django.request:Bad Request: /api/announcement/
WARNING:django.request:Bad Request: /api/announcement/
WARNING:django.request:Not Found: /pk/
WARNING:django.request:Not Found: /favicon.ico/
ERROR:django.request:Internal Server Error: /admin/
Traceback (most recent call last):
  File "/home/shariq/HS/smartsuiteapisdeployment/.venv/lib/python3.10/site-packages/django/core/handlers/exception.py", line 55, in inner
    response = get_response(request)
  File "/home/shariq/HS/smartsuiteapisdeployment/.venv/lib/python3.10/site-packages/django/core/handlers/base.py", line 197, in _get_response
    response = wrapped_callback(request, *callback_args, **callback_kwargs)
  File "/home/shariq/HS/smartsuiteapisdeployment/.venv/lib/python3.10/site-packages/django/contrib/admin/sites.py", line 260, in wrapper
    return self.admin_view(view, cacheable)(*args, **kwargs)
  File "/home/shariq/HS/smartsuiteapisdeployment/.venv/lib/python3.10/site-packages/django/utils/decorators.py", line 188, in _view_wrapper
    result = _process_exception(request, e)
  File "/home/shariq/HS/smartsuiteapisdeployment/.venv/lib/python3.10/site-packages/django/utils/decorators.py", line 186, in _view_wrapper
    response = view_func(request, *args, **kwargs)
  File "/home/shariq/HS/smartsuiteapisdeployment/.venv/lib/python3.10/site-packages/django/views/decorators/cache.py", line 80, in _view_wrapper
    response = view_func(request, *args, **kwargs)
  File "/home/shariq/HS/smartsuiteapisdeployment/.venv/lib/python3.10/site-packages/django/contrib/admin/sites.py", line 241, in inner
    return view(request, *args, **kwargs)
  File "/home/shariq/HS/smartsuiteapisdeployment/.venv/lib/python3.10/site-packages/django/contrib/admin/sites.py", line 557, in index
    app_list = self.get_app_list(request)
  File "/home/shariq/HS/smartsuiteapisdeployment/accounts/models.py", line 112, in get_app_list
    app['models'].sort(key=lambda x: ordering[x['name']])
  File "/home/shariq/HS/smartsuiteapisdeployment/accounts/models.py", line 112, in <lambda>
    app['models'].sort(key=lambda x: ordering[x['name']])
KeyError: 'Notifications Statuses'
INFO:django.utils.autoreload:/home/shariq/HS/smartsuiteapisdeployment/accounts/models.py changed, reloading.
INFO:django.utils.autoreload:/home/shariq/HS/smartsuiteapisdeployment/announcement/admin.py changed, reloading.
INFO:django.utils.autoreload:/home/shariq/HS/smartsuiteapisdeployment/announcement/admin.py changed, reloading.
INFO:django.utils.autoreload:/home/shariq/HS/smartsuiteapisdeployment/announcement/admin.py changed, reloading.
INFO:django.utils.autoreload:/home/shariq/HS/smartsuiteapisdeployment/announcement/admin.py changed, reloading.
ERROR:django.request:Internal Server Error: /api/announcement/
Traceback (most recent call last):
  File "/home/shariq/HS/smartsuiteapisdeployment/.venv/lib/python3.10/site-packages/django/core/handlers/exception.py", line 55, in inner
    response = get_response(request)
  File "/home/shariq/HS/smartsuiteapisdeployment/.venv/lib/python3.10/site-packages/django/core/handlers/base.py", line 197, in _get_response
    response = wrapped_callback(request, *callback_args, **callback_kwargs)
  File "/home/shariq/HS/smartsuiteapisdeployment/.venv/lib/python3.10/site-packages/django/views/decorators/csrf.py", line 65, in _view_wrapper
    return view_func(request, *args, **kwargs)
  File "/home/shariq/HS/smartsuiteapisdeployment/.venv/lib/python3.10/site-packages/django/views/generic/base.py", line 104, in view
    return self.dispatch(request, *args, **kwargs)
  File "/home/shariq/HS/smartsuiteapisdeployment/.venv/lib/python3.10/site-packages/rest_framework/views.py", line 509, in dispatch
    response = self.handle_exception(exc)
  File "/home/shariq/HS/smartsuiteapisdeployment/.venv/lib/python3.10/site-packages/rest_framework/views.py", line 469, in handle_exception
    self.raise_uncaught_exception(exc)
  File "/home/shariq/HS/smartsuiteapisdeployment/.venv/lib/python3.10/site-packages/rest_framework/views.py", line 480, in raise_uncaught_exception
    raise exc
  File "/home/shariq/HS/smartsuiteapisdeployment/.venv/lib/python3.10/site-packages/rest_framework/views.py", line 506, in dispatch
    response = handler(request, *args, **kwargs)
  File "/home/shariq/HS/smartsuiteapisdeployment/announcement/api/views.py", line 13, in post
    serializer.save(announced_by=request.user)
  File "/home/shariq/HS/smartsuiteapisdeployment/.venv/lib/python3.10/site-packages/rest_framework/serializers.py", line 208, in save
    self.instance = self.create(validated_data)
  File "/home/shariq/HS/smartsuiteapisdeployment/announcement/api/serializers.py", line 26, in create
    new_announcement = Accouncements.objects.create(**validated_data)
  File "/home/shariq/HS/smartsuiteapisdeployment/.venv/lib/python3.10/site-packages/django/db/models/manager.py", line 87, in manager_method
    return getattr(self.get_queryset(), name)(*args, **kwargs)
  File "/home/shariq/HS/smartsuiteapisdeployment/.venv/lib/python3.10/site-packages/django/db/models/query.py", line 677, in create
    obj = self.model(**kwargs)
  File "/home/shariq/HS/smartsuiteapisdeployment/.venv/lib/python3.10/site-packages/django/db/models/base.py", line 543, in __init__
    _setattr(self, field.name, rel_obj)
  File "/home/shariq/HS/smartsuiteapisdeployment/.venv/lib/python3.10/site-packages/django/db/models/fields/related_descriptors.py", line 287, in __set__
    raise ValueError(
ValueError: Cannot assign "<django.contrib.auth.models.AnonymousUser object at 0x7fac7f1af460>": "Accouncements.announced_by" must be a "CustomUser" instance.
ERROR:django.request:Internal Server Error: /api/announcement/
Traceback (most recent call last):
  File "/home/shariq/HS/smartsuiteapisdeployment/.venv/lib/python3.10/site-packages/django/core/handlers/exception.py", line 55, in inner
    response = get_response(request)
  File "/home/shariq/HS/smartsuiteapisdeployment/.venv/lib/python3.10/site-packages/django/core/handlers/base.py", line 197, in _get_response
    response = wrapped_callback(request, *callback_args, **callback_kwargs)
  File "/home/shariq/HS/smartsuiteapisdeployment/.venv/lib/python3.10/site-packages/django/views/decorators/csrf.py", line 65, in _view_wrapper
    return view_func(request, *args, **kwargs)
  File "/home/shariq/HS/smartsuiteapisdeployment/.venv/lib/python3.10/site-packages/django/views/generic/base.py", line 104, in view
    return self.dispatch(request, *args, **kwargs)
  File "/home/shariq/HS/smartsuiteapisdeployment/.venv/lib/python3.10/site-packages/rest_framework/views.py", line 509, in dispatch
    response = self.handle_exception(exc)
  File "/home/shariq/HS/smartsuiteapisdeployment/.venv/lib/python3.10/site-packages/rest_framework/views.py", line 469, in handle_exception
    self.raise_uncaught_exception(exc)
  File "/home/shariq/HS/smartsuiteapisdeployment/.venv/lib/python3.10/site-packages/rest_framework/views.py", line 480, in raise_uncaught_exception
    raise exc
  File "/home/shariq/HS/smartsuiteapisdeployment/.venv/lib/python3.10/site-packages/rest_framework/views.py", line 506, in dispatch
    response = handler(request, *args, **kwargs)
  File "/home/shariq/HS/smartsuiteapisdeployment/announcement/api/views.py", line 13, in post
    serializer.save(announced_by=request.user)
  File "/home/shariq/HS/smartsuiteapisdeployment/.venv/lib/python3.10/site-packages/rest_framework/serializers.py", line 208, in save
    self.instance = self.create(validated_data)
  File "/home/shariq/HS/smartsuiteapisdeployment/announcement/api/serializers.py", line 26, in create
    new_announcement = Accouncements.objects.create(**validated_data)
  File "/home/shariq/HS/smartsuiteapisdeployment/.venv/lib/python3.10/site-packages/django/db/models/manager.py", line 87, in manager_method
    return getattr(self.get_queryset(), name)(*args, **kwargs)
  File "/home/shariq/HS/smartsuiteapisdeployment/.venv/lib/python3.10/site-packages/django/db/models/query.py", line 677, in create
    obj = self.model(**kwargs)
  File "/home/shariq/HS/smartsuiteapisdeployment/.venv/lib/python3.10/site-packages/django/db/models/base.py", line 564, in __init__
    _setattr(self, prop, value)
  File "/home/shariq/HS/smartsuiteapisdeployment/.venv/lib/python3.10/site-packages/django/db/models/fields/related_descriptors.py", line 665, in __set__
    raise TypeError(
TypeError: Direct assignment to the forward side of a many-to-many set is prohibited. Use to_users.set() instead.
INFO:django.utils.autoreload:/home/shariq/HS/smartsuiteapisdeployment/announcement/api/serializers.py changed, reloading.
INFO:django.utils.autoreload:/home/shariq/HS/smartsuiteapisdeployment/announcement/api/serializers.py changed, reloading.
ERROR:django.request:Internal Server Error: /api/announcement/
Traceback (most recent call last):
  File "/home/shariq/HS/smartsuiteapisdeployment/.venv/lib/python3.10/site-packages/django/core/handlers/exception.py", line 55, in inner
    response = get_response(request)
  File "/home/shariq/HS/smartsuiteapisdeployment/.venv/lib/python3.10/site-packages/django/core/handlers/base.py", line 197, in _get_response
    response = wrapped_callback(request, *callback_args, **callback_kwargs)
  File "/home/shariq/HS/smartsuiteapisdeployment/.venv/lib/python3.10/site-packages/django/views/decorators/csrf.py", line 65, in _view_wrapper
    return view_func(request, *args, **kwargs)
  File "/home/shariq/HS/smartsuiteapisdeployment/.venv/lib/python3.10/site-packages/django/views/generic/base.py", line 104, in view
    return self.dispatch(request, *args, **kwargs)
  File "/home/shariq/HS/smartsuiteapisdeployment/.venv/lib/python3.10/site-packages/rest_framework/views.py", line 509, in dispatch
    response = self.handle_exception(exc)
  File "/home/shariq/HS/smartsuiteapisdeployment/.venv/lib/python3.10/site-packages/rest_framework/views.py", line 469, in handle_exception
    self.raise_uncaught_exception(exc)
  File "/home/shariq/HS/smartsuiteapisdeployment/.venv/lib/python3.10/site-packages/rest_framework/views.py", line 480, in raise_uncaught_exception
    raise exc
  File "/home/shariq/HS/smartsuiteapisdeployment/.venv/lib/python3.10/site-packages/rest_framework/views.py", line 506, in dispatch
    response = handler(request, *args, **kwargs)
  File "/home/shariq/HS/smartsuiteapisdeployment/announcement/api/views.py", line 14, in post
    return Response(serializer.data, status=status.HTTP_200_OK)
  File "/home/shariq/HS/smartsuiteapisdeployment/.venv/lib/python3.10/site-packages/rest_framework/serializers.py", line 571, in data
    ret = super().data
  File "/home/shariq/HS/smartsuiteapisdeployment/.venv/lib/python3.10/site-packages/rest_framework/serializers.py", line 249, in data
    self._data = self.to_representation(self.instance)
  File "/home/shariq/HS/smartsuiteapisdeployment/.venv/lib/python3.10/site-packages/rest_framework/serializers.py", line 538, in to_representation
    ret[field.field_name] = field.to_representation(attribute)
  File "/home/shariq/HS/smartsuiteapisdeployment/.venv/lib/python3.10/site-packages/rest_framework/fields.py", line 1869, in to_representation
    method = getattr(self.parent, self.method_name)
AttributeError: 'CreateAnnouncementSerializer' object has no attribute 'get_announced_by'
INFO:django.utils.autoreload:/home/shariq/HS/smartsuiteapisdeployment/announcement/api/serializers.py changed, reloading.
ERROR:django.request:Internal Server Error: /api/announcement/
Traceback (most recent call last):
  File "/home/shariq/HS/smartsuiteapisdeployment/.venv/lib/python3.10/site-packages/django/core/handlers/exception.py", line 55, in inner
    response = get_response(request)
  File "/home/shariq/HS/smartsuiteapisdeployment/.venv/lib/python3.10/site-packages/django/core/handlers/base.py", line 197, in _get_response
    response = wrapped_callback(request, *callback_args, **callback_kwargs)
  File "/home/shariq/HS/smartsuiteapisdeployment/.venv/lib/python3.10/site-packages/django/views/decorators/csrf.py", line 65, in _view_wrapper
    return view_func(request, *args, **kwargs)
  File "/home/shariq/HS/smartsuiteapisdeployment/.venv/lib/python3.10/site-packages/django/views/generic/base.py", line 104, in view
    return self.dispatch(request, *args, **kwargs)
  File "/home/shariq/HS/smartsuiteapisdeployment/.venv/lib/python3.10/site-packages/rest_framework/views.py", line 509, in dispatch
    response = self.handle_exception(exc)
  File "/home/shariq/HS/smartsuiteapisdeployment/.venv/lib/python3.10/site-packages/rest_framework/views.py", line 469, in handle_exception
    self.raise_uncaught_exception(exc)
  File "/home/shariq/HS/smartsuiteapisdeployment/.venv/lib/python3.10/site-packages/rest_framework/views.py", line 480, in raise_uncaught_exception
    raise exc
  File "/home/shariq/HS/smartsuiteapisdeployment/.venv/lib/python3.10/site-packages/rest_framework/views.py", line 506, in dispatch
    response = handler(request, *args, **kwargs)
  File "/home/shariq/HS/smartsuiteapisdeployment/announcement/api/views.py", line 14, in post
    return Response(serializer.data, status=status.HTTP_200_OK)
  File "/home/shariq/HS/smartsuiteapisdeployment/.venv/lib/python3.10/site-packages/rest_framework/serializers.py", line 571, in data
    ret = super().data
  File "/home/shariq/HS/smartsuiteapisdeployment/.venv/lib/python3.10/site-packages/rest_framework/serializers.py", line 249, in data
    self._data = self.to_representation(self.instance)
  File "/home/shariq/HS/smartsuiteapisdeployment/.venv/lib/python3.10/site-packages/rest_framework/serializers.py", line 538, in to_representation
    ret[field.field_name] = field.to_representation(attribute)
  File "/home/shariq/HS/smartsuiteapisdeployment/.venv/lib/python3.10/site-packages/rest_framework/fields.py", line 1870, in to_representation
    return method(value)
  File "/home/shariq/HS/smartsuiteapisdeployment/announcement/api/serializers.py", line 36, in get_to_list
    return UsersListSerializer(obj.to_list.all(), many=True)
AttributeError: 'Accouncements' object has no attribute 'to_list'
INFO:django.utils.autoreload:/home/shariq/HS/smartsuiteapisdeployment/announcement/api/serializers.py changed, reloading.
ERROR:django.request:Internal Server Error: /api/announcement/
Traceback (most recent call last):
  File "/home/shariq/HS/smartsuiteapisdeployment/.venv/lib/python3.10/site-packages/django/core/handlers/exception.py", line 55, in inner
    response = get_response(request)
  File "/home/shariq/HS/smartsuiteapisdeployment/.venv/lib/python3.10/site-packages/django/core/handlers/base.py", line 197, in _get_response
    response = wrapped_callback(request, *callback_args, **callback_kwargs)
  File "/home/shariq/HS/smartsuiteapisdeployment/.venv/lib/python3.10/site-packages/django/views/decorators/csrf.py", line 65, in _view_wrapper
    return view_func(request, *args, **kwargs)
  File "/home/shariq/HS/smartsuiteapisdeployment/.venv/lib/python3.10/site-packages/django/views/generic/base.py", line 104, in view
    return self.dispatch(request, *args, **kwargs)
  File "/home/shariq/HS/smartsuiteapisdeployment/.venv/lib/python3.10/site-packages/rest_framework/views.py", line 509, in dispatch
    response = self.handle_exception(exc)
  File "/home/shariq/HS/smartsuiteapisdeployment/.venv/lib/python3.10/site-packages/rest_framework/views.py", line 469, in handle_exception
    self.raise_uncaught_exception(exc)
  File "/home/shariq/HS/smartsuiteapisdeployment/.venv/lib/python3.10/site-packages/rest_framework/views.py", line 480, in raise_uncaught_exception
    raise exc
  File "/home/shariq/HS/smartsuiteapisdeployment/.venv/lib/python3.10/site-packages/rest_framework/views.py", line 506, in dispatch
    response = handler(request, *args, **kwargs)
  File "/home/shariq/HS/smartsuiteapisdeployment/announcement/api/views.py", line 13, in post
    serializer.save(announced_by=request.user)
  File "/home/shariq/HS/smartsuiteapisdeployment/.venv/lib/python3.10/site-packages/rest_framework/serializers.py", line 208, in save
    self.instance = self.create(validated_data)
  File "/home/shariq/HS/smartsuiteapisdeployment/announcement/api/serializers.py", line 25, in create
    users = validated_data.pop('to_users')
KeyError: 'to_users'
INFO:django.utils.autoreload:/home/shariq/HS/smartsuiteapisdeployment/announcement/api/serializers.py changed, reloading.
INFO:django.utils.autoreload:/home/shariq/HS/smartsuiteapisdeployment/announcement/api/serializers.py changed, reloading.
ERROR:django.request:Internal Server Error: /api/announcement/
Traceback (most recent call last):
  File "/home/shariq/HS/smartsuiteapisdeployment/.venv/lib/python3.10/site-packages/django/core/handlers/exception.py", line 55, in inner
    response = get_response(request)
  File "/home/shariq/HS/smartsuiteapisdeployment/.venv/lib/python3.10/site-packages/django/core/handlers/base.py", line 220, in _get_response
    response = response.render()
  File "/home/shariq/HS/smartsuiteapisdeployment/.venv/lib/python3.10/site-packages/django/template/response.py", line 114, in render
    self.content = self.rendered_content
  File "/home/shariq/HS/smartsuiteapisdeployment/.venv/lib/python3.10/site-packages/rest_framework/response.py", line 74, in rendered_content
    ret = renderer.render(self.data, accepted_media_type, context)
  File "/home/shariq/HS/smartsuiteapisdeployment/.venv/lib/python3.10/site-packages/rest_framework/renderers.py", line 100, in render
    ret = json.dumps(
  File "/home/shariq/HS/smartsuiteapisdeployment/.venv/lib/python3.10/site-packages/rest_framework/utils/json.py", line 25, in dumps
    return json.dumps(*args, **kwargs)
  File "/usr/lib/python3.10/json/__init__.py", line 238, in dumps
    **kw).encode(obj)
  File "/usr/lib/python3.10/json/encoder.py", line 199, in encode
    chunks = self.iterencode(o, _one_shot=True)
  File "/usr/lib/python3.10/json/encoder.py", line 257, in iterencode
    return _iterencode(o, 0)
  File "/home/shariq/HS/smartsuiteapisdeployment/.venv/lib/python3.10/site-packages/rest_framework/utils/encoders.py", line 67, in default
    return super().default(obj)
  File "/usr/lib/python3.10/json/encoder.py", line 179, in default
    raise TypeError(f'Object of type {o.__class__.__name__} '
TypeError: Object of type ListSerializer is not JSON serializable
INFO:django.utils.autoreload:/home/shariq/HS/smartsuiteapisdeployment/announcement/api/serializers.py changed, reloading.
